Workbook

Sheet README
A1: BitMach Master Model | v3 detailed EPC, vendor finance and debt structure
A2: This version adds engineer-friendly electrical CAPEX detail, vendor-style miner finance, EPC tranches, external funding and an amortization tab.
A3: What this workbook does | B3: Builds a formula-driven model for (i) the first 12 months of Phase 1 cash flow and burn, and (ii) a simplified 10-year site / solar / compute ramp to 2GW.
A4: Updated / new tabs | B4: Purpose
A5: CAPEX_Electrical_Detail | B5: Exact Hamar T2603-24 electrical quote packages, scope quantities, adders for unpriced items, and normalization into fixed/site + variable/MW electrical CAPEX.
A6: 12M_Miner_Vendor | B6: M7DS hardware basis with supplier-style payment mechanics: deposit, vendor-financed balance, monthly principal and interest schedule.
A7: 12M_EPC_Tranches | B7: Gross monthly electrical EPC basis and assumed EPC payment tranches / retention finance.
A8: 12M_Funding | B8: Equity and senior debt draw schedule sized to monthly funding need, net of arrangement fees.
A9: Debt_Amortization | B9: Indicative 60-month senior debt schedule with interest capitalized during grace and amortization thereafter.
A10: 12M_Capex / 12M_Cashflow | B10: Now reference the detailed sheets rather than generic hard-coded timing heuristics for the main hardware / EPC cash spend.

Sheet Control
A1: Control Centre | Edit blue cells only
A2: Core assumptions, logistics, staffing and optional revenue controls.
A3: Driver | B3: Unit | C3: Base Case | D3: Notes
A4: FX (ZAR/USD) | B4: ZAR/USD | C4: 17 | D4: April 2026 investor materials use R17.00/USD for Phase 1 capital framing.
A5: Opening cash | B5: ZAR'000 | C5: 0 | D5: Leave at 0 to see pure burn before financing.
A6: BTC price start | B6: USD/BTC | C6: 75000 | D6: Conservative editable placeholder.
A7: BTC annual growth | B7: % | C7: 0.1 | D7: Editable market assumption.
A8: Network hash start | B8: TH/s | C8: 900000000 | D8: Editable network assumption.
A9: Network hash annual growth | B9: % | C9: 0.15 | D9: Editable market assumption.
A10: Block subsidy | B10: BTC/block | C10: 3.125 | D10: Protocol input.
A11: Fee factor on subsidy | B11: % | C11: 0.1 | D11: Protocol / pool-fee uplift assumption.
A12: Blocks per day | B12: blocks/day | C12: 144 | D12: Protocol input.
A13: Tax rate | B13: % | C13: 0.27 | D13: Placeholder corporate tax rate.
A14: Uptime | B14: % | C14: 0.95 | D14: Operational uptime.
A15: General annual inflation | B15: % | C15: 0.05 | D15: 10Y model escalation.
... A31: Miner efficiency | B31: J/T | C31: 12.5 | D31: Management instruction: use M7DS at 12.5J/T.
A32: Miner power | B32: W/miner | C32: =C30*C31 | D32: Formula = hashrate × J/T.
A33: Miner price | B33: USD/miner | C33: 5915 | D33: From latest uploaded workbook; editable.
A34: Aux load | B34: % | C34: 0.05 | D34: Cooling / container auxiliaries.
A35: Miner slots per XS2400 | B35: miners/container | C35: 240 | D35: HeatCore XS2400 working basis.
A36: Hydro container cost | B36: USD/container | C36: 350000 | D36: Hydro container placeholder; replace with quote.
A37: Container gross MW | B37: MW/container | C37: =(C35*C32/1000000)*(1+C34) | D37: Formula from miner power, slot count and aux load.
A38: Miner maintenance | B38: ZAR/miner/year | C38: 2000 | D38: Recurring maintenance per miner.
A39: Electrical/BOS capex | B39: ZAR'000/MW | C39: =CAPEX_Electrical_Detail!$C$28 | D39: All-in electrical EPC per MW from detailed Hamar quote basis incl adders. Summary use only; monthly/annual sheets now use fixed/site + variable/MW.
A40: Ocean freight | B40: USD/container | C40: 8000 | D40: Editable logistics placeholder.
A41: Port/clearing | B41: ZAR'000/container | C41: 150 | D41: Editable logistics placeholder.
A42: Inland trucking | B42: ZAR'000/container | C42: 120 | D42: Editable logistics placeholder.
A43: Crane/rigging | B43: ZAR'000/container | C43: 100 | D43: Editable logistics placeholder.
A44: Cargo insurance | B44: % | C44: 0.01 | D44: Editable cargo insurance assumption.
A45: Import duty | B45: % | C45: 0.05 | D45: Editable customs placeholder.
A46: Initial spare parts | B46: % | C46: 0.02 | D46: Initial spares as % of hardware capex.
A47: Tools & equipment initial | B47: ZAR'000/site | C47: 750 | D47: Tools, meters, accessories and small equipment.
A48: Office setup / deposits | B48: ZAR'000 | C48: 600 | D48: Corporate office setup / deposits.
A49: Software / SCADA setup | B49: ZAR'000 | C49: 1500 | D49: Initial systems setup.
A50: Legal setup total | B50: ZAR'000 | C50: 1200 | D50: Initial legal documentation.
A51: Staff hardware setup | B51: ZAR'000/FTE | C51: 35 | D51: Laptop / phone / PPE / provisioning.
... A87: Annual DR equivalent hours/day | B87: hours/day | C87: 1.5 | D87: Annual DR hours placeholder.
A89: Detailed EPC & financing assumptions
A90: Electrical site-fixed share | B90: % of all-in 20MW electrical EPC | C90: 0.25 | D90: Use to split the Hamar 20MW quote into fixed/site cost and variable/MW cost.
A91: Harmonic mitigation allowance | B91: % of quoted electrical EPC | C91: 0.05 | D91: Quote explicitly excludes harmonic mitigation pending Stage 3 spectra; editable allowance.
...

Sheet CAPEX_Electrical_Detail
A1: Detailed Electrical CAPEX Basis | Grootvlei Phase 1
A2: Exact Hamar T2603-24 electrical EPC quote packages are used as the cost basis; unpriced items are layered in as explicit editable adders.
A4: Package | B4: Unit | C4: 20MW basis (ZAR'000) | D4: Source / notes
A5: Preliminary & general costs | B5: ZAR'000 | C5: 7142.5 | D5: Exact Hamar summary sheet value.
A6: Engineering & design - engineering | B6: ZAR'000 | C6: 1449.2 | D6: Exact Hamar summary sheet value.
A7: Engineering & design - drafting / DO | B7: ZAR'000 | C7: 358.4 | D7: Exact Hamar summary sheet value.
A8: Main equipment package | B8: ZAR'000 | C8: 49215.7 | D8: Package includes essential board substation, 100kVA board, control room, RMUs, mini-subs, 100kVA transformer and busduct.
A9: Racking & accessories | B9: ZAR'000 | C9: 204.22016 | D9: Exact Hamar BOQ subtotal.
A10: Cabling | B10: ZAR'000 | C10: 28884.259 | D10: Exact Hamar BOQ subtotal.
A11: Cable terminations | B11: ZAR'000 | C11: 873.42903 | D11: Exact Hamar BOQ subtotal.
A12: Contingency | B12: ZAR'000 | C12: 2500 | D12: Exact Hamar summary sheet value.
A13: Quoted electrical EPC subtotal | C13: =SUM(C5:C12) | D13: Exact costed packages from the 25 March 2026 Hamar quotation.
A15: Unpriced / under-specified adders
A16: Harmonic mitigation allowance | B16: ZAR'000 | C16: =C13*Control!$C$91 | D16: Concept comments say harmonic mitigation is required but not allowed for in the preliminary offer.
A17: Lighting / small power allowance | B17: ZAR'000 | C17: =C13*Control!$C$92 | D17: Lighting line in quote is blank; editable allowance.
A18: Instrumentation / SCADA allowance | B18: ZAR'000 | C18: =C13*Control!$C$93 | D18: Instrumentation line in quote is blank; editable allowance.
A19: Earthing / lightning allowance | B19: ZAR'000 | C19: =C13*Control!$C$94 | D19: Concept basis requires earthing / lightning and wet/high-humidity suitability.
A20: Civil / drainage / fencing allowance | B20: ZAR'000 | C20: =C13*Control!$C$95 | D20: Brownfield electrical quote does not fully price all enabling works.
A21: Adders subtotal | C21: =SUM(C16:C20) | D21: All editable adders above.
A22: Brownfield similarity factor | B22: x | C22: =Control!$C$96 | D22: 1.00 = use Grootvlei basis; adjust if another site is easier or harder.
A23: All-in electrical EPC | 20MW | B23: ZAR'000 | C23: =(C13+C21)*C22 | D23: Exact quote subtotal plus adders, multiplied by the site similarity factor.
A26: Fixed/site cost | B26: ZAR'000/site | C26: =C23*Control!$C$90 | D26: Editable fixed/site share assumption applied to the all-in 20MW electrical EPC basis.
A27: Variable electrical EPC | B27: ZAR'000/MW | C27: =C23*(1-Control!$C$90)/20 | D27: Variable portion used to scale incremental MW.
A28: All-in electrical EPC | B28: ZAR'000/MW | C28: =C23/20 | D28: For reference only.
A30: Quoted scope composition / quantities
A31: Item | B31: Qty | C31: Unit | D31: Notes
A32: 3m containerised substation for essential board | B32: 1 | C32: ea | D32: Main equipment package
A33: 3m substation switchgear (100kVA board with feeders) | B33: 1 | C33: ea | D33: Main equipment package
A34: 6m containerised control room | B34: 1 | C34: ea | D34: Main equipment package
A35: Schneider RMU | B35: 3 | C35: ea | D35: Main equipment package
A36: 2MVA mini sub | B36: 20 | C36: ea | D36: Main equipment package
A37: 100kVA transformer | B37: 1 | C37: ea | D37: Main equipment package
A38: Busducting from transformer to container (20m) | B38: 12 | C38: ea | D38: Main equipment package
A39: 3c x 35mm² 6.6/11kV XLPE cable | B39: 150 | C39: m | D39: Cabling subtotal
A40: 1c x 150mm² 6.6/11kV XLPE cable | B40: 2100 | C40: m | D40: Cabling subtotal
A41: 1c x 500mm² 6.6/11kV XLPE cable | B41: 9000 | C41: m | D41: Cabling subtotal
A42: 1c x 70mm² G/Y insulated earth | B42: 11250 | C42: m | D42: Cabling subtotal
A43: 3c x 35mm² 6.6/11kV XLPE cable joint | B43: 2 | C43: joint | D43: Cable termination subtotal
... A45: 1c x 500mm² 6.6/11kV XLPE cable joint | B45: 18 | C45: joint | D45: Cable termination subtotal
A48: Scope boundary note | D48: Hamar email thread states the EPC scope includes all electrical works from the 6.6kV feeders to the 400V connection at the BitMach containers, including the essential section and the DX-issued metering scope.
...

Sheet 12M_Deployment
A1: 12-Month Phase 1 Deployment
A2: Edit only the blue MW schedule rows. Base case: Grootvlei ramps first, AMSA follows, and AMSA solar comes online during the ramp.
D3: 1 | E3: 2 | F3: 3 | G3: 4 | H3: 5 | I3: 6 | J3: 7 | K3: 8 | L3: 9 | M3: 10 | N3: 11 | O3: 12
D4: Jan-26 | E4: Feb-26 | F4: Mar-26 | G4: Apr-26 | H4: May-26 | I4: Jun-26 | J4: Jul-26 | K4: Aug-26 | L4: Sep-26 | M4: Oct-26 | N4: Nov-26 | O4: Dec-26
A5: Days in month | B5: days | D5: 31 | E5: 28 | F5: 31 | G5: 30 | H5: 31 | I5: 30 | J5: 31 | K5: 31 | L5: 30 | M5: 31 | N5: 30 | O5: 31
A7: Grootvlei closing MW | B7: MW | D7: 0 | E7: 0 | F7: 5 | G7: 10 | H7: 15 | I7: 15 | J7: 15 | K7: 15 | L7: 15 | M7: 15 | N7: 15 | O7: 15
A8: AMSA closing MW | B8: MW | D8: 0 | E8: 0 | F8: 0 | G8: 0 | H8: 0 | I8: 5 | J8: 5 | K8: 5 | L8: 5 | M8: 5 | N8: 5 | O8: 5
A9: AMSA solar closing MW | B9: MW | D9: 0 | E9: 0 | F9: 0 | G9: 0 | H9: 10 | I9: 10 | J9: 10 | K9: 10 | L9: 10 | M9: 10 | N9: 10 | O9: 10
A12: Grootvlei opening MW | B12: MW | D12: 0 | E12: =D7 | F12: =E7 | G12: =F7 | H12: =G7 | I12: =H7 | J12: =I7 | K12: =J7 | L12: =K7 | ... O12: =N7
A13: AMSA opening MW | B13: MW | D13: 0 | E13: =D8 | F13: =E8 | G13: =F8 | H13: =G8 | I13: =H8 | J13: =I8 | K13: =J8 | L13: =K8 | ... O13: =N8
A14: AMSA solar opening MW | B14: MW | D14: 0 | E14: =D9 | F14: =E9 | G14: =F9 | H14: =G9 | I14: =H9 | J14: =I9 | K14: =J9 | L14: =K9 | ... O14: =N9
A16: Grootvlei average MW | B16: MW | D16: =(D12+D7)/2 | E16: =(E12+E7)/2 | F16: =(F12+F7)/2 | G16: =(G12+G7)/2 | H16: =(H12+H7)/2 | I16: =(I12+I7)/2 | J16: =(J12+J7)/2 | K16: =(K12+K7)/2 | ... O16: =(O12+O7)/2
A17: AMSA average MW | B17: MW | D17: =(D13+D8)/2 | E17: =(E13+E8)/2 | F17: =(F13+F8)/2 | G17: =(G13+G8)/2 | H17: =(H13+H8)/2 | I17: =(I13+I8)/2 | J17: =(J13+J8)/2 | K17: =(K13+K8)/2 | ... O17: =(O13+O8)/2
A18: AMSA average solar MW | B18: MW | D18: =(D14+D9)/2 | E18: =(E14+E9)/2 | F18: =(F14+F9)/2 | G18: =(G14+G9)/2 | H18: =(H14+H9)/2 | I18: =(I14+I9)/2 | J18: =(J14+J9)/2 | K18: =(K14+K9)/2 | ... O18: =(O14+O9)/2
A19: Total average MW | B19: MW | D19: =D16+D17 | E19: =E16+E17 | F19: =F16+F17 | G19: =G16+G17 | H19: =H16+H17 | I19: =I16+I17 | J19: =J16+J17 | K19: =K16+K17 | ... O19: =O16+O17
A21: Grootvlei new MW | B21: MW | D21: =MAX(D7-D12,0) | E21: =MAX(E7-E12,0) | F21: =MAX(F7-F12,0) | G21: =MAX(G7-G12,0) | H21: =MAX(H7-H12,0) | I21: =MAX(I7-I12,0) | J21: =MAX(J7-J12,0) | K21: =MAX(K7-K12,0) | ... O21: =MAX(O7-O12,0)
A22: AMSA new MW | B22: MW | D22: =MAX(D8-D13,0) | E22: =MAX(E8-E13,0) | F22: =MAX(F8-F13,0) | G22: =MAX(G8-G13,0) | H22: =MAX(H8-H13,0) | I22: =MAX(I8-I13,0) | J22: =MAX(J8-J13,0) | K22: =MAX(K8-K13,0) | ... O22: =MAX(O8-O13,0)
A23: AMSA solar new MW | B23: MW | D23: =MAX(D9-D14,0) | E23: =MAX(E9-E14,0) | F23: =MAX(F9-F14,0) | G23: =MAX(G9-G14,0) | H23: =MAX(H9-H14,0) | I23: =MAX(I9-I14,0) | J23: =MAX(J9-J14,0) | K23: =MAX(K9-K14,0) | ... O23: =MAX(O9-O14,0)
A24: Total new MW | B24: MW | D24: =D21+D22 | E24: =E21+E22 | F24: =F21+F22 | G24: =G21+G22 | H24: =H21+H22 | I24: =I21+I22 | J24: =J21+J22 | K24: =K21+K22 | ... O24: =O21+O22
A26: Grootvlei active site | B26: flag | D26: =IF(D16>0,1,0) | E26: =IF(E16>0,1,0) | F26: =IF(F16>0,1,0) | G26: =IF(G16>0,1,0) | H26: =IF(H16>0,1,0) | I26: =IF(I16>0,1,0) | J26: =IF(J16>0,1,0) | K26: =IF(K16>0,1,0) | ... O26: =IF(O16>0,1,0)
A27: AMSA active site | B27: flag | D27: =IF(D17>0,1,0) | E27: =IF(E17>0,1,0) | F27: =IF(F17>0,1,0) | G27: =IF(G17>0,1,0) | H27: =IF(H17>0,1,0) | I27: =IF(I17>0,1,0) | J27: =IF(J17>0,1,0) | K27: =IF(K17>0,1,0) | ... O27: =IF(O17>0,1,0)
A28: Total active sites | B28: count | D28: =D26+D27 | E28: =E26+E27 | F28: =F26+F27 | G28: =G26+G27 | H28: =H26+H27 | I28: =I26+I27 | J28: =J26+J27 | K28: =K26+K27 | ... O28: =O26+O27
A30: Grootvlei site start | B30: flag | D30: =IF(D12=0,IF(D7>0,1,0),0) | E30: =IF(E12=0,IF(E7>0,1,0),0) | F30: =IF(F12=0,IF(F7>0,1,0),0) | G30: =IF(G12=0,IF(G7>0,1,0),0) | H30: =IF(H12=0,IF(H7>0,1,0),0) | I30: =IF(I12=0,IF(I7>0,1,0),0) | J30: =IF(J12=0,IF(J7>0,1,0),0) | K30: =IF(K12=0,IF(K7>0,1,0),0) | ... O30: =IF(O12=0,IF(O7>0,1,0),0)
A31: AMSA site start | B31: flag | D31: =IF(D13=0,IF(D8>0,1,0),0) | E31: =IF(E13=0,IF(E8>0,1,0),0) | F31: =IF(F13=0,IF(F8>0,1,0),0) | G31: =IF(G13=0,IF(G8>0,1,0),0) | H31: =IF(H13=0,IF(H8>0,1,0),0) | I31: =IF(I13=0,IF(I8>0,1,0),0) | J31: =IF(J13=0,IF(J8>0,1,0),0) | K31: =IF(K13=0,IF(K8>0,1,0),0) | ... O31: =IF(O13=0,IF(O8>0,1,0),0)
A32: Total site starts | B32: count | D32: =D30+D31 | E32: =E30+E31 | F32: =F30+F31 | G32: =G30+G31 | H32: =H30+H31 | I32: =I30+I31 | J32: =J30+J31 | K32: =K30+K31 | ... O32: =O30+O31
A34: Grootvlei closing containers | B34: containers | D34: =ROUNDUP(D7/Control!$C$37,0) | E34: =ROUNDUP(E7/Control!$C$37,0) | F34: =ROUNDUP(F7/Control!$C$37,0) | G34: =ROUNDUP(G7/Control!$C$37,0) | H34: =ROUNDUP(H7/Control!$C$37,0) | I34: =ROUNDUP(I7/Control!$C$37,0) | J34: =ROUNDUP(J7/Control!$C$37,0) | K34: =ROUNDUP(K7/Control!$C$37,0) | ... O34: =ROUNDUP(O7/Control!$C$37,0)
A35: AMSA closing containers | B35: containers | D35: =ROUNDUP(D8/Control!$C$37,0) | E35: =ROUNDUP(E8/Control!$C$37,0) | F35: =ROUNDUP(F8/Control!$C$37,0) | G35: =ROUNDUP(G8/Control!$C$37,0) | H35: =ROUNDUP(H8/Control!$C$37,0) | I35: =ROUNDUP(I8/Control!$C$37,0) | J35: =ROUNDUP(J8/Control!$C$37,0) | K35: =ROUNDUP(K8/Control!$C$37,0) | ... O35: =ROUNDUP(O8/Control!$C$37,0)
A36: Total closing containers | B36: containers | D36: =D34+D35 | E36: =E34+E35 | F36: =F34+F35 | G36: =G34+G35 | H36: =H34+H35 | I36: =I34+I35 | J36: =J34+J35 | K36: =K34+K35 | ... O36: =O34+O35
A38: Grootvlei opening containers | B38: containers | D38: 0 | E38: =D34 | F38: =E34 | G38: =F34 | H38: =G34 | I38: =H34 | J38: =I34 | K38: =J34 | L38: =K34 | ... O38: =N34
A39: AMSA opening containers | B39: containers | D39: 0 | E39: =D35 | F39: =E35 | G39: =F35 | H39: =G35 | I39: =H35 | J39: =I35 | K39: =J35 | L39: =K35 | ... O39: =N35
A40: Total opening containers | B40: containers | D40: =D38+D39 | E40: =E38+E39 | F40: =F38+F39 | G40: =G38+G39 | H40: =H38+H39 | I40: =I38+I39 | J40: =J38+J39 | K40: =K38+K39 | ... O40: =O38+O39
A42: Grootvlei new containers | B42: containers | D42: =MAX(D34-D38,0) | E42: =MAX(E34-E38,0) | F42: =MAX(F34-F38,0) | G42: =MAX(G34-G38,0) | H42: =MAX(H34-H38,0) | I42: =MAX(I34-I38,0) | J42: =MAX(J34-J38,0) | K42: =MAX(K34-K38,0) | ... O42: =MAX(O34-O38,0)
A43: AMSA new containers | B43: containers | D43: =MAX(D35-D39,0) | E43: =MAX(E35-E39,0) | F43: =MAX(F35-F39,0) | G43: =MAX(G35-G39,0) | H43: =MAX(H35-H39,0) | I43: =MAX(I35-I39,0) | J43: =MAX(J35-J39,0) | K43: =MAX(K35-K39,0) | ... O43: =MAX(O35-O39,0)
A44: Total new containers | B44: containers | D44: =D42+D43 | E44: =E42+E43 | F44: =F42+F43 | G44: =G42+G43 | H44: =H42+H43 | I44: =I42+I43 | J44: =J42+J43 | K44: =K42+K43 | ... O44: =O42+O43
A46: Grootvlei closing site FTE | B46: FTE | D46: =D26*Control!$C$54+D7*Control!$C$56+D7*Control!$C$58 | E46: =E26*Control!$C$54+E7*Control!$C$56+E7*Control!$C$58 | F46: =F26*Control!$C$54+F7*Control!$C$56+F7*Control!$C$58 | G46: =G26*Control!$C$54+G7*Control!$C$56+G7*Control!$C$58 | H46: =H26*Control!$C$54+H7*Control!$C$56+H7*Control!$C$58 | I46: =I26*Control!$C$54+I7*Control!$C$56+I7*Control!$C$58 | J46: =J26*Control!$C$54+J7*Control!$C$56+J7*Control!$C$58 | K46: =K26*Control!$C$54+K7*Control!$C$56+K7*Control!$C$58 | ... O46: =O26*Control!$C$54+O7*Control!$C$56+O7*Control!$C$58
A47: AMSA closing site FTE | B47: FTE | D47: =D27*Control!$C$54+D8*Control!$C$56+D8*Control!$C$58 | E47: =E27*Control!$C$54+E8*Control!$C$56+E8*Control!$C$58 | F47: =F27*Control!$C$54+F8*Control!$C$56+F8*Control!$C$58 | G47: =G27*Control!$C$54+G8*Control!$C$56+G8*Control!$C$58 | H47: =H27*Control!$C$54+H8*Control!$C$56+H8*Control!$C$58 | I47: =I27*Control!$C$54+I8*Control!$C$56+I8*Control!$C$58 | J47: =J27*Control!$C$54+J8*Control!$C$56+J8*Control!$C$58 | K47: =K27*Control!$C$54+K8*Control!$C$56+K8*Control!$C$58 | ... O47: =O27*Control!$C$54+O8*Control!$C$56+O8*Control!$C$58
A48: Total closing site FTE | B48: FTE | D48: =D46+D47 | E48: =E46+E47 | F48: =F46+F47 | G48: =G46+G47 | H48: =H46+H47 | I48: =I46+I47 | J48: =J46+J47 | K48: =K46+K47 | ... O48: =O46+O47
A49: Total closing FTE incl corporate | B49: FTE | D49: =D48+Control!$C$52 | E49: =E48+Control!$C$52 | F49: =F48+Control!$C$52 | G49: =G48+Control!$C$52 | H49: =H48+Control!$C$52 | I49: =I48+Control!$C$52 | J49: =J48+Control!$C$52 | K49: =K48+Control!$C$52 | ... O49: =O48+Control!$C$52
A51: Total opening FTE incl corporate | B51: FTE | D51: =Control!$C$52 | E51: =D49 | F51: =E49 | G51: =F49 | H51: =G49 | I51: =H49 | J51: =I49 | K51: =J49 | L51: =K49 | ... O51: =N49
A52: New FTE onboarded | B52: FTE | D52: =MAX(D49-D51,0) | E52: =MAX(E49-E51,0) | F52: =MAX(F49-F51,0) | G52: =MAX(G49-G51,0) | H52: =MAX(H49-H51,0) | I52: =MAX(I49-I51,0) | J52: =MAX(J49-J51,0) | K52: =MAX(K49-K51,0) | ... O52: =MAX(O49-O51,0)
...

Sheet 12M_Revenue
A1: 12-Month Revenue Build
A2: BTC revenue is base case. Demand response and hyperscaler rows are built, but default to OFF in base case.
D3: 1 | E3: 2 | F3: 3 | G3: 4 | H3: 5 | I3: 6 | J3: 7 | K3: 8 | L3: 9 | M3: 10 | N3: 11 | O3: 12
D4: Jan-26 | E4: Feb-26 | F4: Mar-26 | G4: Apr-26 | H4: May-26 | I4: Jun-26 | J4: Jul-26 | K4: Aug-26 | L4: Sep-26 | M4: Oct-26 | N4: Nov-26 | O4: Dec-26
A5: BTC price (USD) | B5: USD/BTC | D5: =Control!$C$6 | E5: =D5*(1+Control!$C$7)^(1/12) | F5: =E5*(1+Control!$C$7)^(1/12) | G5: =F5*(1+Control!$C$7)^(1/12) | H5: =G5*(1+Control!$C$7)^(1/12) | I5: =H5*(1+Control!$C$7)^(1/12) | J5: =I5*(1+Control!$C$7)^(1/12) | K5: =J5*(1+Control!$C$7)^(1/12) | L5: =K5*(1+Control!$C$7)^(1/12) | ... O5: =N5*(1+Control!$C$7)^(1/12)
A6: BTC price (ZAR) | B6: ZAR/BTC | D6: =D5*Control!$C$4 | E6: =E5*Control!$C$4 | F6: =F5*Control!$C$4 | G6: =G5*Control!$C$4 | H6: =H5*Control!$C$4 | I6: =I5*Control!$C$4 | J6: =J5*Control!$C$4 | K6: =K5*Control!$C$4 | ... O6: =O5*Control!$C$4
A7: Network hash (TH/s) | B7: TH/s | D7: =Control!$C$8 | E7: =D7*(1+Control!$C$9)^(1/12) | F7: =E7*(1+Control!$C$9)^(1/12) | G7: =F7*(1+Control!$C$9)^(1/12) | H7: =G7*(1+Control!$C$9)^(1/12) | I7: =H7*(1+Control!$C$9)^(1/12) | J7: =I7*(1+Control!$C$9)^(1/12) | K7: =J7*(1+Control!$C$9)^(1/12) | L7: =K7*(1+Control!$C$9)^(1/12) | ... O7: =N7*(1+Control!$C$9)^(1/12)
A8: Network BTC mined | B8: BTC/month | D8: ='12M_Deployment'!D5*Control!$C$12*Control!$C$10*(1+Control!$C$11) | E8: ='12M_Deployment'!E5*Control!$C$12*Control!$C$10*(1+Control!$C$11) | F8: ='12M_Deployment'!F5*Control!$C$12*Control!$C$10*(1+Control!$C$11) | G8: ='12M_Deployment'!G5*Control!$C$12*Control!$C$10*(1+Control!$C$11) | H8: ='12M_Deployment'!H5*Control!$C$12*Control!$C$10*(1+Control!$C$11) | I8: ='12M_Deployment'!I5*Control!$C$12*Control!$C$10*(1+Control!$C$11) | J8: ='12M_Deployment'!J5*Control!$C$12*Control!$C$10*(1+Control!$C$11) | K8: ='12M_Deployment'!K5*Control!$C$12*Control!$C$10*(1+Control!$C$11) | ... O8: ='12M_Deployment'!O5*Control!$C$12*Control!$C$10*(1+Control!$C$11)
A10: Grootvlei BTC mined | B10: BTC/month | D10: ='12M_Deployment'!D58/D7*D8 | E10: ='12M_Deployment'!E58/E7*E8 | F10: ='12M_Deployment'!F58/F7*F8 | G10: ='12M_Deployment'!G58/G7*G8 | H10: ='12M_Deployment'!H58/H7*H8 | I10: ='12M_Deployment'!I58/I7*I8 | J10: ='12M_Deployment'!J58/J7*J8 | K10: ='12M_Deployment'!K58/K7*K8 | ... O10: ='12M_Deployment'!O58/O7*O8
A11: AMSA BTC mined | B11: BTC/month | D11: ='12M_Deployment'!D59/D7*D8 | E11: ='12M_Deployment'!E59/E7*E8 | F11: ='12M_Deployment'!F59/F7*F8 | G11: ='12M_Deployment'!G59/G7*G8 | H11: ='12M_Deployment'!H59/H7*H8 | I11: ='12M_Deployment'!I59/I7*I8 | J11: ='12M_Deployment'!J59/J7*J8 | K11: ='12M_Deployment'!K59/K7*K8 | ... O11: ='12M_Deployment'!O59/O7*O8
A12: Total BTC mined | B12: BTC/month | D12: =D10+D11 | E12: =E10+E11 | F12: =F10+F11 | G12: =G10+G11 | H12: =H10+H11 | I12: =I10+I11 | J12: =J10+J11 | K12: =K10+K11 | ... O12: =O10+O11
A13: BTC revenue | B13: ZAR'000 | D13: =D12*D6/1000 | E13: =E12*E6/1000 | F13: =F12*F6/1000 | G13: =G12*G6/1000 | H13: =H12*H6/1000 | I13: =I12*I6/1000 | J13: =J12*J6/1000 | K13: =K12*K6/1000 | ... O13: =O12*O6/1000
A15: Demand response revenue - base case | B15: ZAR'000 | D15: =IF(Control!$C$71=1,D16,0) | E15: =IF(Control!$C$71=1,E16,0) | F15: =IF(Control!$C$71=1,F16,0) | G15: =IF(Control!$C$71=1,G16,0) | H15: =IF(Control!$C$71=1,H16,0) | I15: =IF(Control!$C$71=1,I16,0) | J15: =IF(Control!$C$71=1,J16,0) | K15: =IF(Control!$C$71=1,K16,0) | ... O15: =IF(Control!$C$71=1,O16,0)
A16: Demand response revenue - upside | B16: ZAR'000 | D16: =IF(D$3>=Control!$C$72,'12M_Deployment'!D19*Control!$C$74*'12M_Deployment'!D5*Control!$C$75*Control!$C$73,0) | E16: =IF(E$3>=Control!$C$72,'12M_Deployment'!E19*Control!$C$74*'12M_Deployment'!E5*Control!$C$75*Control!$C$73,0) | F16: =IF(F$3>=Control!$C$72,'12M_Deployment'!F19*Control!$C$74*'12M_Deployment'!F5*Control!$C$75*Control!$C$73,0) | G16: =IF(G$3>=Control!$C$72,'12M_Deployment'!G19*Control!$C$74*'12M_Deployment'!G5*Control!$C$75*Control!$C$73,0) | H16: =IF(H$3>=Control!$C$72,'12M_Deployment'!H19*Control!$C$74*'12M_Deployment'!H5*Control!$C$75*Control!$C$73,0) | I16: =IF(I$3>=Control!$C$72,'12M_Deployment'!I19*Control!$C$74*'12M_Deployment'!I5*Control!$C$75*Control!$C$73,0) | J16: =IF(J$3>=Control!$C$72,'12M_Deployment'!J19*Control!$C$74*'12M_Deployment'!J5*Control!$C$75*Control!$C$73,0) | K16: =IF(K$3>=Control!$C$72,'12M_Deployment'!K19*Control!$C$74*'12M_Deployment'!K5*Control!$C$75*Control!$C$73,0) | ... O16: =IF(O$3>=Control!$C$72,'12M_Deployment'!O19*Control!$C$74*'12M_Deployment'!O5*Control!$C$75*Control!$C$73,0)
A18: Hyperscaler revenue - base case | B18: ZAR'000 | D18: =IF(Control!$C$76=1,D19,0) | E18: =IF(Control!$C$76=1,E19,0) | F18: =IF(Control!$C$76=1,F19,0) | G18: =IF(Control!$C$76=1,G19,0) | H18: =IF(Control!$C$76=1,H19,0) | I18: =IF(Control!$C$76=1,I19,0) | J18: =IF(Control!$C$76=1,J19,0) | K18: =IF(Control!$C$76=1,K19,0) | ... O18: =IF(Control!$C$76=1,O19,0)
A19: Hyperscaler revenue - upside | B19: ZAR'000 | D19: =IF(D$3>=Control!$C$77,Control!$C$78*Control!$C$79*'12M_Deployment'!D5*Control!$C$80*Control!$C$4/1000,0) | E19: =IF(E$3>=Control!$C$77,Control!$C$78*Control!$C$79*'12M_Deployment'!E5*Control!$C$80*Control!$C$4/1000,0) | F19: =IF(F$3>=Control!$C$77,Control!$C$78*Control!$C$79*'12M_Deployment'!F5*Control!$C$80*Control!$C$4/1000,0) | G19: =IF(G$3>=Control!$C$77,Control!$C$78*Control!$C$79*'12M_Deployment'!G5*Control!$C$80*Control!$C$4/1000,0) | H19: =IF(H$3>=Control!$C$77,Control!$C$78*Control!$C$79*'12M_Deployment'!H5*Control!$C$80*Control!$C$4/1000,0) | I19: =IF(I$3>=Control!$C$77,Control!$C$78*Control!$C$79*'12M_Deployment'!I5*Control!$C$80*Control!$C$4/1000,0) | J19: =IF(J$3>=Control!$C$77,Control!$C$78*Control!$C$79*'12M_Deployment'!J5*Control!$C$80*Control!$C$4/1000,0) | K19: =IF(K$3>=Control!$C$77,Control!$C$78*Control!$C$79*'12M_Deployment'!K5*Control!$C$80*Control!$C$4/1000,0) | ... O19: =IF(O$3>=Control!$C$77,Control!$C$78*Control!$C$79*'12M_Deployment'!O5*Control!$C$80*Control!$C$4/1000,0)
A21: Total revenue - base case | B21: ZAR'000 | D21: =D13+D15+D18 | E21: =E13+E15+E18 | F21: =F13+F15+F18 | G21: =G13+G15+G18 | H21: =H13+H15+H18 | I21: =I13+I15+I18 | J21: =J13+J15+J18 | K21: =K13+K15+K18 | ... O21: =O13+O15+O18
A22: Total revenue - with upside | B22: ZAR'000 | D22: =D13+D16+D19 | E22: =E13+E16+E19 | F22: =F13+F16+F19 | G22: =G13+G16+G19 | H22: =H13+H16+H19 | I22: =I13+I16+I19 | J22: =J13+J16+J19 | K22: =K13+K16+K19 | ... O22: =O13+O16+O19

Sheet 12M_Opex
A1: 12-Month Operating Cost Build
A2: Covers site energy cost, payroll, benefits, travel, software, legal, office, tools, security, insurance and utilities.
D3: 1 | E3: 2 | F3: 3 | G3: 4 | H3: 5 | I3: 6 | J3: 7 | K3: 8 | L3: 9 | M3: 10 | N3: 11 | O3: 12
D4: Jan-26 | E4: Feb-26 | F4: Mar-26 | G4: Apr-26 | H4: May-26 | I4: Jun-26 | J4: Jul-26 | K4: Aug-26 | L4: Sep-26 | M4: Oct-26 | N4: Nov-26 | O4: Dec-26
A5: Grootvlei electricity cost | B5: ZAR'000 | D5: ='12M_Deployment'!D62*Control!$C$25 | E5: ='12M_Deployment'!E62*Control!$C$25 | F5: ='12M_Deployment'!F62*Control!$C$25 | G5: ='12M_Deployment'!G62*Control!$C$25 | H5: ='12M_Deployment'!H62*Control!$C$25 | I5: ='12M_Deployment'!I62*Control!$C$25 | J5: ='12M_Deployment'!J62*Control!$C$25 | K5: ='12M_Deployment'!K62*Control!$C$25 | ... O5: ='12M_Deployment'!O62*Control!$C$25
A6: AMSA Eskom electricity cost | B6: ZAR'000 | D6: ='12M_Deployment'!D65*Control!$C$26 | E6: ='12M_Deployment'!E65*Control!$C$26 | F6: ='12M_Deployment'!F65*Control!$C$26 | G6: ='12M_Deployment'!G65*Control!$C$26 | H6: ='12M_Deployment'!H65*Control!$C$26 | I6: ='12M_Deployment'!I65*Control!$C$26 | J6: ='12M_Deployment'!J65*Control!$C$26 | K6: ='12M_Deployment'!K65*Control!$C$26 | ... O6: ='12M_Deployment'!O65*Control!$C$26
A7: AMSA solar O&M | B7: ZAR'000 | D7: ='12M_Deployment'!D18*Control!$C$27*Control!$C$28/12 | E7: ='12M_Deployment'!E18*Control!$C$27*Control!$C$28/12 | F7: ='12M_Deployment'!F18*Control!$C$27*Control!$C$28/12 | G7: ='12M_Deployment'!G18*Control!$C$27*Control!$C$28/12 | H7: ='12M_Deployment'!H18*Control!$C$27*Control!$C$28/12 | I7: ='12M_Deployment'!I18*Control!$C$27*Control!$C$28/12 | J7: ='12M_Deployment'!J18*Control!$C$27*Control!$C$28/12 | K7: ='12M_Deployment'!K18*Control!$C$27*Control!$C$28/12 | ... O7: ='12M_Deployment'!O18*Control!$C$27*Control!$C$28/12
A8: Total energy cost | B8: ZAR'000 | D8: =D5+D6+D7 | E8: =E5+E6+E7 | F8: =F5+F6+F7 | G8: =G5+G6+G7 | H8: =H5+H6+H7 | I8: =I5+I6+I7 | J8: =J5+J6+J7 | K8: =K5+K6+K7 | ... O8: =O5+O6+O7
A10: Corporate payroll | B10: ZAR'000 | D10: =Control!$C$52*Control!$C$53/12 | E10: =Control!$C$52*Control!$C$53/12 | F10: =Control!$C$52*Control!$C$53/12 | G10: =Control!$C$52*Control!$C$53/12 | H10: =Control!$C$52*Control!$C$53/12 | I10: =Control!$C$52*Control!$C$53/12 | J10: =Control!$C$52*Control!$C$53/12 | K10: =Control!$C$52*Control!$C$53/12 | ... O10: =Control!$C$52*Control!$C$53/12
A11: Site management payroll | B11: ZAR'000 | D11: ='12M_Deployment'!D28*Control!$C$54*Control!$C$55/12 | E11: ='12M_Deployment'!E28*Control!$C$54*Control!$C$55/12 | F11: ='12M_Deployment'!F28*Control!$C$54*Control!$C$55/12 | G11: ='12M_Deployment'!G28*Control!$C$54*Control!$C$55/12 | H11: ='12M_Deployment'!H28*Control!$C$54*Control!$C$55/12 | I11: ='12M_Deployment'!I28*Control!$C$54*Control!$C$55/12 | J11: ='12M_Deployment'!J28*Control!$C$54*Control!$C$55/12 | K11: ='12M_Deployment'!K28*Control!$C$54*Control!$C$55/12 | ... O11: ='12M_Deployment'!O28*Control!$C$54*Control!$C$55/12
A12: Technician payroll | B12: ZAR'000 | D12: ='12M_Deployment'!D19*Control!$C$56*Control!$C$57/12 | E12: ='12M_Deployment'!E19*Control!$C$56*Control!$C$57/12 | F12: ='12M_Deployment'!F19*Control!$C$56*Control!$C$57/12 | G12: ='12M_Deployment'!G19*Control!$C$56*Control!$C$57/12 | H12: ='12M_Deployment'!H19*Control!$C$56*Control!$C$57/12 | I12: ='12M_Deployment'!I19*Control!$C$56*Control!$C$57/12 | J12: ='12M_Deployment'!J19*Control!$C$56*Control!$C$57/12 | K12: ='12M_Deployment'!K19*Control!$C$56*Control!$C$57/12 | ... O12: ='12M_Deployment'!O19*Control!$C$56*Control!$C$57/12
A13: Electrician payroll | B13: ZAR'000 | D13: ='12M_Deployment'!D19*Control!$C$58*Control!$C$59/12 | E13: ='12M_Deployment'!E19*Control!$C$58*Control!$C$59/12 | F13: ='12M_Deployment'!F19*Control!$C$58*Control!$C$59/12 | G13: ='12M_Deployment'!G19*Control!$C$58*Control!$C$59/12 | H13: ='12M_Deployment'!H19*Control!$C$58*Control!$C$59/12 | I13: ='12M_Deployment'!I19*Control!$C$58*Control!$C$59/12 | J13: ='12M_Deployment'!J19*Control!$C$58*Control!$C$59/12 | K13: ='12M_Deployment'!K19*Control!$C$58*Control!$C$59/12 | ... O13: ='12M_Deployment'!O19*Control!$C$58*Control!$C$59/12
A14: Gross payroll | B14: ZAR'000 | D14: =SUM(D10:D13) | E14: =SUM(E10:E13) | F14: =SUM(F10:F13) | G14: =SUM(G10:G13) | H14: =SUM(H10:H13) | I14: =SUM(I10:I13) | J14: =SUM(J10:J13) | K14: =SUM(K10:K13) | ... O14: =SUM(O10:O13)
A15: Benefits | B15: ZAR'000 | D15: =D14*Control!$C$60 | E15: =E14*Control!$C$60 | F15: =F14*Control!$C$60 | G15: =G14*Control!$C$60 | H15: =H14*Control!$C$60 | I15: =I14*Control!$C$60 | J15: =J14*Control!$C$60 | K15: =K14*Control!$C$60 | ... O15: =O14*Control!$C$60
A16: Salaries & benefits | B16: ZAR'000 | D16: =D14+D15 | E16: =E14+E15 | F16: =F14+F15 | G16: =G14+G15 | H16: =H14+H15 | I16: =I14+I15 | J16: =J14+J15 | K16: =K14+K15 | ... O16: =O14+O15
A17: Travel / accommodation | B17: ZAR'000 | D17: =D14*Control!$C$61+'12M_Deployment'!D32*Control!$C$62 | E17: =E14*Control!$C$61+'12M_Deployment'!E32*Control!$C$62 | F17: =F14*Control!$C$61+'12M_Deployment'!F32*Control!$C$62 | G17: =G14*Control!$C$61+'12M_Deployment'!G32*Control!$C$62 | H17: =H14*Control!$C$61+'12M_Deployment'!H32*Control!$C$62 | I17: =I14*Control!$C$61+'12M_Deployment'!I32*Control!$C$62 | J17: =J14*Control!$C$61+'12M_Deployment'!J32*Control!$C$62 | K17: =K14*Control!$C$61+'12M_Deployment'!K32*Control!$C$62 | ... O17: =O14*Control!$C$61+'12M_Deployment'!O32*Control!$C$62
A18: Software / storage / monitoring | B18: ZAR'000 | D18: ='12M_Deployment'!D49*Control!$C$63+'12M_Deployment'!D28*Control!$C$64+Control!$C$67 | E18: ='12M_Deployment'!E49*Control!$C$63+'12M_Deployment'!E28*Control!$C$64+Control!$C$67 | F18: ='12M_Deployment'!F49*Control!$C$63+'12M_Deployment'!F28*Control!$C$64+Control!$C$67 | G18: ='12M_Deployment'!G49*Control!$C$63+'12M_Deployment'!G28*Control!$C$64+Control!$C$67 | H18: ='12M_Deployment'!H49*Control!$C$63+'12M_Deployment'!H28*Control!$C$64+Control!$C$67 | I18: ='12M_Deployment'!I49*Control!$C$63+'12M_Deployment'!I28*Control!$C$64+Control!$C$67 | J18: ='12M_Deployment'!J49*Control!$C$63+'12M_Deployment'!J28*Control!$C$64+Control!$C$67 | K18: ='12M_Deployment'!K49*Control!$C$63+'12M_Deployment'!K28*Control!$C$64+Control!$C$67 | ... O18: ='12M_Deployment'!O49*Control!$C$63+'12M_Deployment'!O28*Control!$C$64+Control!$C$67
A19: Legal fees | B19: ZAR'000 | D19: =Control!$C$65 | E19: =Control!$C$65 | F19: =Control!$C$65 | G19: =Control!$C$65 | H19: =Control!$C$65 | I19: =Control!$C$65 | J19: =Control!$C$65 | K19: =Control!$C$65 | ... O19: =Control!$C$65
A20: Office rent | B20: ZAR'000 | D20: =Control!$C$66 | E20: =Control!$C$66 | F20: =Control!$C$66 | G20: =Control!$C$66 | H20: =Control!$C$66 | I20: =Control!$C$66 | J20: =Control!$C$66 | K20: =Control!$C$66 | ... O20: =Control!$C$66
A21: Tools / consumables recurring | B21: ZAR'000 | D21: ='12M_Deployment'!D19*Control!$C$68 | E21: ='12M_Deployment'!E19*Control!$C$68 | F21: ='12M_Deployment'!F19*Control!$C$68 | G21: ='12M_Deployment'!G19*Control!$C$68 | H21: ='12M_Deployment'!H19*Control!$C$68 | I21: ='12M_Deployment'!I19*Control!$C$68 | J21: ='12M_Deployment'!J19*Control!$C$68 | K21: ='12M_Deployment'!K19*Control!$C$68 | ... O21: ='12M_Deployment'!O19*Control!$C$68
A22: Security & operating insurance | B22: ZAR'000 | D22: ='12M_Deployment'!D28*Control!$C$69 | E22: ='12M_Deployment'!E28*Control!$C$69 | F22: ='12M_Deployment'!F28*Control!$C$69 | G22: ='12M_Deployment'!G28*Control!$C$69 | H22: ='12M_Deployment'!H28*Control!$C$69 | I22: ='12M_Deployment'!I28*Control!$C$69 | J22: ='12M_Deployment'!J28*Control!$C$69 | K22: ='12M_Deployment'!K28*Control!$C$69 | ... O22: ='12M_Deployment'!O28*Control!$C$69
A23: Other utilities / water | B23: ZAR'000 | D23: ='12M_Deployment'!D19*Control!$C$70 | E23: ='12M_Deployment'!E19*Control!$C$70 | F23: ='12M_Deployment'!F19*Control!$C$70 | G23: ='12M_Deployment'!G19*Control!$C$70 | H23: ='12M_Deployment'!H19*Control!$C$70 | I23: ='12M_Deployment'!I19*Control!$C$70 | J23: ='12M_Deployment'!J19*Control!$C$70 | K23: ='12M_Deployment'!K19*Control!$C$70 | ... O23: ='12M_Deployment'!O19*Control!$C$70
A24: Total cash opex | B24: ZAR'000 | D24: =SUM(D8,D16:D23) | E24: =SUM(E8,E16:E23) | F24: =SUM(F8,F16:F23) | G24: =SUM(G8,G16:G23) | H24: =SUM(H8,H16:H23) | I24: =SUM(I8,I16:I23) | J24: =SUM(J8,J16:J23) | K24: =SUM(K8,K16:K23) | ... O24: =SUM(O8,O16:O23)
A25: EBITDA - base case | B25: ZAR'000 | D25: ='12M_Revenue'!D21-D24 | E25: ='12M_Revenue'!E21-E24 | F25: ='12M_Revenue'!F21-F24 | G25: ='12M_Revenue'!G21-G24 | H25: ='12M_Revenue'!H21-H24 | I25: ='12M_Revenue'!I21-I24 | J25: ='12M_Revenue'!J21-J24 | K25: ='12M_Revenue'!K21-K24 | ... O25: ='12M_Revenue'!O21-O24
A26: EBITDA - with upside | B26: ZAR'000 | D26: ='12M_Revenue'!D22-D24 | E26: ='12M_Revenue'!E22-E24 | F26: ='12M_Revenue'!F22-F24 | G26: ='12M_Revenue'!G22-G24 | H26: ='12M_Revenue'!H22-H24 | I26: ='12M_Revenue'!I22-I24 | J26: ='12M_Revenue'!J22-J24 | K26: ='12M_Revenue'!K22-K24 | ... O26: ='12M_Revenue'!O22-O24

Sheet 12M_Capex
A1: 12-Month Capex & Deployment Spend
A2: This sheet now pulls detailed electrical EPC and miner vendor finance logic from dedicated tabs. Edit a few assumptions in Control and the full cash-timing logic updates.
D3: 1 | E3: 2 | F3: 3 | G3: 4 | H3: 5 | I3: 6 | J3: 7 | K3: 8 | L3: 9 | M3: 10 | N3: 11 | O3: 12
D4: Jan-26 | E4: Feb-26 | F4: Mar-26 | G4: Apr-26 | H4: May-26 | I4: Jun-26 | J4: Jul-26 | K4: Aug-26 | L4: Sep-26 | M4: Oct-26 | N4: Nov-26 | O4: Dec-26
A5: New MW commissioned | B5: MW | D5: ='12M_Deployment'!D24 | E5: ='12M_Deployment'!E24 | F5: ='12M_Deployment'!F24 | G5: ='12M_Deployment'!G24 | H5: ='12M_Deployment'!H24 | I5: ='12M_Deployment'!I24 | J5: ='12M_Deployment'!J24 | K5: ='12M_Deployment'!K24 | ... O5: ='12M_Deployment'!O24
A6: New containers commissioned | B6: containers | D6: ='12M_Deployment'!D44 | E6: ='12M_Deployment'!E44 | F6: ='12M_Deployment'!F44 | G6: ='12M_Deployment'!G44 | H6: ='12M_Deployment'!H44 | I6: ='12M_Deployment'!I44 | J6: ='12M_Deployment'!J44 | K6: ='12M_Deployment'!K44 | ... O6: ='12M_Deployment'!O44
A7: New solar MW | B7: MW | D7: ='12M_Deployment'!D23 | E7: ='12M_Deployment'!E23 | F7: ='12M_Deployment'!F23 | G7: ='12M_Deployment'!G23 | H7: ='12M_Deployment'!H23 | I7: ='12M_Deployment'!I23 | J7: ='12M_Deployment'!J23 | K7: ='12M_Deployment'!K23 | ... O7: ='12M_Deployment'!O23
A8: New FTE onboarded | B8: FTE | D8: ='12M_Deployment'!D52 | E8: ='12M_Deployment'!E52 | F8: ='12M_Deployment'!F52 | G8: ='12M_Deployment'!G52 | H8: ='12M_Deployment'!H52 | I8: ='12M_Deployment'!I52 | J8: ='12M_Deployment'!J52 | K8: ='12M_Deployment'!K52 | ... O8: ='12M_Deployment'!O52
A10: ASIC hardware capex basis | B10: ZAR'000 | D10: =('12M_Deployment'!D24/(1+Control!$C$34))*1000000/Control!$C$32*Control!$C$33*Control!$C$4/1000 | E10: =('12M_Deployment'!E24/(1+Control!$C$34))*1000000/Control!$C$32*Control!$C$33*Control!$C$4/1000 | F10: =('12M_Deployment'!F24/(1+Control!$C$34))*1000000/Control!$C$32*Control!$C$33*Control!$C$4/1000 | G10: =('12M_Deployment'!G24/(1+Control!$C$34))*1000000/Control!$C$32*Control!$C$33*Control!$C$4/1000 | H10: =('12M_Deployment'!H24/(1+Control!$C$34))*1000000/Control!$C$32*Control!$C$33*Control!$C$4/1000 | I10: =('12M_Deployment'!I24/(1+Control!$C$34))*1000000/Control!$C$32*Control!$C$33*Control!$C$4/1000 | J10: =('12M_Deployment'!J24/(1+Control!$C$34))*1000000/Control!$C$32*Control!$C$33*Control!$C$4/1000 | K10: =('12M_Deployment'!K24/(1+Control!$C$34))*1000000/Control!$C$32*Control!$C$33*Control!$C$4/1000 | ... O10: =('12M_Deployment'!O24/(1+Control!$C$34))*1000000/Control!$C$32*Control!$C$33*Control!$C$4/1000
A11: Hydro container capex basis | B11: ZAR'000 | D11: ='12M_Deployment'!D44*Control!$C$36*Control!$C$4/1000 | E11: ='12M_Deployment'!E44*Control!$C$36*Control!$C$4/1000 | F11: ='12M_Deployment'!F44*Control!$C$36*Control!$C$4/1000 | G11: ='12M_Deployment'!G44*Control!$C$36*Control!$C$4/1000 | H11: ='12M_Deployment'!H44*Control!$C$36*Control!$C$4/1000 | I11: ='12M_Deployment'!I44*Control!$C$36*Control!$C$4/1000 | J11: ='12M_Deployment'!J44*Control!$C$36*Control!$C$4/1000 | K11: ='12M_Deployment'!K44*Control!$C$36*Control!$C$4/1000 | ... O11: ='12M_Deployment'!O44*Control!$C$36*Control!$C$4/1000
A12: Electrical EPC basis (fixed/site + variable/MW) | B12: ZAR'000 | D12: ='12M_Deployment'!D32*CAPEX_Electrical_Detail!$C$26+'12M_Deployment'!D24*CAPEX_Electrical_Detail!$C$27 | E12: ='12M_Deployment'!E32*CAPEX_Electrical_Detail!$C$26+'12M_Deployment'!E24*CAPEX_Electrical_Detail!$C$27 | F12: ='12M_Deployment'!F32*CAPEX_Electrical_Detail!$C$26+'12M_Deployment'!F24*CAPEX_Electrical_Detail!$C$27 | G12: ='12M_Deployment'!G32*CAPEX_Electrical_Detail!$C$26+'12M_Deployment'!G24*CAPEX_Electrical_Detail!$C$27 | H12: ='12M_Deployment'!H32*CAPEX_Electrical_Detail!$C$26+'12M_Deployment'!H24*CAPEX_Electrical_Detail!$C$27 | I12: ='12M_Deployment'!I32*CAPEX_Electrical_Detail!$C$26+'12M_Deployment'!I24*CAPEX_Electrical_Detail!$C$27 | J12: ='12M_Deployment'!J32*CAPEX_Electrical_Detail!$C$26+'12M_Deployment'!J24*CAPEX_Electrical_Detail!$C$27 | K12: ='12M_Deployment'!K32*CAPEX_Electrical_Detail!$C$26+'12M_Deployment'!K24*CAPEX_Electrical_Detail!$C$27 | ... O12: ='12M_Deployment'!O32*CAPEX_Electrical_Detail!$C$26+'12M_Deployment'!O24*CAPEX_Electrical_Detail!$C$27
A13: Solar PV capex basis | B13: ZAR'000 | D13: ='12M_Deployment'!D23*Control!$C$27 | E13: ='12M_Deployment'!E23*Control!$C$27 | F13: ='12M_Deployment'!F23*Control!$C$27 | G13: ='12M_Deployment'!G23*Control!$C$27 | H13: ='12M_Deployment'!H23*Control!$C$27 | I13: ='12M_Deployment'!I23*Control!$C$27 | J13: ='12M_Deployment'!J23*Control!$C$27 | K13: ='12M_Deployment'!K23*Control!$C$27 | ... O13: ='12M_Deployment'!O23*Control!$C$27
A14: Initial spare parts basis | B14: ZAR'000 | D14: =D10*Control!$C$46 | E14: =E10*Control!$C$46 | F14: =F10*Control!$C$46 | G14: =G10*Control!$C$46 | H14: =H10*Control!$C$46 | I14: =I10*Control!$C$46 | J14: =J10*Control!$C$46 | K14: =K10*Control!$C$46 | ... O14: =O10*Control!$C$46
A15: Tools/equipment initial basis | B15: ZAR'000 | D15: ='12M_Deployment'!D32*Control!$C$47 | E15: ='12M_Deployment'!E32*Control!$C$47 | F15: ='12M_Deployment'!F32*Control!$C$47 | G15: ='12M_Deployment'!G32*Control!$C$47 | H15: ='12M_Deployment'!H32*Control!$C$47 | I15: ='12M_Deployment'!I32*Control!$C$47 | J15: ='12M_Deployment'!J32*Control!$C$47 | K15: ='12M_Deployment'!K32*Control!$C$47 | ... O15: ='12M_Deployment'!O32*Control!$C$47
A16: Staff hardware basis | B16: ZAR'000 | D16: ='12M_Deployment'!D52*Control!$C$51 | E16: ='12M_Deployment'!E52*Control!$C$51 | F16: ='12M_Deployment'!F52*Control!$C$51 | G16: ='12M_Deployment'!G52*Control!$C$51 | H16: ='12M_Deployment'!H52*Control!$C$51 | I16: ='12M_Deployment'!I52*Control!$C$51 | J16: ='12M_Deployment'!J52*Control!$C$51 | K16: ='12M_Deployment'!K52*Control!$C$51 | ... O16: ='12M_Deployment'!O52*Control!$C$51
A17: Freight basis | B17: ZAR'000 | D17: ='12M_Deployment'!D44*Control!$C$40*Control!$C$4/1000 | E17: ='12M_Deployment'!E44*Control!$C$40*Control!$C$4/1000 | F17: ='12M_Deployment'!F44*Control!$C$40*Control!$C$4/1000 | G17: ='12M_Deployment'!G44*Control!$C$40*Control!$C$4/1000 | H17: ='12M_Deployment'!H44*Control!$C$40*Control!$C$4/1000 | I17: ='12M_Deployment'!I44*Control!$C$40*Control!$C$4/1000 | J17: ='12M_Deployment'!J44*Control!$C$40*Control!$C$4/1000 | K17: ='12M_Deployment'!K44*Control!$C$40*Control!$C$4/1000 | ... O17: ='12M_Deployment'!O44*Control!$C$40*Control!$C$4/1000
A18: Port/clearing basis | B18: ZAR'000 | D18: ='12M_Deployment'!D44*Control!$C$41 | E18: ='12M_Deployment'!E44*Control!$C$41 | F18: ='12M_Deployment'!F44*Control!$C$41 | G18: ='12M_Deployment'!G44*Control!$C$41 | H18: ='12M_Deployment'!H44*Control!$C$41 | I18: ='12M_Deployment'!I44*Control!$C$41 | J18: ='12M_Deployment'!J44*Control!$C$41 | K18: ='12M_Deployment'!K44*Control!$C$41 | ... O18: ='12M_Deployment'!O44*Control!$C$41
A19: Inland trucking basis | B19: ZAR'000 | D19: ='12M_Deployment'!D44*Control!$C$42 | E19: ='12M_Deployment'!E44*Control!$C$42 | F19: ='12M_Deployment'!F44*Control!$C$42 | G19: ='12M_Deployment'!G44*Control!$C$42 | H19: ='12M_Deployment'!H44*Control!$C$42 | I19: ='12M_Deployment'!I44*Control!$C$42 | J19: ='12M_Deployment'!J44*Control!$C$42 | K19: ='12M_Deployment'!K44*Control!$C$42 | ... O19: ='12M_Deployment'!O44*Control!$C$42
A20: Crane/rigging basis | B20: ZAR'000 | D20: ='12M_Deployment'!D44*Control!$C$43 | E20: ='12M_Deployment'!E44*Control!$C$43 | F20: ='12M_Deployment'!F44*Control!$C$43 | G20: ='12M_Deployment'!G44*Control!$C$43 | H20: ='12M_Deployment'!H44*Control!$C$43 | I20: ='12M_Deployment'!I44*Control!$C$43 | J20: ='12M_Deployment'!J44*Control!$C$43 | K20: ='12M_Deployment'!K44*Control!$C$43 | ... O20: ='12M_Deployment'!O44*Control!$C$43
A21: Cargo insurance basis | B21: ZAR'000 | D21: =(D10+D11)*Control!$C$44 | E21: =(E10+E11)*Control!$C$44 | F21: =(F10+F11)*Control!$C$44 | G21: =(G10+G11)*Control!$C$44 | H21: =(H10+H11)*Control!$C$44 | I21: =(I10+I11)*Control!$C$44 | J21: =(J10+J11)*Control!$C$44 | K21: =(K10+K11)*Control!$C$44 | ... O21: =(O10+O11)*Control!$C$44
A22: Import duty basis | B22: ZAR'000 | D22: =(D10+D11)*Control!$C$45 | E22: =(E10+E11)*Control!$C$45 | F22: =(F10+F11)*Control!$C$45 | G22: =(G10+G11)*Control!$C$45 | H22: =(H10+H11)*Control!$C$45 | I22: =(I10+I11)*Control!$C$45 | J22: =(J10+J11)*Control!$C$45 | K22: =(K10+K11)*Control!$C$45 | ... O22: =(O10+O11)*Control!$C$45
A23: Office/software/legal setup basis | B23: ZAR'000 | D23: =IF(D$3=1,Control!$C$48+Control!$C$49+Control!$C$50,0) | E23: =IF(E$3=1,Control!$C$48+Control!$C$49+Control!$C$50,0) | F23: =IF(F$3=1,Control!$C$48+Control!$C$49+Control!$C$50,0) | G23: =IF(G$3=1,Control!$C$48+Control!$C$49+Control!$C$50,0) | H23: =IF(H$3=1,Control!$C$48+Control!$C$49+Control!$C$50,0) | I23: =IF(I$3=1,Control!$C$48+Control!$C$49+Control!$C$50,0) | J23: =IF(J$3=1,Control!$C$48+Control!$C$49+Control!$C$50,0) | K23: =IF(K$3=1,Control!$C$48+Control!$C$49+Control!$C$50,0) | ... O23: =IF(O$3=1,Control!$C$48+Control!$C$49+Control!$C$50,0)
A26: ASIC hardware cash spend (deposit + vendor installments) | B26: ZAR'000 | D26: ='12M_Miner_Vendor'!D14 | E26: ='12M_Miner_Vendor'!E14 | F26: ='12M_Miner_Vendor'!F14 | G26: ='12M_Miner_Vendor'!G14 | H26: ='12M_Miner_Vendor'!H14 | I26: ='12M_Miner_Vendor'!I14 | J26: ='12M_Miner_Vendor'!J14 | K26: ='12M_Miner_Vendor'!K14 | ... O26: ='12M_Miner_Vendor'!O14
A27: Hydro container cash spend (editable staged terms) | B27: ZAR'000 | D27: =IFERROR(OFFSET(D11,0,Control!$C$117)*Control!$C$118,0)+IF(Control!$C$117>0,IFERROR(OFFSET(D11,0,Control!$C$117-1)*Control!$C$119,0),0)+D11*Control!$C$120 | E27: =IFERROR(OFFSET(E11,0,Control!$C$117)*Control!$C$118,0)+IF(Control!$C$117>0,IFERROR(OFFSET(E11,0,Control!$C$117-1)*Control!$C$119,0),0)+E11*Control!$C$120 | F27: =IFERROR(OFFSET(F11,0,Control!$C$117)*Control!$C$118,0)+IF(Control!$C$117>0,IFERROR(OFFSET(F11,0,Control!$C$117-1)*Control!$C$119,0),0)+F11*Control!$C$120 | G27: =IFERROR(OFFSET(G11,0,Control!$C$117)*Control!$C$118,0)+IF(Control!$C$117>0,IFERROR(OFFSET(G11,0,Control!$C$117-1)*Control!$C$119,0),0)+G11*Control!$C$120 | H27: =IFERROR(OFFSET(H11,0,Control!$C$117)*Control!$C$118,0)+IF(Control!$C$117>0,IFERROR(OFFSET(H11,0,Control!$C$117-1)*Control!$C$119,0),0)+H11*Control!$C$120 | I27: =IFERROR(OFFSET(I11,0,Control!$C$117)*Control!$C$118,0)+IF(Control!$C$117>0,IFERROR(OFFSET(I11,0,Control!$C$117-1)*Control!$C$119,0),0)+I11*Control!$C$120 | J27: =IFERROR(OFFSET(J11,0,Control!$C$117)*Control!$C$118,0)+IF(Control!$C$117>0,IFERROR(OFFSET(J11,0,Control!$C$117-1)*Control!$C$119,0),0)+J11*Control!$C$120 | K27: =IFERROR(OFFSET(K11,0,Control!$C$117)*Control!$C$118,0)+IF(Control!$C$117>0,IFERROR(OFFSET(K11,0,Control!$C$117-1)*Control!$C$119,0),0)+K11*Control!$C$120 | ... O27: =IFERROR(OFFSET(O11,0,Control!$C$117)*Control!$C$118,0)+IF(Control!$C$117>0,IFERROR(OFFSET(O11,0,Control!$C$117-1)*Control!$C$119,0),0)+O11*Control!$C$120
A28: Electrical EPC cash spend (tranches + financed retention) | B28: ZAR'000 | D28: ='12M_EPC_Tranches'!D14 | E28: ='12M_EPC_Tranches'!E14 | F28: ='12M_EPC_Tranches'!F14 | G28: ='12M_EPC_Tranches'!G14 | H28: ='12M_EPC_Tranches'!H14 | I28: ='12M_EPC_Tranches'!I14 | J28: ='12M_EPC_Tranches'!J14 | K28: ='12M_EPC_Tranches'!K14 | ... O28: ='12M_EPC_Tranches'!O14
A29: Solar PV cash spend | B29: ZAR'000 | D29: =0.2*F13+0.5*E13+0.3*D13 | E29: =0.2*G13+0.5*F13+0.3*E13 | F29: =0.2*H13+0.5*G13+0.3*F13 | G29: =0.2*I13+0.5*H13+0.3*G13 | H29: =0.2*J13+0.5*I13+0.3*H13 | I29: =0.2*K13+0.5*J13+0.3*I13 | J29: =0.2*L13+0.5*K13+0.3*J13 | K29: =0.2*M13+0.5*L13+0.3*K13 | ... M29: =0.2*O13+0.5*N13+0.3*M13 | N29: =0.5*O13+0.3*N13 | O29: =0.3*O13
A30: Initial spare parts cash spend | B30: ZAR'000 | D30: =D14 | E30: =E14 | F30: =F14 | G30: =G14 | H30: =H14 | I30: =I14 | J30: =J14 | K30: =K14 | ... O30: =O14
A31: Tools/equipment initial cash spend | B31: ZAR'000 | D31: =D15 | E31: =E15 | F31: =F15 | G31: =G15 | H31: =H15 | I31: =I15 | J31: =J15 | K31: =K15 | ... O31: =O15
A32: Staff hardware cash spend | B32: ZAR'000 | D32: =D16 | E32: =E16 | F32: =F16 | G32: =G16 | H32: =H16 | I32: =I16 | J32: =J16 | K32: =K16 | ... O32: =O16
A33: Freight cash spend | B33: ZAR'000 | D33: =E17 | E33: =F17 | F33: =G17 | G33: =H17 | H33: =I17 | I33: =J17 | J33: =K17 | K33: =L17 | ... N33: =O17 | O33: 0
A34: Port/clearing cash spend | B34: ZAR'000 | D34: =E18 | E34: =F18 | F34: =G18 | G34: =H18 | H34: =I18 | I34: =J18 | J34: =K18 | K34: =L18 | ... N34: =O18 | O34: 0
A35: Inland trucking cash spend | B35: ZAR'000 | D35: =E19 | E35: =F19 | F35: =G19 | G35: =H19 | H35: =I19 | I35: =J19 | J35: =K19 | K35: =L19 | ... N35: =O19 | O35: 0
A36: Crane/rigging cash spend | B36: ZAR'000 | D36: =D20 | E36: =E20 | F36: =F20 | G36: =G20 | H36: =H20 | I36: =I20 | J36: =J20 | K36: =K20 | ... O36: =O20
A37: Cargo insurance cash spend | B37: ZAR'000 | D37: =E21 | E37: =F21 | F37: =G21 | G37: =H21 | H37: =I21 | I37: =J21 | J37: =K21 | K37: =L21 | ... N37: =O21 | O37: 0
A38: Import duty cash spend | B38: ZAR'000 | D38: =E22 | E38: =F22 | F38: =G22 | G38: =H22 | H38: =I22 | I38: =J22 | J38: =K22 | K38: =L22 | ... N38: =O22 | O38: 0
A39: Office/software/legal setup cash spend | B39: ZAR'000 | D39: =D23 | E39: =E23 | F39: =F23 | G39: =G23 | H39: =H23 | I39: =I23 | J39: =J23 | K39: =K23 | ... O39: =O23
A40: Total capex cash spend | B40: ZAR'000 | D40: =SUM(D26:D39) | E40: =SUM(E26:E39) | F40: =SUM(F26:F39) | G40: =SUM(G26:G39) | H40: =SUM(H26:H39) | I40: =SUM(I26:I39) | J40: =SUM(J26:J39) | K40: =SUM(K26:K39) | ... O40: =SUM(O26:O39)
A41: Cumulative capex spend | B41: ZAR'000 | D41: =D40 | E41: =D41+E40 | F41: =E41+F40 | G41: =F41+G40 | H41: =G41+H40 | I41: =H41+I40 | J41: =I41+J40 | K41: =J41+K40 | L41: =K41+L40 | ... O41: =N41+O40

Sheet 12M_Miner_Vendor
A1: 12-Month Miner Commercial Schedule
A2: Uses M7DS technical / price assumptions from the model, and applies supplier-style payment mechanics from the attached contract as a placeholder until a final M7DS-specific term sheet is inserted.
D3: 1 | E3: 2 | F3: 3 | G3: 4 | H3: 5 | I3: 6 | J3: 7 | K3: 8 | L3: 9 | M3: 10 | N3: 11 | O3: 12
D4: ='12M_Deployment'!D4 | E4: ='12M_Deployment'!E4 | F4: ='12M_Deployment'!F4 | G4: ='12M_Deployment'!G4 | H4: ='12M_Deployment'!H4 | I4: ='12M_Deployment'!I4 | J4: ='12M_Deployment'!J4 | K4: ='12M_Deployment'!K4 | ... O4: ='12M_Deployment'!O4
A5: New MW commissioned | B5: MW | D5: ='12M_Deployment'!D24 | E5: ='12M_Deployment'!E24 | F5: ='12M_Deployment'!F24 | G5: ='12M_Deployment'!G24 | H5: ='12M_Deployment'!H24 | I5: ='12M_Deployment'!I24 | J5: ='12M_Deployment'!J24 | K5: ='12M_Deployment'!K24 | ... O5: ='12M_Deployment'!O24
A6: Gross hardware capex basis | B6: ZAR'000 | D6: =(D5/(1+Control!$C$34))*1000000/Control!$C$32*Control!$C$33*Control!$C$4/1000 | E6: =(E5/(1+Control!$C$34))*1000000/Control!$C$32*Control!$C$33*Control!$C$4/1000 | F6: =(F5/(1+Control!$C$34))*1000000/Control!$C$32*Control!$C$33*Control!$C$4/1000 | G6: =(G5/(1+Control!$C$34))*1000000/Control!$C$32*Control!$C$33*Control!$C$4/1000 | H6: =(H5/(1+Control!$C$34))*1000000/Control!$C$32*Control!$C$33*Control!$C$4/1000 | I6: =(I5/(1+Control!$C$34))*1000000/Control!$C$32*Control!$C$33*Control!$C$4/1000 | J6: =(J5/(1+Control!$C$34))*1000000/Control!$C$32*Control!$C$33*Control!$C$4/1000 | K6: =(K5/(1+Control!$C$34))*1000000/Control!$C$32*Control!$C$33*Control!$C$4/1000 | ... O6: =(O5/(1+Control!$C$34))*1000000/Control!$C$32*Control!$C$33*Control!$C$4/1000
A7: New miners commissioned | B7: miners | D7: =(D5/(1+Control!$C$34))*1000000/Control!$C$32 | E7: =(E5/(1+Control!$C$34))*1000000/Control!$C$32 | F7: =(F5/(1+Control!$C$34))*1000000/Control!$C$32 | G7: =(G5/(1+Control!$C$34))*1000000/Control!$C$32 | H7: =(H5/(1+Control!$C$34))*1000000/Control!$C$32 | I7: =(I5/(1+Control!$C$34))*1000000/Control!$C$32 | J7: =(J5/(1+Control!$C$34))*1000000/Control!$C$32 | K7: =(K5/(1+Control!$C$34))*1000000/Control!$C$32 | ... O7: =(O5/(1+Control!$C$34))*1000000/Control!$C$32
A9: Deposit cash due | B9: ZAR'000 | D9: =IFERROR(OFFSET(D6,0,Control!$C$97)*Control!$C$98,0) | E9: =IFERROR(OFFSET(E6,0,Control!$C$97)*Control!$C$98,0) | F9: =IFERROR(OFFSET(F6,0,Control!$C$97)*Control!$C$98,0) | G9: =IFERROR(OFFSET(G6,0,Control!$C$97)*Control!$C$98,0) | H9: =IFERROR(OFFSET(H6,0,Control!$C$97)*Control!$C$98,0) | I9: =IFERROR(OFFSET(I6,0,Control!$C$97)*Control!$C$98,0) | J9: =IFERROR(OFFSET(J6,0,Control!$C$97)*Control!$C$98,0) | K9: =IFERROR(OFFSET(K6,0,Control!$C$97)*Control!$C$98,0) | ... O9: =IFERROR(OFFSET(O6,0,Control!$C$97)*Control!$C$98,0)
A10: Vendor-financed principal originated | B10: ZAR'000 | D10: =D6*Control!$C$99 | E10: =E6*Control!$C$99 | F10: =F6*Control!$C$99 | G10: =G6*Control!$C$99 | H10: =H6*Control!$C$99 | I10: =I6*Control!$C$99 | J10: =J6*Control!$C$99 | K10: =K6*Control!$C$99 | ... O10: =O6*Control!$C$99
A11: Opening vendor payable | B11: ZAR'000 | D11: =0 | E11: =D15 | F11: =E15 | G11: =F15 | H11: =G15 | I11: =H15 | J11: =I15 | K11: =J15 | L11: =K15 | ... O11: =N15
A12: Scheduled principal | B12: ZAR'000 | D12: =SUM(D20:D31) | E12: =SUM(E20:E31) | F12: =SUM(F20:F31) | G12: =SUM(G20:G31) | H12: =SUM(H20:H31) | I12: =SUM(I20:I31) | J12: =SUM(J20:J31) | K12: =SUM(K20:K31) | ... O12: =SUM(O20:O31)
A13: Scheduled interest | B13: ZAR'000 | D13: =SUM(D35:D46) | E13: =SUM(E35:E46) | F13: =SUM(F35:F46) | G13: =SUM(G35:G46) | H13: =SUM(H35:H46) | I13: =SUM(I35:I46) | J13: =SUM(J35:J46) | K13: =SUM(K35:K46) | ... O13: =SUM(O35:O46)
A14: Total hardware cash payment | B14: ZAR'000 | D14: =D9+D12+D13 | E14: =E9+E12+E13 | F14: =F9+F12+F13 | G14: =G9+G12+G13 | H14: =H9+H12+H13 | I14: =I9+I12+I13 | J14: =J9+J12+J13 | K14: =K9+K12+K13 | ... O14: =O9+O12+O13
A15: Closing vendor payable | B15: ZAR'000 | D15: =D11+D10-D12 | E15: =E11+E10-E12 | F15: =F11+F10-F12 | G15: =G11+G10-G12 | H15: =H11+H10-H12 | I15: =I11+I10-I12 | J15: =J11+J10-J12 | K15: =K11+K10-K12 | ... O15: =O11+O10-O12
A17: Principal by origination month
A18: Origin month | B18: Source tranche | D18: Month 1 | E18: Month 2 | F18: Month 3 | G18: Month 4 | H18: Month 5 | I18: Month 6 | J18: Month 7 | K18: Month 8 | L18: Month 9 | M18: Month 10 | N18: Month 11 | O18: Month 12
A20: Origin 1 | B20: =D4 | D20: =IF(AND(D$3>=D$3,D$3<D$3+Control!$C$100),D$10/Control!$C$100,0) | E20: =IF(AND(E$3>=D$3,E$3<D$3+Control!$C$100),D$10/Control!$C$100,0) | F20: =IF(AND(F$3>=D$3,F$3<D$3+Control!$C$100),D$10/Control!$C$100,0) | G20: =IF(AND(G$3>=D$3,G$3<D$3+Control!$C$100),D$10/Control!$C$100,0) | H20: =IF(AND(H$3>=D$3,H$3<D$3+Control!$C$100),D$10/Control!$C$100,0) | I20: =IF(AND(I$3>=D$3,I$3<D$3+Control!$C$100),D$10/Control!$C$100,0) | J20: =IF(AND(J$3>=D$3,J$3<D$3+Control!$C$100),D$10/Control!$C$100,0) | K20: =IF(AND(K$3>=D$3,K$3<D$3+Control!$C$100),D$10/Control!$C$100,0) | L20: =IF(AND(L$3>=D$3,L$3<D$3+Control!$C$100),D$10/Control!$C$100,0) | M20: =IF(AND(M$3>=D$3,M$3<D$3+Control!$C$100),D$10/Control!$C$100,0) | N20: =IF(AND(N$3>=D$3,N$3<D$3+Control!$C$100),D$10/Control!$C$100,0) | O20: =IF(AND(O$3>=D$3,O$3<D$3+Control!$C$100),D$10/Control!$C$100,0)
A21: Origin 2 | B21: =E4 | D21: =IF(AND(D$3>=E$3,D$3<E$3+Control!$C$100),E$10/Control!$C$100,0) | E21: =IF(AND(E$3>=E$3,E$3<E$3+Control!$C$100),E$10/Control!$C$100,0) | F21: =IF(AND(F$3>=E$3,F$3<E$3+Control!$C$100),E$10/Control!$C$100,0) | G21: =IF(AND(G$3>=E$3,G$3<E$3+Control!$C$100),E$10/Control!$C$100,0) | H21: =IF(AND(H$3>=E$3,H$3<E$3+Control!$C$100),E$10/Control!$C$100,0) | I21: =IF(AND(I$3>=E$3,I$3<E$3+Control!$C$100),E$10/Control!$C$100,0) | J21: =IF(AND(J$3>=E$3,J$3<E$3+Control!$C$100),E$10/Control!$C$100,0) | K21: =IF(AND(K$3>=E$3,K$3<E$3+Control!$C$100),E$10/Control!$C$100,0) | L21: =IF(AND(L$3>=E$3,L$3<E$3+Control!$C$100),E$10/Control!$C$100,0) | M21: =IF(AND(M$3>=E$3,M$3<E$3+Control!$C$100),E$10/Control!$C$100,0) | N21: =IF(AND(N$3>=E$3,N$3<E$3+Control!$C$100),E$10/Control!$C$100,0) | O21: =IF(AND(O$3>=E$3,O$3<E$3+Control!$C$100),E$10/Control!$C$100,0)
A22: Origin 3 | B22: =F4 | D22: =IF(AND(D$3>=F$3,D$3<F$3+Control!$C$100),F$10/Control!$C$100,0) | E22: =IF(AND(E$3>=F$3,E$3<F$3+Control!$C$100),F$10/Control!$C$100,0) | F22: =IF(AND(F$3>=F$3,F$3<F$3+Control!$C$100),F$10/Control!$C$100,0) | G22: =IF(AND(G$3>=F$3,G$3<F$3+Control!$C$100),F$10/Control!$C$100,0) | H22: =IF(AND(H$3>=F$3,H$3<F$3+Control!$C$100),F$10/Control!$C$100,0) | I22: =IF(AND(I$3>=F$3,I$3<F$3+Control!$C$100),F$10/Control!$C$100,0) | J22: =IF(AND(J$3>=F$3,J$3<F$3+Control!$C$100),F$10/Control!$C$100,0) | K22: =IF(AND(K$3>=F$3,K$3<F$3+Control!$C$100),F$10/Control!$C$100,0) | L22: =IF(AND(L$3>=F$3,L$3<F$3+Control!$C$100),F$10/Control!$C$100,0) | M22: =IF(AND(M$3>=F$3,M$3<F$3+Control!$C$100),F$10/Control!$C$100,0) | N22: =IF(AND(N$3>=F$3,N$3<F$3+Control!$C$100),F$10/Control!$C$100,0) | O22: =IF(AND(O$3>=F$3,O$3<F$3+Control!$C$100),F$10/Control!$C$100,0)
A23: Origin 4 | B23: =G4 | D23: =IF(AND(D$3>=G$3,D$3<G$3+Control!$C$100),G$10/Control!$C$100,0) | E23: =IF(AND(E$3>=G$3,E$3<G$3+Control!$C$100),G$10/Control!$C$100,0) | F23: =IF(AND(F$3>=G$3,F$3<G$3+Control!$C$100),G$10/Control!$C$100,0) | G23: =IF(AND(G$3>=G$3,G$3<G$3+Control!$C$100),G$10/Control!$C$100,0) | H23: =IF(AND(H$3>=G$3,H$3<G$3+Control!$C$100),G$10/Control!$C$100,0) | I23: =IF(AND(I$3>=G$3,I$3<G$3+Control!$C$100),G$10/Control!$C$100,0) | J23: =IF(AND(J$3>=G$3,J$3<G$3+Control!$C$100),G$10/Control!$C$100,0) | K23: =IF(AND(K$3>=G$3,K$3<G$3+Control!$C$100),G$10/Control!$C$100,0) | L23: =IF(AND(L$3>=G$3,L$3<G$3+Control!$C$100),G$10/Control!$C$100,0) | M23: =IF(AND(M$3>=G$3,M$3<G$3+Control!$C$100),G$10/Control!$C$100,0) | N23: =IF(AND(N$3>=G$3,N$3<G$3+Control!$C$100),G$10/Control!$C$100,0) | O23: =IF(AND(O$3>=G$3,O$3<G$3+Control!$C$100),G$10/Control!$C$100,0)
A24: Origin 5 | B24: =H4 | D24: =IF(AND(D$3>=H$3,D$3<H$3+Control!$C$100),H$10/Control!$C$100,0) | E24: =IF(AND(E$3>=H$3,E$3<H$3+Control!$C$100),H$10/Control!$C$100,0) | F24: =IF(AND(F$3>=H$3,F$3<H$3+Control!$C$100),H$10/Control!$C$100,0) | G24: =IF(AND(G$3>=H$3,G$3<H$3+Control!$C$100),H$10/Control!$C$100,0) | H24: =IF(AND(H$3>=H$3,H$3<H$3+Control!$C$100),H$10/Control!$C$100,0) | I24: =IF(AND(I$3>=H$3,I$3<H$3+Control!$C$100),H$10/Control!$C$100,0) | J24: =IF(AND(J$3>=H$3,J$3<H$3+Control!$C$100),H$10/Control!$C$100,0) | K24: =IF(AND(K$3>=H$3,K$3<H$3+Control!$C$100),H$10/Control!$C$100,0) | L24: =IF(AND(L$3>=H$3,L$3<H$3+Control!$C$100),H$10/Control!$C$100,0) | M24: =IF(AND(M$3>=H$3,M$3<H$3+Control!$C$100),H$10/Control!$C$100,0) | N24: =IF(AND(N$3>=H$3,N$3<H$3+Control!$C$100),H$10/Control!$C$100,0) | O24: =IF(AND(O$3>=H$3,O$3<H$3+Control!$C$100),H$10/Control!$C$100,0)
A25: Origin 6 | B25: =I4 | D25: =IF(AND(D$3>=I$3,D$3<I$3+Control!$C$100),I$10/Control!$C$100,0) | E25: =IF(AND(E$3>=I$3,E$3<I$3+Control!$C$100),I$10/Control!$C$100,0) | F25: =IF(AND(F$3>=I$3,F$3<I$3+Control!$C$100),I$10/Control!$C$100,0) | G25: =IF(AND(G$3>=I$3,G$3<I$3+Control!$C$100),I$10/Control!$C$100,0) | H25: =IF(AND(H$3>=I$3,H$3<I$3+Control!$C$100),I$10/Control!$C$100,0) | I25: =IF(AND(I$3>=I$3,I$3<I$3+Control!$C$100),I$10/Control!$C$100,0) | J25: =IF(AND(J$3>=I$3,J$3<I$3+Control!$C$100),I$10/Control!$C$100,0) | K25: =IF(AND(K$3>=I$3,K$3<I$3+Control!$C$100),I$10/Control!$C$100,0) | L25: =IF(AND(L$3>=I$3,L$3<I$3+Control!$C$100),I$10/Control!$C$100,0) | M25: =IF(AND(M$3>=I$3,M$3<I$3+Control!$C$100),I$10/Control!$C$100,0) | N25: =IF(AND(N$3>=I$3,N$3<I$3+Control!$C$100),I$10/Control!$C$100,0) | O25: =IF(AND(O$3>=I$3,O$3<I$3+Control!$C$100),I$10/Control!$C$100,0)
A26: Origin 7 | B26: =J4 | D26: =IF(AND(D$3>=J$3,D$3<J$3+Control!$C$100),J$10/Control!$C$100,0) | E26: =IF(AND(E$3>=J$3,E$3<J$3+Control!$C$100),J$10/Control!$C$100,0) | F26: =IF(AND(F$3>=J$3,F$3<J$3+Control!$C$100),J$10/Control!$C$100,0) | G26: =IF(AND(G$3>=J$3,G$3<J$3+Control!$C$100),J$10/Control!$C$100,0) | H26: =IF(AND(H$3>=J$3,H$3<J$3+Control!$C$100),J$10/Control!$C$100,0) | I26: =IF(AND(I$3>=J$3,I$3<J$3+Control!$C$100),J$10/Control!$C$100,0) | J26: =IF(AND(J$3>=J$3,J$3<J$3+Control!$C$100),J$10/Control!$C$100,0) | K26: =IF(AND(K$3>=J$3,K$3<J$3+Control!$C$100),J$10/Control!$C$100,0) | L26: =IF(AND(L$3>=J$3,L$3<J$3+Control!$C$100),J$10/Control!$C$100,0) | M26: =IF(AND(M$3>=J$3,M$3<J$3+Control!$C$100),J$10/Control!$C$100,0) | N26: =IF(AND(N$3>=J$3,N$3<J$3+Control!$C$100),J$10/Control!$C$100,0) | O26: =IF(AND(O$3>=J$3,O$3<J$3+Control!$C$100),J$10/Control!$C$100,0)
A27: Origin 8 | B27: =K4 | D27: =IF(AND(D$3>=K$3,D$3<K$3+Control!$C$100),K$10/Control!$C$100,0) | E27: =IF(AND(E$3>=K$3,E$3<K$3+Control!$C$100),K$10/Control!$C$100,0) | F27: =IF(AND(F$3>=K$3,F$3<K$3+Control!$C$100),K$10/Control!$C$100,0) | G27: =IF(AND(G$3>=K$3,G$3<K$3+Control!$C$100),K$10/Control!$C$100,0) | H27: =IF(AND(H$3>=K$3,H$3<K$3+Control!$C$100),K$10/Control!$C$100,0) | I27: =IF(AND(I$3>=K$3,I$3<K$3+Control!$C$100),K$10/Control!$C$100,0) | J27: =IF(AND(J$3>=K$3,J$3<K$3+Control!$C$100),K$10/Control!$C$100,0) | K27: =IF(AND(K$3>=K$3,K$3<K$3+Control!$C$100),K$10/Control!$C$100,0) | L27: =IF(AND(L$3>=K$3,L$3<K$3+Control!$C$100),K$10/Control!$C$100,0) | M27: =IF(AND(M$3>=K$3,M$3<K$3+Control!$C$100),K$10/Control!$C$100,0) | N27: =IF(AND(N$3>=K$3,N$3<K$3+Control!$C$100),K$10/Control!$C$100,0) | O27: =IF(AND(O$3>=K$3,O$3<K$3+Control!$C$100),K$10/Control!$C$100,0)
A28: Origin 9 | B28: =L4 | D28: =IF(AND(D$3>=L$3,D$3<L$3+Control!$C$100),L$10/Control!$C$100,0) | E28: =IF(AND(E$3>=L$3,E$3<L$3+Control!$C$100),L$10/Control!$C$100,0) | F28: =IF(AND(F$3>=L$3,F$3<L$3+Control!$C$100),L$10/Control!$C$100,0) | G28: =IF(AND(G$3>=L$3,G$3<L$3+Control!$C$100),L$10/Control!$C$100,0) | H28: =IF(AND(H$3>=L$3,H$3<L$3+Control!$C$100),L$10/Control!$C$100,0) | I28: =IF(AND(I$3>=L$3,I$3<L$3+Control!$C$100),L$10/Control!$C$100,0) | J28: =IF(AND(J$3>=L$3,J$3<L$3+Control!$C$100),L$10/Control!$C$100,0) | K28: =IF(AND(K$3>=L$3,K$3<L$3+Control!$C$100),L$10/Control!$C$100,0) | L28: =IF(AND(L$3>=L$3,L$3<L$3+Control!$C$100),L$10/Control!$C$100,0) | M28: =IF(AND(M$3>=L$3,M$3<L$3+Control!$C$100),L$10/Control!$C$100,0) | N28: =IF(AND(N$3>=L$3,N$3<L$3+Control!$C$100),L$10/Control!$C$100,0) | O28: =IF(AND(O$3>=L$3,O$3<L$3+Control!$C$100),L$10/Control!$C$100,0)
