Workbook

Sheet Dashboard
A1: BitMach | Simplified 20MW Phase 1 Model (36 months)
A2: Equity-first base case for management and investor conversations. Detailed master model remains separate; optional revenue and debt are included only as editable upside levers.
A4: Headline KPIs
A5: Phase 1 envelope (MW) | D5: Site split (GVL / AMSA MW) | G5: 36M BTC mined | J5: 36M revenue (base)
A6: =Inputs!C7 -> 20 | D6: =Inputs!C8&" / "&Inputs!C9 -> 15 / 5 | G6: =SUM(Annual_Summary!C11:E11) -> 649.36229 | J6: =SUM(Annual_Summary!C12:E12) -> 1036384.4
A8: Peak funding required | D8: Total equity required | G8: Year 3 EBITDA | J8: End-36M cash
A9: =Annual_Summary!C25 -> 470888.25 | D9: =Annual_Summary!C26 -> 470888.25 | G9: =Annual_Summary!E15 -> 255462.49 | J9: =Annual_Summary!E21 -> 589548.42
A11: Implied payback (yrs) | D11: Year 1 capex | G11: Year 2 unlevered CF | J11: Optionality toggles
A12: =IF(Annual_Summary!E15=0,"",SUM(Annual_Summary!C17:E17)/Annual_Summary!E15) -> 1.9783947 | D12: =Annual_Summary!C17 -> 505405.63 | G12: =Annual_Summary!D18 -> 232752.44 | J12: =IF(AND(Inputs!C82=0,Inputs!C87=0),"DR OFF / HYP OFF","UPSIDE ON") -> DR OFF / HYP OFF
A16: Annual output summary | G16: Site deployment and revenue architecture
A17: Metric | B17: Year 1 | C17: Year 2 | D17: Year 3 | E17: 36M total | F17: Comment | G17: Topic | H17: Base case | I17: Why it matters | J17: Edit at | K17: Current phase footprint | L17: MW
A18: Year-end gross MW | B18: =Annual_Summary!C7 -> 20 | C18: =Annual_Summary!D7 -> 20 | D18: =Annual_Summary!E7 -> 20 | E18: =D18 -> 20 | F18: Gross compute MW in place | G18: Grootvlei compute | H18: 15MW by month 5 | 22h/day | I18: Primary production node and Eskom brownfield anchor | J18: Inputs / Deployment_36M | K18: Phase 1 total gross | L18: =Inputs!C7 -> 20
A19: BTC mined | B19: =Annual_Summary!C11 -> 177.7338 | C19: =Annual_Summary!D11 -> 247.36135 | D19: =Annual_Summary!E11 -> 224.26714 | E19: =SUM(B19:D19) -> 649.36229 | F19: Bitcoin produced | G19: AMSA compute | H19: 5MW by month 6 | I19: Adds industrial diversification and solar blend pathway | J19: Inputs / Deployment_36M | K19: Year-end Grootvlei | L19: =Annual_Summary!C8 -> 15
A20: Revenue (base) | B20: =Annual_Summary!C12 -> 246952.8 | C20: =Annual_Summary!D12 -> 386487.07 | D20: =Annual_Summary!E12 -> 402944.55 | E20: =SUM(B20:D20) -> 1036384.4 | F20: BTC revenue only | G20: AMSA solar | H20: 10MW from month 5 | I20: Reduces blended energy cost materially | J20: Inputs / Deployment_36M | K20: Year-end AMSA | L20: =Annual_Summary!C9 -> 5
A21: Cash opex | B21: =Annual_Summary!C14 -> 111101.93 | C21: =Annual_Summary!D14 -> 153734.63 | D21: =Annual_Summary!E14 -> 147482.06 | E21: =SUM(B21:D21) -> 412318.62 | F21: Cash operating cost | G21: Revenue stack | H21: BTC base; DR + hyperscaler optional | I21: Keeps base case conservative for investors/lenders | J21: Revenue_36M toggles | K21: Year-end AMSA solar | L21: =Annual_Summary!C10 -> 10
A22: EBITDA (base) | B22: =Annual_Summary!C15 -> 135850.87 | C22: =Annual_Summary!D15 -> 232752.44 | D22: =Annual_Summary!E15 -> 255462.49 | E22: =SUM(B22:D22) -> 624065.8 | F22: Revenue less opex | G22: Funding stack | H22: 100% equity default | I22: Aligns with current Phase 1 raise framing | J22: Inputs / Funding_36M | K22: Peak funding | L22: =Annual_Summary!C25 -> 470888.25
A23: Capex spend | B23: =Annual_Summary!C17 -> 505405.63 | C23: =Annual_Summary!D17 -> 0 | D23: =Annual_Summary!E17 -> 0 | E23: =SUM(B23:D23) -> 505405.63 | F23: Cash capital deployed | G23: Operating model | H23: 98% uptime; 22h GVL; 12h + 9h AMSA | I23: Separates uptime from site operating windows | J23: Inputs | K23: Total equity | L23: =Annual_Summary!C26 -> 470888.25
A24: Unlevered cash flow | B24: =Annual_Summary!C18 -> -369554.77 | C24: =Annual_Summary!D18 -> 232752.44 | D24: =Annual_Summary!E18 -> 255462.49 | E24: =SUM(B24:D24) -> 118660.17 | F24: Base-case free cash flow before funding | G24: Investor use | H24: Use Dashboard + Annual_Summary only | I24: Detailed monthly tabs remain internal | J24: Sources_Notes | K24: Y3 EBITDA | L24: =Annual_Summary!E15 -> 255462.49
G25: Editable choice | H25: Still easy to switch to a 10 / 10 split | I25: Scenario flexibility without breaking formulas | J25: Inputs / Deployment_36M | K25: Implied payback | L25: =IF(Annual_Summary!E15=0,"",SUM(Annual_Summary!C17:E17)/Annual_Summary!E15) -> 1.9783947
A27: Base-case assumptions | G27: Model framing and cautions
A28: Driver | B28: Value | C28: Unit | D28: Where to edit | E28: Model role | F28: Comment | G28: 1) This workbook is intentionally smaller than the detailed master model. 2) Base case excludes demand-response and hyperscaler resale revenue. 3) Debt is off by default to match the current Phase 1 equity raise framing. 4) The latest April 2026 deck uses a 15MW Grootvlei / 5MW AMSA split, but the workbook is editable if management wants a 10 / 10 variant.
A29: Technical uptime | B29: =Inputs!C10 -> 0.98 | C29: % | D29: Inputs!C10 | E29: Production conversion | F29: User confirmed 98% is realistic.
A30: Grootvlei hours/day | B30: =Inputs!C12 -> 22 | C30: hours | D30: Inputs!C12 | E30: Availability profile | F30: User confirmed 22h/day is aligned with current negotiations.
A31: AMSA Eskom hours/day | B31: =Inputs!C13 -> 12 | C31: hours | D31: Inputs!C13 | E31: Grid supply profile | F31: Editable.
A32: AMSA solar hours/day | B32: =Inputs!C14 -> 9 | C32: hours | D32: Inputs!C14 | E32: Solar contribution | F32: Editable.
A33: BTC price start | B33: =Inputs!C21 -> 75000 | C33: USD/BTC | D33: Inputs!C21 | E33: Top-line driver | F33: Editable.
A34: Network growth p.a. | B34: =Inputs!C24 -> 0.1 | C34: % | D34: Inputs!C24 | E34: Difficulty sensitivity | F34: Editable stress point.
A35: Year 1 tariffs (GVL / AMSA) | B35: =TEXT(Inputs!C29,"0.00")&" / "&TEXT(Inputs!C32,"0.00") -> 1.00 / 0.90 | C35: R/kWh | D35: Inputs tariffs | E35: Primary IRR driver | F35: Keeping conservative

Sheet Inputs
A1: BitMach Phase 1 (20MW) | Simplified 36-Month Model
A2: Scaled-down fundraising model for the first 20MW only. Core case is conservative; optionality is visible but off by default.
A3: Driver | B3: Unit | C3: Value | D3: Notes
A4: MODEL ASSUMPTIONS | D4: Editable blue cells. Defaults aim to be conservative and bankable.
A5: Model start date | B5: date | C5: 46204 | D5: Editable. Relative 36-month model start.
A6: Horizon months | B6: months | C6: 36 | D6: Fixed workbook horizon.
A7: Phase 1 total gross MW | B7: MW | C7: 20 | D7: Scaled-down Phase 1 only.
A8: Grootvlei target MW | B8: MW | C8: 15 | D8: Latest investor deck uses 15MW Grootvlei + 5MW AMSA; change these two cells to 10/10 if management wants the older Nedbank memo framing.
A9: AMSA target MW | B9: MW | C9: 5 | D9: Editable site split.
A10: Technical uptime | B10: % | C10: 0.98 | D10: MARA achieves 99.9%
A11: Aux load | B11: % | C11: 0.05 | D11: Cooling / container auxiliaries.
A12: Grootvlei hours/day | B12: hours/day | C12: 22 | D12: 22h/day remains consistent with Eskom negotiations.
A13: AMSA Eskom hours/day | B13: hours/day | C13: 12 | D13: Grid-supplied runtime leg.
A14: AMSA solar hours/day | B14: hours/day | C14: 9 | D14: Solar-supplied runtime leg.
A15: AMSA solar MW in Phase 1 | B15: MW | C15: 10 | D15: Conservative Year-1 placeholder; keep editable.
A16: Solar COD month | B16: month# | C16: 5 | D16: Solar available during ramp-up.
... A18: Salary annual inflation | B18: % | C18: 0.05 | D18: Used for payroll escalation.
A19: BITCOIN / NETWORK | D19: Core market assumptions.
A20: FX (ZAR/USD) | B20: ZAR/USD | C20: 17 | D20: April 2026 investor materials use R17.00/USD.
A21: BTC price start | B21: USD/BTC | C21: 75000 | D21: Editable spot / entry assumption.
A22: BTC annual growth | B22: % | C22: 0.15 | D22: Base case market growth.
A23: Network hash start | B23: TH/s | C23: 900000000 | D23: Editable.
A24: Network hash annual growth | B24: % | C24: 0.1 | D24: Base case difficulty / network growth.
A25: Blocks per day | B25: blocks/day | C25: 144 | D25: Protocol input.
A26: Block subsidy | B26: BTC/block | C26: 3.125 | D26: Protocol input.
A27: Fee factor on subsidy | B27: % | C27: 0.15 | D27: Pool fee / transaction fee uplift.
A28: SITE PRICING | D28: Explicit yearly tariffs rather than a hidden blend.
A29: Grootvlei tariff - Year 1 | B29: R/kWh | C29: 1 | D29: Proof-phase conservative tariff.
A30: Grootvlei tariff - Year 2 | B30: R/kWh | C30: 0.95 | D30: Partial improvement after proof of flexibility.
A31: Grootvlei tariff - Year 3 | B31: R/kWh | C31: 0.9 | D31: Future-state improvement placeholder; editable.
A32: AMSA Eskom tariff - Year 1 | B32: R/kWh | C32: 0.9 | D32: AMSA grid leg.
A33: AMSA Eskom tariff - Year 2 | B33: R/kWh | C33: 0.85 | D33: AMSA grid leg.
A34: AMSA Eskom tariff - Year 3 | B34: R/kWh | C34: 0.8 | D34: AMSA grid leg.
A35: Solar capex | B35: ZAR'000/MW | C35: 7000 | D35: Conservative placeholder.
A36: Solar O&M | B36: % p.a. | C36: 0.02 | D36: Annual O&M as % of solar capex.
A37: HARDWARE | D37: Default set to the internally consistent working basis currently used in the detailed master model; editable if Bitmain terms are finalized.
A38: Miner hashrate | B38: TH/miner | C38: 700 | D38: Editable. Current working base.
A39: Miner efficiency | B39: J/T | C39: 12.5 | D39: Editable. Current working base.
A40: Miner power | B40: W/miner | C40: =C38*C39 -> 8750 | D40: Formula = hashrate x J/T.
A41: Miner price | B41: USD/miner | C41: 5915 | D41: Editable hardware pricing.
...

Sheet Deployment_36M
A1: Deployment_36M | Editable site ramp for the first 20MW only
A2: Edit only the three closing-MW rows (Grootvlei, AMSA, AMSA solar). Everything else is formula-driven. Default ramp = 0/0/5/10/15/20MW gross over the first six months.
A4: Metric | B4: Unit | C4: Notes
A5: Date | B5: date | C5: From Inputs start date | D5: =Inputs!C5 -> 46204 | E5: =EDATE(D5,1) -> 46235 | F5: =EDATE(E5,1) -> 46266 | G5: =EDATE(F5,1) -> 46296 | H5: =EDATE(G5,1) -> 46327 | I5: =EDATE(H5,1) -> 46357 | J5: =EDATE(I5,1) -> 46388 | K5: =EDATE(J5,1) -> 46419 | L5: =EDATE(K5,1) -> 46447 | ... AM5: =EDATE(AL5,1) -> 47270
A6: Days in month | B6: days | C6: Calendar days | D6: =DAY(EOMONTH(D5,0)) -> 31 | E6: =DAY(EOMONTH(E5,0)) -> 31 | F6: =DAY(EOMONTH(F5,0)) -> 30 | G6: =DAY(EOMONTH(G5,0)) -> 31 | H6: =DAY(EOMONTH(H5,0)) -> 30 | I6: =DAY(EOMONTH(I5,0)) -> 31 | J6: =DAY(EOMONTH(J5,0)) -> 31 | K6: =DAY(EOMONTH(K5,0)) -> 28 | ... AM6: =DAY(EOMONTH(AM5,0)) -> 30
A8: Grootvlei closing MW | B8: MW | C8: Editable | D8: 0 | E8: 0 | F8: 5 | G8: 10 | H8: 15 | I8: 15 | J8: 15 | K8: 15 | L8: 15 | M8: 15 | N8: 15 | O8: 15 | P8: 15 | Q8: 15 | R8: 15 | S8: 15 | T8: 15 | U8: 15 | V8: 15 | W8: 15 | X8: 15 | Y8: 15 | Z8: 15 | AA8: 15 | AB8: 15 | AC8: 15 | AD8: 15 | AE8: 15 | AF8: 15 | AG8: 15 | AH8: 15 | AI8: 15 | AJ8: 15 | AK8: 15 | AL8: 15 | AM8: 15
A9: AMSA closing MW | B9: MW | C9: Editable | D9: 0 | E9: 0 | F9: 0 | G9: 0 | H9: 0 | I9: 5 | J9: 5 | K9: 5 | L9: 5 | M9: 5 | N9: 5 | O9: 5 | P9: 5 | Q9: 5 | R9: 5 | S9: 5 | T9: 5 | U9: 5 | V9: 5 | W9: 5 | X9: 5 | Y9: 5 | Z9: 5 | AA9: 5 | AB9: 5 | AC9: 5 | AD9: 5 | AE9: 5 | AF9: 5 | AG9: 5 | AH9: 5 | AI9: 5 | AJ9: 5 | AK9: 5 | AL9: 5 | AM9: 5
A10: AMSA solar closing MW | B10: MW | C10: Editable | D10: 0 | E10: 0 | F10: 0 | G10: 0 | H10: 10 | I10: 10 | J10: 10 | K10: 10 | L10: 10 | M10: 10 | N10: 10 | O10: 10 | P10: 10 | Q10: 10 | R10: 10 | S10: 10 | T10: 10 | U10: 10 | V10: 10 | W10: 10 | X10: 10 | Y10: 10 | Z10: 10 | AA10: 10 | AB10: 10 | AC10: 10 | AD10: 10 | AE10: 10 | AF10: 10 | AG10: 10 | AH10: 10 | AI10: 10 | AJ10: 10 | AK10: 10 | AL10: 10 | AM10: 10
A13: Grootvlei opening MW | B13: MW | C13: Formula | D13: =0 -> 0 | E13: =D8 -> 0 | F13: =E8 -> 0 | G13: =F8 -> 5 | H13: =G8 -> 10 | I13: =H8 -> 15 | J13: =I8 -> 15 | K13: =J8 -> 15 | L13: =K8 -> 15 | ... AM13: =AL8 -> 15
A14: AMSA opening MW | B14: MW | C14: Formula | D14: =0 -> 0 | E14: =D9 -> 0 | F14: =E9 -> 0 | G14: =F9 -> 0 | H14: =G9 -> 0 | I14: =H9 -> 0 | J14: =I9 -> 5 | K14: =J9 -> 5 | L14: =K9 -> 5 | ... AM14: =AL9 -> 5
A15: AMSA solar opening MW | B15: MW | C15: Formula | D15: =0 -> 0 | E15: =D10 -> 0 | F15: =E10 -> 0 | G15: =F10 -> 0 | H15: =G10 -> 0 | I15: =H10 -> 10 | J15: =I10 -> 10 | K15: =J10 -> 10 | L15: =K10 -> 10 | ... AM15: =AL10 -> 10
A18: Grootvlei average MW | B18: MW | C18: Formula | D18: =(D13+D8)/2 -> 0 | E18: =(E13+E8)/2 -> 0 | F18: =(F13+F8)/2 -> 2.5 | G18: =(G13+G8)/2 -> 7.5 | H18: =(H13+H8)/2 -> 12.5 | I18: =(I13+I8)/2 -> 15 | J18: =(J13+J8)/2 -> 15 | K18: =(K13+K8)/2 -> 15 | ... AM18: =(AM13+AM8)/2 -> 15
A19: AMSA average MW | B19: MW | C19: Formula | D19: =(D14+D9)/2 -> 0 | E19: =(E14+E9)/2 -> 0 | F19: =(F14+F9)/2 -> 0 | G19: =(G14+G9)/2 -> 0 | H19: =(H14+H9)/2 -> 0 | I19: =(I14+I9)/2 -> 2.5 | J19: =(J14+J9)/2 -> 5 | K19: =(K14+K9)/2 -> 5 | ... AM19: =(AM14+AM9)/2 -> 5
A20: AMSA average solar MW | B20: MW | C20: Formula | D20: =(D15+D10)/2 -> 0 | E20: =(E15+E10)/2 -> 0 | F20: =(F15+F10)/2 -> 0 | G20: =(G15+G10)/2 -> 0 | H20: =(H15+H10)/2 -> 5 | I20: =(I15+I10)/2 -> 10 | J20: =(J15+J10)/2 -> 10 | K20: =(K15+K10)/2 -> 10 | ... AM20: =(AM15+AM10)/2 -> 10
A21: Total average MW | B21: MW | C21: Formula | D21: =D18+D19 -> 0 | E21: =E18+E19 -> 0 | F21: =F18+F19 -> 2.5 | G21: =G18+G19 -> 7.5 | H21: =H18+H19 -> 12.5 | I21: =I18+I19 -> 17.5 | J21: =J18+J19 -> 20 | K21: =K18+K19 -> 20 | ... AM21: =AM18+AM19 -> 20
A24: Grootvlei new MW | B24: MW | C24: Formula | D24: =MAX(0,D8-D13) -> 0 | E24: =MAX(0,E8-E13) -> 0 | F24: =MAX(0,F8-F13) -> 5 | G24: =MAX(0,G8-G13) -> 5 | H24: =MAX(0,H8-H13) -> 5 | I24: =MAX(0,I8-I13) -> 0 | J24: =MAX(0,J8-J13) -> 0 | K24: =MAX(0,K8-K13) -> 0 | ... AM24: =MAX(0,AM8-AM13) -> 0
A25: AMSA new MW | B25: MW | C25: Formula | D25: =MAX(0,D9-D14) -> 0 | E25: =MAX(0,E9-E14) -> 0 | F25: =MAX(0,F9-F14) -> 0 | G25: =MAX(0,G9-G14) -> 0 | H25: =MAX(0,H9-H14) -> 0 | I25: =MAX(0,I9-I14) -> 5 | J25: =MAX(0,J9-J14) -> 0 | K25: =MAX(0,K9-K14) -> 0 | ... AM25: =MAX(0,AM9-AM14) -> 0
A26: AMSA solar new MW | B26: MW | C26: Formula | D26: =MAX(0,D10-D15) -> 0 | E26: =MAX(0,E10-E15) -> 0 | F26: =MAX(0,F10-F15) -> 0 | G26: =MAX(0,G10-G15) -> 0 | H26: =MAX(0,H10-H15) -> 10 | I26: =MAX(0,I10-I15) -> 0 | J26: =MAX(0,J10-J15) -> 0 | K26: =MAX(0,K10-K15) -> 0 | ... AM26: =MAX(0,AM10-AM15) -> 0
A27: Total new MW | B27: MW | C27: Formula | D27: =D24+D25 -> 0 | E27: =E24+E25 -> 0 | F27: =F24+F25 -> 5 | G27: =G24+G25 -> 5 | H27: =H24+H25 -> 5 | I27: =I24+I25 -> 5 | J27: =J24+J25 -> 0 | K27: =K24+K25 -> 0 | ... AM27: =AM24+AM25 -> 0
A30: Grootvlei active site | B30: flag | C30: Formula | D30: =IF(D8>0,1,0) -> 0 | E30: =IF(E8>0,1,0) -> 0 | F30: =IF(F8>0,1,0) -> 1 | G30: =IF(G8>0,1,0) -> 1 | H30: =IF(H8>0,1,0) -> 1 | I30: =IF(I8>0,1,0) -> 1 | J30: =IF(J8>0,1,0) -> 1 | K30: =IF(K8>0,1,0) -> 1 | ... AM30: =IF(AM8>0,1,0) -> 1
A31: AMSA active site | B31: flag | C31: Formula | D31: =IF(D9>0,1,0) -> 0 | E31: =IF(E9>0,1,0) -> 0 | F31: =IF(F9>0,1,0) -> 0 | G31: =IF(G9>0,1,0) -> 0 | H31: =IF(H9>0,1,0) -> 0 | I31: =IF(I9>0,1,0) -> 1 | J31: =IF(J9>0,1,0) -> 1 | K31: =IF(K9>0,1,0) -> 1 | ... AM31: =IF(AM9>0,1,0) -> 1
A32: Total active sites | B32: count | C32: Formula | D32: =D30+D31 -> 0 | E32: =E30+E31 -> 0 | F32: =F30+F31 -> 1 | G32: =G30+G31 -> 1 | H32: =H30+H31 -> 1 | I32: =I30+I31 -> 2 | J32: =J30+J31 -> 2 | K32: =K30+K31 -> 2 | ... AM32: =AM30+AM31 -> 2
A35: Grootvlei site start | B35: flag | C35: Formula | D35: =IF(AND(D8>0,D13=0),1,0) -> 0 | E35: =IF(AND(E8>0,E13=0),1,0) -> 0 | F35: =IF(AND(F8>0,F13=0),1,0) -> 1 | G35: =IF(AND(G8>0,G13=0),1,0) -> 0 | H35: =IF(AND(H8>0,H13=0),1,0) -> 0 | I35: =IF(AND(I8>0,I13=0),1,0) -> 0 | J35: =IF(AND(J8>0,J13=0),1,0) -> 0 | K35: =IF(AND(K8>0,K13=0),1,0) -> 0 | ... AM35: =IF(AND(AM8>0,AM13=0),1,0) -> 0
A36: AMSA site start | B36: flag | C36: Formula | D36: =IF(AND(D9>0,D14=0),1,0) -> 0 | E36: =IF(AND(E9>0,E14=0),1,0) -> 0 | F36: =IF(AND(F9>0,F14=0),1,0) -> 0 | G36: =IF(AND(G9>0,G14=0),1,0) -> 0 | H36: =IF(AND(H9>0,H14=0),1,0) -> 0 | I36: =IF(AND(I9>0,I14=0),1,0) -> 1 | J36: =IF(AND(J9>0,J14=0),1,0) -> 0 | K36: =IF(AND(K9>0,K14=0),1,0) -> 0 | ... AM36: =IF(AND(AM9>0,AM14=0),1,0) -> 0
A37: Total site starts | B37: count | C37: Formula | D37: =D35+D36 -> 0 | E37: =E35+E36 -> 0 | F37: =F35+F36 -> 1 | G37: =G35+G36 -> 0 | H37: =H35+H36 -> 0 | I37: =I35+I36 -> 1 | J37: =J35+J36 -> 0 | K37: =K35+K36 -> 0 | ... AM37: =AM35+AM36 -> 0
A40: Grootvlei closing containers | B40: containers | C40: Formula | D40: =ROUNDUP(D8/Inputs!C45,0) -> 0 | E40: =ROUNDUP(E8/Inputs!C45,0) -> 0 | F40: =ROUNDUP(F8/Inputs!C45,0) -> 3 | G40: =ROUNDUP(G8/Inputs!C45,0) -> 5 | H40: =ROUNDUP(H8/Inputs!C45,0) -> 7 | I40: =ROUNDUP(I8/Inputs!C45,0) -> 7 | J40: =ROUNDUP(J8/Inputs!C45,0) -> 7 | K40: =ROUNDUP(K8/Inputs!C45,0) -> 7 | L40: =ROUNDUP(L8/Inputs!C45,0) -> 7 | M40: =ROUNDUP(M8/Inputs!C45,0) -> 7 | N40: =ROUNDUP(N8/Inputs!C45,0) -> 7 | O40: =ROUNDUP(O8/Inputs!C45,0) -> 7 | P40: =ROUNDUP(P8/Inputs!C45,0) -> 7 | Q40: =ROUNDUP(Q8/Inputs!C45,0) -> 7 | R40: =ROUNDUP(R8/Inputs!C45,0) -> 7 | S40: =ROUNDUP(S8/Inputs!C45,0) -> 7 | T40: =ROUNDUP(T8/Inputs!C45,0) -> 7 | U40: =ROUNDUP(U8/Inputs!C45,0) -> 7 | V40: =ROUNDUP(V8/Inputs!C45,0) -> 7 | W40: =ROUNDUP(W8/Inputs!C45,0) -> 7 | X40: =ROUNDUP(X8/Inputs!C45,0) -> 7 | Y40: =ROUNDUP(Y8/Inputs!C45,0) -> 7 | Z40: =ROUNDUP(Z8/Inputs!C45,0) -> 7 | AA40: =ROUNDUP(AA8/Inputs!C45,0) -> 7 | AB40: =ROUNDUP(AB8/Inputs!C45,0) -> 7 | AC40: =ROUNDUP(AC8/Inputs!C45,0) -> 7 | AD40: =ROUNDUP(AD8/Inputs!C45,0) -> 7 | AE40: =ROUNDUP(AE8/Inputs!C45,0) -> 7 | AF40: =ROUNDUP(AF8/Inputs!C45,0) -> 7 | AG40: =ROUNDUP(AG8/Inputs!C45,0) -> 7 | AH40: =ROUNDUP(AH8/Inputs!C45,0) -> 7 | AI40: =ROUNDUP(AI8/Inputs!C45,0) -> 7 | AJ40: =ROUNDUP(AJ8/Inputs!C45,0) -> 7 | AK40: =ROUNDUP(AK8/Inputs!C45,0) -> 7 | AL40: =ROUNDUP(AL8/Inputs!C45,0) -> 7 | AM40: =ROUNDUP(AM8/Inputs!C45,0) -> 7
A41: AMSA closing containers | B41: containers | C41: Formula | D41: =ROUNDUP(D9/Inputs!C45,0) -> 0 | E41: =ROUNDUP(E9/Inputs!C45,0) -> 0 | F41: =ROUNDUP(F9/Inputs!C45,0) -> 0 | G41: =ROUNDUP(G9/Inputs!C45,0) -> 0 | H41: =ROUNDUP(H9/Inputs!C45,0) -> 0 | I41: =ROUNDUP(I9/Inputs!C45,0) -> 3 | J41: =ROUNDUP(J9/Inputs!C45,0) -> 3 | K41: =ROUNDUP(K9/Inputs!C45,0) -> 3 | L41: =ROUNDUP(L9/Inputs!C45,0) -> 3 | M41: =ROUNDUP(M9/Inputs!C45,0) -> 3 | N41: =ROUNDUP(N9/Inputs!C45,0) -> 3 | O41: =ROUNDUP(O9/Inputs!C45,0) -> 3 | P41: =ROUNDUP(P9/Inputs!C45,0) -> 3 | Q41: =ROUNDUP(Q9/Inputs!C45,0) -> 3 | R41: =ROUNDUP(R9/Inputs!C45,0) -> 3 | S41: =ROUNDUP(S9/Inputs!C45,0) -> 3 | T41: =ROUNDUP(T9/Inputs!C45,0) -> 3 | U41: =ROUNDUP(U9/Inputs!C45,0) -> 3 | V41: =ROUNDUP(V9/Inputs!C45,0) -> 3 | W41: =ROUNDUP(W9/Inputs!C45,0) -> 3 | X41: =ROUNDUP(X9/Inputs!C45,0) -> 3 | Y41: =ROUNDUP(Y9/Inputs!C45,0) -> 3 | Z41: =ROUNDUP(Z9/Inputs!C45,0) -> 3 | AA41: =ROUNDUP(AA9/Inputs!C45,0) -> 3 | AB41: =ROUNDUP(AB9/Inputs!C45,0) -> 3 | AC41: =ROUNDUP(AC9/Inputs!C45,0) -> 3 | AD41: =ROUNDUP(AD9/Inputs!C45,0) -> 3 | AE41: =ROUNDUP(AE9/Inputs!C45,0) -> 3 | AF41: =ROUNDUP(AF9/Inputs!C45,0) -> 3 | AG41: =ROUNDUP(AG9/Inputs!C45,0) -> 3 | AH41: =ROUNDUP(AH9/Inputs!C45,0) -> 3 | AI41: =ROUNDUP(AI9/Inputs!C45,0) -> 3 | AJ41: =ROUNDUP(AJ9/Inputs!C45,0) -> 3 | AK41: =ROUNDUP(AK9/Inputs!C45,0) -> 3 | AL41: =ROUNDUP(AL9/Inputs!C45,0) -> 3 | AM41: =ROUNDUP(AM9/Inputs!C45,0) -> 3
A42: Total closing containers | B42: containers | C42: Formula | D42: =D40+D41 -> 0 | E42: =E40+E41 -> 0 | F42: =F40+F41 -> 3 | G42: =G40+G41 -> 5 | H42: =H40+H41 -> 7 | I42: =I40+I41 -> 10 | J42: =J40+J41 -> 10 | K42: =K40+K41 -> 10 | ... AM42: =AM40+AM41 -> 10
A45: Grootvlei opening containers | B45: containers | C45: Formula | D45: =0 -> 0 | E45: =D40 -> 0 | F45: =E40 -> 0 | G45: =F40 -> 3 | H45: =G40 -> 5 | I45: =H40 -> 7 | J45: =I40 -> 7 | K45: =J40 -> 7 | L45: =K40 -> 7 | ... AM45: =AL40 -> 7
A46: AMSA opening containers | B46: containers | C46: Formula | D46: =0 -> 0 | E46: =D41 -> 0 | F46: =E41 -> 0 | G46: =F41 -> 0 | H46: =G41 -> 0 | I46: =H41 -> 0 | J46: =I41 -> 3 | K46: =J41 -> 3 | L46: =K41 -> 3 | ... AM46: =AL41 -> 3
A47: Total opening containers | B47: containers | C47: Formula | D47: =0 -> 0 | E47: =D42 -> 0 | F47: =E42 -> 0 | G47: =F42 -> 3 | H47: =G42 -> 5 | I47: =H42 -> 7 | J47: =I42 -> 10 | K47: =J42 -> 10 | L47: =K42 -> 10 | ... AM47: =AL42 -> 10
A50: Grootvlei new containers | B50: containers | C50: Formula | D50: =MAX(0,D40-D45) -> 0 | E50: =MAX(0,E40-E45) -> 0 | F50: =MAX(0,F40-F45) -> 3 | G50: =MAX(0,G40-G45) -> 2 | H50: =MAX(0,H40-H45) -> 2 | I50: =MAX(0,I40-I45) -> 0 | J50: =MAX(0,J40-J45) -> 0 | K50: =MAX(0,K40-K45) -> 0 | ... AM50: =MAX(0,AM40-AM45) -> 0
A51: AMSA new containers | B51: containers | C51: Formula | D51: =MAX(0,D41-D46) -> 0 | E51: =MAX(0,E41-E46) -> 0 | F51: =MAX(0,F41-F46) -> 0 | G51: =MAX(0,G41-G46) -> 0 | H51: =MAX(0,H41-H46) -> 0 | I51: =MAX(0,I41-I46) -> 3 | J51: =MAX(0,J41-J46) -> 0 | K51: =MAX(0,K41-K46) -> 0 | ... AM51: =MAX(0,AM41-AM46) -> 0
A52: Total new containers | B52: containers | C52: Formula | D52: =D50+D51 -> 0 | E52: =E50+E51 -> 0 | F52: =F50+F51 -> 3 | G52: =G50+G51 -> 2 | H52: =H50+H51 -> 2 | I52: =I50+I51 -> 3 | J52: =J50+J51 -> 0 | K52: =K50+K51 -> 0 | ... AM52: =AM50+AM51 -> 0
A55: New site FTE onboarded | B55: FTE | C55: Formula | D55: =(D37*Inputs!C64)+(D27*(Inputs!C66+Inputs!C68)) -> 0 | E55: =(E37*Inputs!C64)+(E27*(Inputs!C66+Inputs!C68)) -> 0 | F55: =(F37*Inputs!C64)+(F27*(Inputs!C66+Inputs!C68)) -> 4.15 | G55: =(G37*Inputs!C64)+(G27*(Inputs!C66+Inputs!C68)) -> 2.15 | H55: =(H37*Inputs!C64)+(H27*(Inputs!C66+Inputs!C68)) -> 2.15 | I55: =(I37*Inputs!C64)+(I27*(Inputs!C66+Inputs!C68)) -> 4.15 | J55: =(J37*Inputs!C64)+(J27*(Inputs!C66+Inputs!C68)) -> 0 | K55: =(K37*Inputs!C64)+(K27*(Inputs!C66+Inputs!C68)) -> 0 | L55: =(L37*Inputs!C64)+(L27*(Inputs!C66+Inputs!C68)) -> 0 | M55: =(M37*Inputs!C64)+(M27*(Inputs!C66+Inputs!C68)) -> 0 | N55: =(N37*Inputs!C64)+(N27*(Inputs!C66+Inputs!C68)) -> 0 | O55: =(O37*Inputs!C64)+(O27*(Inputs!C66+Inputs!C68)) -> 0 | P55: =(P37*Inputs!C64)+(P27*(Inputs!C66+Inputs!C68)) -> 0 | Q55: =(Q37*Inputs!C64)+(Q27*(Inputs!C66+Inputs!C68)) -> 0 | R55: =(R37*Inputs!C64)+(R27*(Inputs!C66+Inputs!C68)) -> 0 | S55: =(S37*Inputs!C64)+(S27*(Inputs!C66+Inputs!C68)) -> 0 | T55: =(T37*Inputs!C64)+(T27*(Inputs!C66+Inputs!C68)) -> 0 | U55: =(U37*Inputs!C64)+(U27*(Inputs!C66+Inputs!C68)) -> 0 | V55: =(V37*Inputs!C64)+(V27*(Inputs!C66+Inputs!C68)) -> 0 | W55: =(W37*Inputs!C64)+(W27*(Inputs!C66+Inputs!C68)) -> 0 | X55: =(X37*Inputs!C64)+(X27*(Inputs!C66+Inputs!C68)) -> 0 | Y55: =(Y37*Inputs!C64)+(Y27*(Inputs!C66+Inputs!C68)) -> 0 | Z55: =(Z37*Inputs!C64)+(Z27*(Inputs!C66+Inputs!C68)) -> 0 | AA55: =(AA37*Inputs!C64)+(AA27*(Inputs!C66+Inputs!C68)) -> 0 | AB55: =(AB37*Inputs!C64)+(AB27*(Inputs!C66+Inputs!C68)) -> 0 | AC55: =(AC37*Inputs!C64)+(AC27*(Inputs!C66+Inputs!C68)) -> 0 | AD55: =(AD37*Inputs!C64)+(AD27*(Inputs!C66+Inputs!C68)) -> 0 | AE55: =(AE37*Inputs!C64)+(AE27*(Inputs!C66+Inputs!C68)) -> 0 | AF55: =(AF37*Inputs!C64)+(AF27*(Inputs!C66+Inputs!C68)) -> 0 | AG55: =(AG37*Inputs!C64)+(AG27*(Inputs!C66+Inputs!C68)) -> 0 | AH55: =(AH37*Inputs!C64)+(AH27*(Inputs!C66+Inputs!C68)) -> 0 | AI55: =(AI37*Inputs!C64)+(AI27*(Inputs!C66+Inputs!C68)) -> 0 | AJ55: =(AJ37*Inputs!C64)+(AJ27*(Inputs!C66+Inputs!C68)) -> 0 | AK55: =(AK37*Inputs!C64)+(AK27*(Inputs!C66+Inputs!C68)) -> 0 | AL55: =(AL37*Inputs!C64)+(AL27*(Inputs!C66+Inputs!C68)) -> 0 | AM55: =(AM37*Inputs!C64)+(AM27*(Inputs!C66+Inputs!C68)) -> 0
A56: Cumulative site FTE onboarded | B56: FTE | C56: Formula | D56: =D55 -> 0 | E56: =D56+E55 -> 0 | F56: =E56+F55 -> 4.15 | G56: =F56+G55 -> 6.3 | H56: =G56+H55 -> 8.45 | I56: =H56+I55 -> 12.6 | J56: =I56+J55 -> 12.6 | K56: =J56+K55 -> 12.6 | L56: =K56+L55 -> 12.6 | ... AM56: =AL56+AM55 -> 12.6

Sheet Revenue_36M
A1: Revenue_36M | Bitcoin anchor revenue plus visible optionality lines
A2: Base-case cashflow uses BTC revenue only. Demand response and hyperscaler rows are formula-driven but off by default in Inputs.
A4: Metric | B4: Unit | C4: Notes
A5: Date | B5: date | C5: Linked from deployment | D5: =Deployment_36M!D5 -> 46204 | E5: =Deployment_36M!E5 -> 46235 | F5: =Deployment_36M!F5 -> 46266 | G5: =Deployment_36M!G5 -> 46296 | H5: =Deployment_36M!H5 -> 46327 | I5: =Deployment_36M!I5 -> 46357 | J5: =Deployment_36M!J5 -> 46388 | K5: =Deployment_36M!K5 -> 46419 | ... AM5: =Deployment_36M!AM5 -> 47270
A6: Days in month | B6: days | C6: Linked from deployment | D6: =Deployment_36M!D6 -> 31 | E6: =Deployment_36M!E6 -> 31 | F6: =Deployment_36M!F6 -> 30 | G6: =Deployment_36M!G6 -> 31 | H6: =Deployment_36M!H6 -> 30 | I6: =Deployment_36M!I6 -> 31 | J6: =Deployment_36M!J6 -> 31 | K6: =Deployment_36M!K6 -> 28 | ... AM6: =Deployment_36M!AM6 -> 30
A8: BTC price (USD) | B8: USD/BTC | C8: Monthly compounding from annual growth | D8: =Inputs!C21 -> 75000 | E8: =D8*POWER(1+Inputs!C22,1/12) -> 75878.619 | F8: =E8*POWER(1+Inputs!C22,1/12) -> 76767.53 | G8: =F8*POWER(1+Inputs!C22,1/12) -> 77666.856 | H8: =G8*POWER(1+Inputs!C22,1/12) -> 78576.716 | I8: =H8*POWER(1+Inputs!C22,1/12) -> 79497.236 | J8: =I8*POWER(1+Inputs!C22,1/12) -> 80428.54 | K8: =J8*POWER(1+Inputs!C22,1/12) -> 81370.753 | L8: =K8*POWER(1+Inputs!C22,1/12) -> 82324.005 | M8: =L8*POWER(1+Inputs!C22,1/12) -> 83288.424 | N8: =M8*POWER(1+Inputs!C22,1/12) -> 84264.141 | O8: =N8*POWER(1+Inputs!C22,1/12) -> 85251.288 | P8: =O8*POWER(1+Inputs!C22,1/12) -> 86250 | Q8: =P8*POWER(1+Inputs!C22,1/12) -> 87260.412 | R8: =Q8*POWER(1+Inputs!C22,1/12) -> 88282.66 | S8: =R8*POWER(1+Inputs!C22,1/12) -> 89316.884 | T8: =S8*POWER(1+Inputs!C22,1/12) -> 90363.224 | U8: =T8*POWER(1+Inputs!C22,1/12) -> 91421.822 | V8: =U8*POWER(1+Inputs!C22,1/12) -> 92492.821 | W8: =V8*POWER(1+Inputs!C22,1/12) -> 93576.366 | X8: =W8*POWER(1+Inputs!C22,1/12) -> 94672.606 | Y8: =X8*POWER(1+Inputs!C22,1/12) -> 95781.687 | Z8: =Y8*POWER(1+Inputs!C22,1/12) -> 96903.762 | AA8: =Z8*POWER(1+Inputs!C22,1/12) -> 98038.981 | AB8: =AA8*POWER(1+Inputs!C22,1/12) -> 99187.5 | AC8: =AB8*POWER(1+Inputs!C22,1/12) -> 100349.47 | AD8: =AC8*POWER(1+Inputs!C22,1/12) -> 101525.06 | AE8: =AD8*POWER(1+Inputs!C22,1/12) -> 102714.42 | AF8: =AE8*POWER(1+Inputs!C22,1/12) -> 103917.71 | AG8: =AF8*POWER(1+Inputs!C22,1/12) -> 105135.09 | AH8: =AG8*POWER(1+Inputs!C22,1/12) -> 106366.74 | AI8: =AH8*POWER(1+Inputs!C22,1/12) -> 107612.82 | AJ8: =AI8*POWER(1+Inputs!C22,1/12) -> 108873.5 | AK8: =AJ8*POWER(1+Inputs!C22,1/12) -> 110148.94 | AL8: =AK8*POWER(1+Inputs!C22,1/12) -> 111439.33 | AM8: =AL8*POWER(1+Inputs!C22,1/12) -> 112744.83
A9: BTC price (ZAR) | B9: ZAR/BTC | C9: USD price x FX | D9: =D8*Inputs!C20 -> 1275000 | E9: =E8*Inputs!C20 -> 1289936.5 | F9: =F8*Inputs!C20 -> 1305048 | G9: =G8*Inputs!C20 -> 1320336.5 | H9: =H8*Inputs!C20 -> 1335804.2 | I9: =I8*Inputs!C20 -> 1351453 | J9: =J8*Inputs!C20 -> 1367285.2 | K9: =K8*Inputs!C20 -> 1383302.8 | L9: =L8*Inputs!C20 -> 1399508.1 | M9: =M8*Inputs!C20 -> 1415903.2 | N9: =N8*Inputs!C20 -> 1432490.4 | O9: =O8*Inputs!C20 -> 1449271.9 | P9: =P8*Inputs!C20 -> 1466250 | Q9: =Q8*Inputs!C20 -> 1483427 | R9: =R8*Inputs!C20 -> 1500805.2 | S9: =S8*Inputs!C20 -> 1518387 | T9: =T8*Inputs!C20 -> 1536174.8 | U9: =U8*Inputs!C20 -> 1554171 | V9: =V8*Inputs!C20 -> 1572378 | W9: =W8*Inputs!C20 -> 1590798.2 | X9: =X8*Inputs!C20 -> 1609434.3 | Y9: =Y8*Inputs!C20 -> 1628288.7 | Z9: =Z8*Inputs!C20 -> 1647364 | AA9: =AA8*Inputs!C20 -> 1666662.7 | AB9: =AB8*Inputs!C20 -> 1686187.5 | AC9: =AC8*Inputs!C20 -> 1705941 | AD9: =AD8*Inputs!C20 -> 1725926 | AE9: =AE8*Inputs!C20 -> 1746145.1 | AF9: =AF8*Inputs!C20 -> 1766601 | AG9: =AG8*Inputs!C20 -> 1787296.6 | AH9: =AH8*Inputs!C20 -> 1808234.6 | AI9: =AI8*Inputs!C20 -> 1829418 | AJ9: =AJ8*Inputs!C20 -> 1850849.4 | AK9: =AK8*Inputs!C20 -> 1872532 | AL9: =AL8*Inputs!C20 -> 1894468.5 | AM9: =AM8*Inputs!C20 -> 1916662.1
A10: Network hash | B10: TH/s | C10: Monthly compounding from annual growth | D10: =Inputs!C23 -> 900000000 | E10: =D10*POWER(1+Inputs!C24,1/12) -> 9.0717673e+08 | F10: =E10*POWER(1+Inputs!C24,1/12) -> 9.1441068e+08 | G10: =F10*POWER(1+Inputs!C24,1/12) -> 9.2170232e+08 | H10: =G10*POWER(1+Inputs!C24,1/12) -> 9.290521e+08 | I10: =H10*POWER(1+Inputs!C24,1/12) -> 9.364605e+08 | J10: =I10*POWER(1+Inputs!C24,1/12) -> 9.4392796e+08 | K10: =J10*POWER(1+Inputs!C24,1/12) -> 9.5145498e+08 | L10: =K10*POWER(1+Inputs!C24,1/12) -> 9.5904201e+08 | M10: =L10*POWER(1+Inputs!C24,1/12) -> 9.6668955e+08 | N10: =M10*POWER(1+Inputs!C24,1/12) -> 9.7439807e+08 | O10: =N10*POWER(1+Inputs!C24,1/12) -> 9.8216805e+08 | P10: =O10*POWER(1+Inputs!C24,1/12) -> 9.9e+08 | Q10: =P10*POWER(1+Inputs!C24,1/12) -> 9.978944e+08 | R10: =Q10*POWER(1+Inputs!C24,1/12) -> 1.0058517e+09 | S10: =R10*POWER(1+Inputs!C24,1/12) -> 1.0138726e+09 | T10: =S10*POWER(1+Inputs!C24,1/12) -> 1.0219573e+09 | U10: =T10*POWER(1+Inputs!C24,1/12) -> 1.0301065e+09 | V10: =U10*POWER(1+Inputs!C24,1/12) -> 1.0383208e+09 | W10: =V10*POWER(1+Inputs!C24,1/12) -> 1.0466005e+09 | X10: =W10*POWER(1+Inputs!C24,1/12) -> 1.0549462e+09 | Y10: =X10*POWER(1+Inputs!C24,1/12) -> 1.0633585e+09 | Z10: =Y10*POWER(1+Inputs!C24,1/12) -> 1.0718379e+09 | AA10: =Z10*POWER(1+Inputs!C24,1/12) -> 1.0803849e+09 | AB10: =AA10*POWER(1+Inputs!C24,1/12) -> 1.089e+09 | AC10: =AB10*POWER(1+Inputs!C24,1/12) -> 1.0976838e+09 | AD10: =AC10*POWER(1+Inputs!C24,1/12) -> 1.1064369e+09 | AE10: =AD10*POWER(1+Inputs!C24,1/12) -> 1.1152598e+09 | AF10: =AE10*POWER(1+Inputs!C24,1/12) -> 1.124153e+09 | AG10: =AF10*POWER(1+Inputs!C24,1/12) -> 1.1331172e+09 | AH10: =AG10*POWER(1+Inputs!C24,1/12) -> 1.1421528e+09 | AI10: =AH10*POWER(1+Inputs!C24,1/12) -> 1.1512605e+09 | AJ10: =AI10*POWER(1+Inputs!C24,1/12) -> 1.1604408e+09 | AK10: =AJ10*POWER(1+Inputs!C24,1/12) -> 1.1696944e+09 | AL10: =AK10*POWER(1+Inputs!C24,1/12) -> 1.1790217e+09 | AM10: =AL10*POWER(1+Inputs!C24,1/12) -> 1.1884233e+09
A11: Network BTC mined | B11: BTC/month | C11: Blocks/day x subsidy x fee factor x days | D11: =D6*Inputs!C25*Inputs!C26*(1+Inputs!C27) -> 16042.5 | E11: =E6*Inputs!C25*Inputs!C26*(1+Inputs!C27) -> 16042.5 | F11: =F6*Inputs!C25*Inputs!C26*(1+Inputs!C27) -> 15525 | G11: =G6*Inputs!C25*Inputs!C26*(1+Inputs!C27) -> 16042.5 | H11: =H6*Inputs!C25*Inputs!C26*(1+Inputs!C27) -> 15525 | I11: =I6*Inputs!C25*Inputs!C26*(1+Inputs!C27) -> 16042.5 | J11: =J6*Inputs!C25*Inputs!C26*(1+Inputs!C27) -> 16042.5 | K11: =K6*Inputs!C25*Inputs!C26*(1+Inputs!C27) -> 14490 | L11: =L6*Inputs!C25*Inputs!C26*(1+Inputs!C27) -> 16042.5 | M11: =M6*Inputs!C25*Inputs!C26*(1+Inputs!C27) -> 15525 | N11: =N6*Inputs!C25*Inputs!C26*(1+Inputs!C27) -> 16042.5 | O11: =O6*Inputs!C25*Inputs!C26*(1+Inputs!C27) -> 15525 | P11: =P6*Inputs!C25*Inputs!C26*(1+Inputs!C27) -> 16042.5 | Q11: =Q6*Inputs!C25*Inputs!C26*(1+Inputs!C27) -> 16042.5 | R11: =R6*Inputs!C25*Inputs!C26*(1+Inputs!C27) -> 15525 | S11: =S6*Inputs!C25*Inputs!C26*(1+Inputs!C27) -> 16042.5 | T11: =T6*Inputs!C25*Inputs!C26*(1+Inputs!C27) -> 15525 | U11: =U6*Inputs!C25*Inputs!C26*(1+Inputs!C27) -> 16042.5 | V11: =V6*Inputs!C25*Inputs!C26*(1+Inputs!C27) -> 16042.5 | W11: =W6*Inputs!C25*Inputs!C26*(1+Inputs!C27) -> 15007.5 | X11: =X6*Inputs!C25*Inputs!C26*(1+Inputs!C27) -> 16042.5 | Y11: =Y6*Inputs!C25*Inputs!C26*(1+Inputs!C27) -> 15525 | Z11: =Z6*Inputs!C25*Inputs!C26*(1+Inputs!C27) -> 16042.5 | AA11: =AA6*Inputs!C25*Inputs!C26*(1+Inputs!C27) -> 15525 | AB11: =AB6*Inputs!C25*Inputs!C26*(1+Inputs!C27) -> 16042.5 | AC11: =AC6*Inputs!C25*Inputs!C26*(1+Inputs!C27) -> 16042.5 | AD11: =AD6*Inputs!C25*Inputs!C26*(1+Inputs!C27) -> 15525 | AE11: =AE6*Inputs!C25*Inputs!C26*(1+Inputs!C27) -> 16042.5 | AF11: =AF6*Inputs!C25*Inputs!C26*(1+Inputs!C27) -> 15525 | AG11: =AG6*Inputs!C25*Inputs!C26*(1+Inputs!C27) -> 16042.5 | AH11: =AH6*Inputs!C25*Inputs!C26*(1+Inputs!C27) -> 16042.5 | AI11: =AI6*Inputs!C25*Inputs!C26*(1+Inputs!C27) -> 14490 | AJ11: =AJ6*Inputs!C25*Inputs!C26*(1+Inputs!C27) -> 16042.5 | AK11: =AK6*Inputs!C25*Inputs!C26*(1+Inputs!C27) -> 15525 | AL11: =AL6*Inputs!C25*Inputs!C26*(1+Inputs!C27) -> 16042.5 | AM11: =AM6*Inputs!C25*Inputs!C26*(1+Inputs!C27) -> 15525
A14: Grootvlei BTC mined | B14: BTC/month | C14: Uses Grootvlei avg MW, 22h/day and technical uptime | D14: =IF(Deployment_36M!D18=0,0,(Deployment_36M!D18*(1-Inputs!C11)*1000000/Inputs!C40*Inputs!C38*Inputs!C10*Inputs!C12/24/D10*D11) ) -> 0 | E14: =IF(Deployment_36M!E18=0,0,(Deployment_36M!E18*(1-Inputs!C11)*1000000/Inputs!C40*Inputs!C38*Inputs!C10*Inputs!C12/24/E10*E11) ) -> 0 | F14: =IF(Deployment_36M!F18=0,0,(Deployment_36M!F18*(1-Inputs!C11)*1000000/Inputs!C40*Inputs!C38*Inputs!C10*Inputs!C12/24/F10*F11) ) -> 2.8978869 | G14: =IF(Deployment_36M!G18=0,0,(Deployment_36M!G18*(1-Inputs!C11)*1000000/Inputs!C40*Inputs!C38*Inputs!C10*Inputs!C12/24/G10*G11) ) -> 8.9123809 | H14: =IF(Deployment_36M!H18=0,0,(Deployment_36M!H18*(1-Inputs!C11)*1000000/Inputs!C40*Inputs!C38*Inputs!C10*Inputs!C12/24/H10*H11) ) -> 14.261088 | I14: =IF(Deployment_36M!I18=0,0,(Deployment_36M!I18*(1-Inputs!C11)*1000000/Inputs!C40*Inputs!C38*Inputs!C10*Inputs!C12/24/I10*I11) ) -> 17.543852 | J14: =IF(Deployment_36M!J18=0,0,(Deployment_36M!J18*(1-Inputs!C11)*1000000/Inputs!C40*Inputs!C38*Inputs!C10*Inputs!C12/24/J10*J11) ) -> 17.405061 | K14: =IF(Deployment_36M!K18=0,0,(Deployment_36M!K18*(1-Inputs!C11)*1000000/Inputs!C40*Inputs!C38*Inputs!C10*Inputs!C12/24/K10*K11) ) -> 15.596333 | L14: =IF(Deployment_36M!L18=0,0,(Deployment_36M!L18*(1-Inputs!C11)*1000000/Inputs!C40*Inputs!C38*Inputs!C10*Inputs!C12/24/L10*L11) ) -> 17.130766 | M14: =IF(Deployment_36M!M18=0,0,(Deployment_36M!M18*(1-Inputs!C11)*1000000/Inputs!C40*Inputs!C38*Inputs!C10*Inputs!C12/24/M10*M11) ) -> 16.44701 | N14: =IF(Deployment_36M!N18=0,0,(Deployment_36M!N18*(1-Inputs!C11)*1000000/Inputs!C40*Inputs!C38*Inputs!C10*Inputs!C12/24/N10*N11) ) -> 16.860793 | O14: =IF(Deployment_36M!O18=0,0,(Deployment_36M!O18*(1-Inputs!C11)*1000000/Inputs!C40*Inputs!C38*Inputs!C10*Inputs!C12/24/O10*O11) ) -> 16.187813 | P14: =IF(Deployment_36M!P18=0,0,(Deployment_36M!P18*(1-Inputs!C11)*1000000/Inputs!C40*Inputs!C38*Inputs!C10*Inputs!C12/24/P10*P11) ) -> 16.595075 | Q14: =IF(Deployment_36M!Q18=0,0,(Deployment_36M!Q18*(1-Inputs!C11)*1000000/Inputs!C40*Inputs!C38*Inputs!C10*Inputs!C12/24/Q10*Q11) ) -> 16.46379 | R14: =IF(Deployment_36M!R18=0,0,(Deployment_36M!R18*(1-Inputs!C11)*1000000/Inputs!C40*Inputs!C38*Inputs!C10*Inputs!C12/24/R10*R11) ) -> 15.806656 | S14: =IF(Deployment_36M!S18=0,0,(Deployment_36M!S18*(1-Inputs!C11)*1000000/Inputs!C40*Inputs!C38*Inputs!C10*Inputs!C12/24/S10*S11) ) -> 16.204329 | T14: =IF(Deployment_36M!T18=0,0,(Deployment_36M!T18*(1-Inputs!C11)*1000000/Inputs!C40*Inputs!C38*Inputs!C10*Inputs!C12/24/T10*T11) ) -> 15.55755 | U14: =IF(Deployment_36M!U18=0,0,(Deployment_36M!U18*(1-Inputs!C11)*1000000/Inputs!C40*Inputs!C38*Inputs!C10*Inputs!C12/24/U10*U11) ) -> 15.948956 | V14: =IF(Deployment_36M!V18=0,0,(Deployment_36M!V18*(1-Inputs!C11)*1000000/Inputs!C40*Inputs!C38*Inputs!C10*Inputs!C12/24/V10*V11) ) -> 15.822783 | W14: =IF(Deployment_36M!W18=0,0,(Deployment_36M!W18*(1-Inputs!C11)*1000000/Inputs!C40*Inputs!C38*Inputs!C10*Inputs!C12/24/W10*W11) ) -> 14.684859 | X14: =IF(Deployment_36M!X18=0,0,(Deployment_36M!X18*(1-Inputs!C11)*1000000/Inputs!C40*Inputs!C38*Inputs!C10*Inputs!C12/24/X10*X11) ) -> 15.573424 | Y14: =IF(Deployment_36M!Y18=0,0,(Deployment_36M!Y18*(1-Inputs!C11)*1000000/Inputs!C40*Inputs!C38*Inputs!C10*Inputs!C12/24/Y10*Y11) ) -> 14.951827 | Z14: =IF(Deployment_36M!Z18=0,0,(Deployment_36M!Z18*(1-Inputs!C11)*1000000/Inputs!C40*Inputs!C38*Inputs!C10*Inputs!C12/24/Z10*Z11) ) -> 15.327994 | AA14: =IF(Deployment_36M!AA18=0,0,(Deployment_36M!AA18*(1-Inputs!C11)*1000000/Inputs!C40*Inputs!C38*Inputs!C10*Inputs!C12/24/AA10*AA11) ) -> 14.716193 | AB14: =IF(Deployment_36M!AB18=0,0,(Deployment_36M!AB18*(1-Inputs!C11)*1000000/Inputs!C40*Inputs!C38*Inputs!C10*Inputs!C12/24/AB10*AB11) ) -> 15.086432 | AC14: =IF(Deployment_36M!AC18=0,0,(Deployment_36M!AC18*(1-Inputs!C11)*1000000/Inputs!C40*Inputs!C38*Inputs!C10*Inputs!C12/24/AC10*AC11) ) -> 14.967082 | AD14: =IF(Deployment_36M!AD18=0,0,(Deployment_36M!AD18*(1-Inputs!C11)*1000000/Inputs!C40*Inputs!C38*Inputs!C10*Inputs!C12/24/AD10*AD11) ) -> 14.369687 | AE14: =IF(Deployment_36M!AE18=0,0,(Deployment_36M!AE18*(1-Inputs!C11)*1000000/Inputs!C40*Inputs!C38*Inputs!C10*Inputs!C12/24/AE10*AE11) ) -> 14.731208 | AF14: =IF(Deployment_36M!AF18=0,0,(Deployment_36M!AF18*(1-Inputs!C11)*1000000/Inputs!C40*Inputs!C38*Inputs!C10*Inputs!C12/24/AF10*AF11) ) -> 14.143228 | AG14: =IF(Deployment_36M!AG18=0,0,(Deployment_36M!AG18*(1-Inputs!C11)*1000000/Inputs!C40*Inputs!C38*Inputs!C10*Inputs!C12/24/AG10*AG11) ) -> 14.499051 | AH14: =IF(Deployment_36M!AH18=0,0,(Deployment_36M!AH18*(1-Inputs!C11)*1000000/Inputs!C40*Inputs!C38*Inputs!C10*Inputs!C12/24/AH10*AH11) ) -> 14.384348 | AI14: =IF(Deployment_36M!AI18=0,0,(Deployment_36M!AI18*(1-Inputs!C11)*1000000/Inputs!C40*Inputs!C38*Inputs!C10*Inputs!C12/24/AI10*AI11) ) -> 12.889532 | AJ14: =IF(Deployment_36M!AJ18=0,0,(Deployment_36M!AJ18*(1-Inputs!C11)*1000000/Inputs!C40*Inputs!C38*Inputs!C10*Inputs!C12/24/AJ10*AJ11) ) -> 14.157658 | AK14: =IF(Deployment_36M!AK18=0,0,(Deployment_36M!AK18*(1-Inputs!C11)*1000000/Inputs!C40*Inputs!C38*Inputs!C10*Inputs!C12/24/AK10*AK11) ) -> 13.59257 | AL14: =IF(Deployment_36M!AL18=0,0,(Deployment_36M!AL18*(1-Inputs!C11)*1000000/Inputs!C40*Inputs!C38*Inputs!C10*Inputs!C12/24/AL10*AL11) ) -> 13.93454 | AM14: =IF(Deployment_36M!AM18=0,0,(Deployment_36M!AM18*(1-Inputs!C11)*1000000/Inputs!C40*Inputs!C38*Inputs!C10*Inputs!C12/24/AM10*AM11) ) -> 13.378358
A15: AMSA BTC mined | B15: BTC/month | C15: Uses AMSA avg MW and combined grid + solar operating hours | D15: =IF(Deployment_36M!D19=0,0,(Deployment_36M!D19*(1-Inputs!C11)*1000000/Inputs!C40*Inputs!C38*Inputs!C10*(Inputs!C13+Inputs!C14)/24/D10*D11) ) -> 0 | E15: =IF(Deployment_36M!E19=0,0,(Deployment_36M!E19*(1-Inputs!C11)*1000000/Inputs!C40*Inputs!C38*Inputs!C10*(Inputs!C13+Inputs!C14)/24/E10*E11) ) -> 0 | F15: =IF(Deployment_36M!F19=0,0,(Deployment_36M!F19*(1-Inputs!C11)*1000000/Inputs!C40*Inputs!C38*Inputs!C10*(Inputs!C13+Inputs!C14)/24/F10*F11) ) -> 0 | G15: =IF(Deployment_36M!G19=0,0,(Deployment_36M!G19*(1-Inputs!C11)*1000000/Inputs!C40*Inputs!C38*Inputs!C10*(Inputs!C13+Inputs!C14)/24/G10*G11) ) -> 0 | H15: =IF(Deployment_36M!H19=0,0,(Deployment_36M!H19*(1-Inputs!C11)*1000000/Inputs!C40*Inputs!C38*Inputs!C10*(Inputs!C13+Inputs!C14)/24/H10*H11) ) -> 0 | I15: =IF(Deployment_36M!I19=0,0,(Deployment_36M!I19*(1-Inputs!C11)*1000000/Inputs!C40*Inputs!C38*Inputs!C10*(Inputs!C13+Inputs!C14)/24/I10*I11) ) -> 2.7910673 | J15: =IF(Deployment_36M!J19=0,0,(Deployment_36M!J19*(1-Inputs!C11)*1000000/Inputs!C40*Inputs!C38*Inputs!C10*(Inputs!C13+Inputs!C14)/24/J10*J11) ) -> 5.5379741 | K15: =IF(Deployment_36M!K19=0,0,(Deployment_36M!K19*(1-Inputs!C11)*1000000/Inputs!C40*Inputs!C38*Inputs!C10*(Inputs!C13+Inputs!C14)/24/K10*K11) ) -> 4.9624697 | L15: =IF(Deployment_36M!L19=0,0,(Deployment_36M!L19*(1-Inputs!C11)*1000000/Inputs!C40*Inputs!C38*Inputs!C10*(Inputs!C13+Inputs!C14)/24/L10*L11) ) -> 5.4506983 | M15: =IF(Deployment_36M!M19=0,0,(Deployment_36M!M19*(1-Inputs!C11)*1000000/Inputs!C40*Inputs!C38*Inputs!C10*(Inputs!C13+Inputs!C14)/24/M10*M11) ) -> 5.2331395 | N15: =IF(Deployment_36M!N19=0,0,(Deployment_36M!N19*(1-Inputs!C11)*1000000/Inputs!C40*Inputs!C38*Inputs!C10*(Inputs!C13+Inputs!C14)/24/N10*N11) ) -> 5.3647978 | O15: =IF(Deployment_36M!O19=0,0,(Deployment_36M!O19*(1-Inputs!C11)*1000000/Inputs!C40*Inputs!C38*Inputs!C10*(Inputs!C13+Inputs!C14)/24/O10*O11) ) -> 5.1506677 | P15: =IF(Deployment_36M!P19=0,0,(Deployment_36M!P19*(1-Inputs!C11)*1000000/Inputs!C40*Inputs!C38*Inputs!C10*(Inputs!C13+Inputs!C14)/24/P10*P11) ) -> 5.2802511 | Q15: =IF(Deployment_36M!Q19=0,0,(Deployment_36M!Q19*(1-Inputs!C11)*1000000/Inputs!C40*Inputs!C38*Inputs!C10*(Inputs!C13+Inputs!C14)/24/Q10*Q11) ) -> 5.2384788 | R15: =IF(Deployment_36M!R19=0,0,(Deployment_36M!R19*(1-Inputs!C11)*1000000/Inputs!C40*Inputs!C38*Inputs!C10*(Inputs!C13+Inputs!C14)/24/R10*R11) ) -> 5.0293905 | S15: =IF(Deployment_36M!S19=0,0,(Deployment_36M!S19*(1-Inputs!C11)*1000000/Inputs!C40*Inputs!C38*Inputs!C10*(Inputs!C13+Inputs!C14)/24/S10*S11) ) -> 5.1559228 | T15: =IF(Deployment_36M!T19=0,0,(Deployment_36M!T19*(1-Inputs!C11)*1000000/Inputs!C40*Inputs!C38*Inputs!C10*(Inputs!C13+Inputs!C14)/24/T10*T11) ) -> 4.9501297 | U15: =IF(Deployment_36M!U19=0,0,(Deployment_36M!U19*(1-Inputs!C11)*1000000/Inputs!C40*Inputs!C38*Inputs!C10*(Inputs!C13+Inputs!C14)/24/U10*U11) ) -> 5.0746679 | V15: =IF(Deployment_36M!V19=0,0,(Deployment_36M!V19*(1-Inputs!C11)*1000000/Inputs!C40*Inputs!C38*Inputs!C10*(Inputs!C13+Inputs!C14)/24/V10*V11) ) -> 5.0345219 | W15: =IF(Deployment_36M!W19=0,0,(Deployment_36M!W19*(1-Inputs!C11)*1000000/Inputs!C40*Inputs!C38*Inputs!C10*(Inputs!C13+Inputs!C14)/24/W10*W11) ) -> 4.6724552 | X15: =IF(Deployment_36M!X19=0,0,(Deployment_36M!X19*(1-Inputs!C11)*1000000/Inputs!C40*Inputs!C38*Inputs!C10*(Inputs!C13+Inputs!C14)/24/X10*X11) ) -> 4.9551802 | Y15: =IF(Deployment_36M!Y19=0,0,(Deployment_36M!Y19*(1-Inputs!C11)*1000000/Inputs!C40*Inputs!C38*Inputs!C10*(Inputs!C13+Inputs!C14)/24/Y10*Y11) ) -> 4.7573995 | Z15: =IF(Deployment_36M!Z19=0,0,(Deployment_36M!Z19*(1-Inputs!C11)*1000000/Inputs!C40*Inputs!C38*Inputs!C10*(Inputs!C13+Inputs!C14)/24/Z10*Z11) ) -> 4.8770889 | AA15: =IF(Deployment_36M!AA19=0,0,(Deployment_36M!AA19*(1-Inputs!C11)*1000000/Inputs!C40*Inputs!C38*Inputs!C10*(Inputs!C13+Inputs!C14)/24/AA10*AA11) ) -> 4.6824252 | AB15: =IF(Deployment_36M!AB19=0,0,(Deployment_36M!AB19*(1-Inputs!C11)*1000000/Inputs!C40*Inputs!C38*Inputs!C10*(Inputs!C13+Inputs!C14)/24/AB10*AB11) ) -> 4.8002283 | AC15: =IF(Deployment_36M!AC19=0,0,(Deployment_36M!AC19*(1-Inputs!C11)*1000000/Inputs!C40*Inputs!C38*Inputs!C10*(Inputs!C13+Inputs!C14)/24/AC10*AC11) ) -> 4.7622534 | AD15: =IF(Deployment_36M!AD19=0,0,(Deployment_36M!AD19*(1-Inputs!C11)*1000000/Inputs!C40*Inputs!C38*Inputs!C10*(Inputs!C13+Inputs!C14)/24/AD10*AD11) ) -> 4.5721732 | AE15: =IF(Deployment_36M!AE19=0,0,(Deployment_36M!AE19*(1-Inputs!C11)*1000000/Inputs!C40*Inputs!C38*Inputs!C10*(Inputs!C13+Inputs!C14)/24/AE10*AE11) ) -> 4.6872026 | AF15: =IF(Deployment_36M!AF19=0,0,(Deployment_36M!AF19*(1-Inputs!C11)*1000000/Inputs!C40*Inputs!C38*Inputs!C10*(Inputs!C13+Inputs!C14)/24/AF10*AF11) ) -> 4.5001179 | AG15: =IF(Deployment_36M!AG19=0,0,(Deployment_36M!AG19*(1-Inputs!C11)*1000000/Inputs!C40*Inputs!C38*Inputs!C10*(Inputs!C13+Inputs!C14)/24/AG10*AG11) ) -> 4.6133345 | AH15: =IF(Deployment_36M!AH19=0,0,(Deployment_36M!AH19*(1-Inputs!C11)*1000000/Inputs!C40*Inputs!C38*Inputs!C10*(Inputs!C13+Inputs!C14)/24/AH10*AH11) ) -> 4.5768381 | AI15: =IF(Deployment_36M!AI19=0,0,(Deployment_36M!AI19*(1-Inputs!C11)*1000000/Inputs!C40*Inputs!C38*Inputs!C10*(Inputs!C13+Inputs!C14)/24/AI10*AI11) ) -> 4.1012146 | AJ15: =IF(Deployment_36M!AJ19=0,0,(Deployment_36M!AJ19*(1-Inputs!C11)*1000000/Inputs!C40*Inputs!C38*Inputs!C10*(Inputs!C13+Inputs!C14)/24/AJ10*AJ11) ) -> 4.5047093 | AK15: =IF(Deployment_36M!AK19=0,0,(Deployment_36M!AK19*(1-Inputs!C11)*1000000/Inputs!C40*Inputs!C38*Inputs!C10*(Inputs!C13+Inputs!C14)/24/AK10*AK11) ) -> 4.3249087 | AL15: =IF(Deployment_36M!AL19=0,0,(Deployment_36M!AL19*(1-Inputs!C11)*1000000/Inputs!C40*Inputs!C38*Inputs!C10*(Inputs!C13+Inputs!C14)/24/AL10*AL11) ) -> 4.4337172 | AM15: =IF(Deployment_36M!AM19=0,0,(Deployment_36M!AM19*(1-Inputs!C11)*1000000/Inputs!C40*Inputs!C38*Inputs!C10*(Inputs!C13+Inputs!C14)/24/AM10*AM11) ) -> 4.2567501
A16: Total BTC mined | B16: BTC/month | C16: Sum of sites | D16: =D14+D15 -> 0 | E16: =E14+E15 -> 0 | F16: =F14+F15 -> 2.8978869 | G16: =G14+G15 -> 8.9123809 | H16: =H14+H15 -> 14.261088 | I16: =I14+I15 -> 20.334919 | J16: =J14+J15 -> 22.943036 | K16: =K14+K15 -> 20.558803 | ... AM16: =AM14+AM15 -> 17.635108
A17: BTC revenue | B17: ZAR'000 | C17: Base-case anchor revenue | D17: =D16*D9/1000 -> 0 | E17: =E16*E9/1000 -> 0 | F17: =F16*F9/1000 -> 3781.8816 | G17: =G16*G9/1000 -> 11767.342 | H17: =H16*H9/1000 -> 19050.021 | I17: =I16*I9/1000 -> 27481.688 | J17: =J16*J9/1000 -> 31369.672 | K17: =K16*K9/1000 -> 28439.05 | ... AM17: =AM16*AM9/1000 -> 33800.542
A18: Demand response revenue | B18: ZAR'000 | C18: Optionality line; off by default | D18: =IF(AND(Inputs!C82=1,1>=Inputs!C83),Deployment_36M!D21*Inputs!C85*D6*1000*Inputs!C84*Inputs!C86/1000,0) -> 0 | E18: =IF(AND(Inputs!C82=1,2>=Inputs!C83),Deployment_36M!E21*Inputs!C85*E6*1000*Inputs!C84*Inputs!C86/1000,0) -> 0 | F18: =IF(AND(Inputs!C82=1,3>=Inputs!C83),Deployment_36M!F21*Inputs!C85*F6*1000*Inputs!C84*Inputs!C86/1000,0) -> 0 | G18: =IF(AND(Inputs!C82=1,4>=Inputs!C83),Deployment_36M!G21*Inputs!C85*G6*1000*Inputs!C84*Inputs!C86/1000,0) -> 0 | H18: =IF(AND(Inputs!C82=1,5>=Inputs!C83),Deployment_36M!H21*Inputs!C85*H6*1000*Inputs!C84*Inputs!C86/1000,0) -> 0 | I18: =IF(AND(Inputs!C82=1,6>=Inputs!C83),Deployment_36M!I21*Inputs!C85*I6*1000*Inputs!C84*Inputs!C86/1000,0) -> 0 | J18: =IF(AND(Inputs!C82=1,7>=Inputs!C83),Deployment_36M!J21*Inputs!C85*J6*1000*Inputs!C84*Inputs!C86/1000,0) -> 0 | K18: =IF(AND(Inputs!C82=1,8>=Inputs!C83),Deployment_36M!K21*Inputs!C85*K6*1000*Inputs!C84*Inputs!C86/1000,0) -> 0 | L18: =IF(AND(Inputs!C82=1,9>=Inputs!C83),Deployment_36M!L21*Inputs!C85*L6*1000*Inputs!C84*Inputs!C86/1000,0) -> 0 | M18: =IF(AND(Inputs!C82=1,10>=Inputs!C83),Deployment_36M!M21*Inputs!C85*M6*1000*Inputs!C84*Inputs!C86/1000,0) -> 0 | N18: =IF(AND(Inputs!C82=1,11>=Inputs!C83),Deployment_36M!N21*Inputs!C85*N6*1000*Inputs!C84*Inputs!C86/1000,0) -> 0 | O18: =IF(AND(Inputs!C82=1,12>=Inputs!C83),Deployment_36M!O21*Inputs!C85*O6*1000*Inputs!C84*Inputs!C86/1000,0) -> 0 | P18: =IF(AND(Inputs!C82=1,13>=Inputs!C83),Deployment_36M!P21*Inputs!C85*P6*1000*Inputs!C84*Inputs!C86/1000,0) -> 0 | Q18: =IF(AND(Inputs!C82=1,14>=Inputs!C83),Deployment_36M!Q21*Inputs!C85*Q6*1000*Inputs!C84*Inputs!C86/1000,0) -> 0 | R18: =IF(AND(Inputs!C82=1,15>=Inputs!C83),Deployment_36M!R21*Inputs!C85*R6*1000*Inputs!C84*Inputs!C86/1000,0) -> 0 | S18: =IF(AND(Inputs!C82=1,16>=Inputs!C83),Deployment_36M!S21*Inputs!C85*S6*1000*Inputs!C84*Inputs!C86/1000,0) -> 0 | T18: =IF(AND(Inputs!C82=1,17>=Inputs!C83),Deployment_36M!T21*Inputs!C85*T6*1000*Inputs!C84*Inputs!C86/1000,0) -> 0 | U18: =IF(AND(Inputs!C82=1,18>=Inputs!C83),Deployment_36M!U21*Inputs!C85*U6*1000*Inputs!C84*Inputs!C86/1000,0) -> 0 | V18: =IF(AND(Inputs!C82=1,19>=Inputs!C83),Deployment_36M!V21*Inputs!C85*V6*1000*Inputs!C84*Inputs!C86/1000,0) -> 0 | W18: =IF(AND(Inputs!C82=1,20>=Inputs!C83),Deployment_36M!W21*Inputs!C85*W6*1000*Inputs!C84*Inputs!C86/1000,0) -> 0 | X18: =IF(AND(Inputs!C82=1,21>=Inputs!C83),Deployment_36M!X21*Inputs!C85*X6*1000*Inputs!C84*Inputs!C86/1000,0) -> 0 | Y18: =IF(AND(Inputs!C82=1,22>=Inputs!C83),Deployment_36M!Y21*Inputs!C85*Y6*1000*Inputs!C84*Inputs!C86/1000,0) -> 0 | Z18: =IF(AND(Inputs!C82=1,23>=Inputs!C83),Deployment_36M!Z21*Inputs!C85*Z6*1000*Inputs!C84*Inputs!C86/1000,0) -> 0 | AA18: =IF(AND(Inputs!C82=1,24>=Inputs!C83),Deployment_36M!AA21*Inputs!C85*AA6*1000*Inputs!C84*Inputs!C86/1000,0) -> 0 | AB18: =IF(AND(Inputs!C82=1,25>=Inputs!C83),Deployment_36M!AB21*Inputs!C85*AB6*1000*Inputs!C84*Inputs!C86/1000,0) -> 0 | AC18: =IF(AND(Inputs!C82=1,26>=Inputs!C83),Deployment_36M!AC21*Inputs!C85*AC6*1000*Inputs!C84*Inputs!C86/1000,0) -> 0 | AD18: =IF(AND(Inputs!C82=1,27>=Inputs!C83),Deployment_36M!AD21*Inputs!C85*AD6*1000*Inputs!C84*Inputs!C86/1000,0) -> 0 | AE18: =IF(AND(Inputs!C82=1,28>=Inputs!C83),Deployment_36M!AE21*Inputs!C85*AE6*1000*Inputs!C84*Inputs!C86/1000,0) -> 0 | AF18: =IF(AND(Inputs!C82=1,29>=Inputs!C83),Deployment_36M!AF21*Inputs!C85*AF6*1000*Inputs!C84*Inputs!C86/1000,0) -> 0 | AG18: =IF(AND(Inputs!C82=1,30>=Inputs!C83),Deployment_36M!AG21*Inputs!C85*AG6*1000*Inputs!C84*Inputs!C86/1000,0) -> 0 | AH18: =IF(AND(Inputs!C82=1,31>=Inputs!C83),Deployment_36M!AH21*Inputs!C85*AH6*1000*Inputs!C84*Inputs!C86/1000,0) -> 0 | AI18: =IF(AND(Inputs!C82=1,32>=Inputs!C83),Deployment_36M!AI21*Inputs!C85*AI6*1000*Inputs!C84*Inputs!C86/1000,0) -> 0 | AJ18: =IF(AND(Inputs!C82=1,33>=Inputs!C83),Deployment_36M!AJ21*Inputs!C85*AJ6*1000*Inputs!C84*Inputs!C86/1000,0) -> 0 | AK18: =IF(AND(Inputs!C82=1,34>=Inputs!C83),Deployment_36M!AK21*Inputs!C85*AK6*1000*Inputs!C84*Inputs!C86/1000,0) -> 0 | AL18: =IF(AND(Inputs!C82=1,35>=Inputs!C83),Deployment_36M!AL21*Inputs!C85*AL6*1000*Inputs!C84*Inputs!C86/1000,0) -> 0 | AM18: =IF(AND(Inputs!C82=1,36>=Inputs!C83),Deployment_36M!AM21*Inputs!C85*AM6*1000*Inputs!C84*Inputs!C86/1000,0) -> 0
A19: Hyperscaler resale revenue | B19: ZAR'000 | C19: Optionality line; off by default | D19: =IF(AND(Inputs!C87=1,1>=Inputs!C88),MIN(Deployment_36M!D21,Inputs!C89)*Inputs!C90*D6*Inputs!C91*Inputs!C20,0)/1000 -> 0 | E19: =IF(AND(Inputs!C87=1,2>=Inputs!C88),MIN(Deployment_36M!E21,Inputs!C89)*Inputs!C90*E6*Inputs!C91*Inputs!C20,0)/1000 -> 0 | F19: =IF(AND(Inputs!C87=1,3>=Inputs!C88),MIN(Deployment_36M!F21,Inputs!C89)*Inputs!C90*F6*Inputs!C91*Inputs!C20,0)/1000 -> 0 | G19: =IF(AND(Inputs!C87=1,4>=Inputs!C88),MIN(Deployment_36M!G21,Inputs!C89)*Inputs!C90*G6*Inputs!C91*Inputs!C20,0)/1000 -> 0 | H19: =IF(AND(Inputs!C87=1,5>=Inputs!C88),MIN(Deployment_36M!H21,Inputs!C89)*Inputs!C90*H6*Inputs!C91*Inputs!C20,0)/1000 -> 0 | I19: =IF(AND(Inputs!C87=1,6>=Inputs!C88),MIN(Deployment_36M!I21,Inputs!C89)*Inputs!C90*I6*Inputs!C91*Inputs!C20,0)/1000 -> 0 | J19: =IF(AND(Inputs!C87=1,7>=Inputs!C88),MIN(Deployment_36M!J21,Inputs!C89)*Inputs!C90*J6*Inputs!C91*Inputs!C20,0)/1000 -> 0 | K19: =IF(AND(Inputs!C87=1,8>=Inputs!C88),MIN(Deployment_36M!K21,Inputs!C89)*Inputs!C90*K6*Inputs!C91*Inputs!C20,0)/1000 -> 0 | L19: =IF(AND(Inputs!C87=1,9>=Inputs!C88),MIN(Deployment_36M!L21,Inputs!C89)*Inputs!C90*L6*Inputs!C91*Inputs!C20,0)/1000 -> 0 | M19: =IF(AND(Inputs!C87=1,10>=Inputs!C88),MIN(Deployment_36M!M21,Inputs!C89)*Inputs!C90*M6*Inputs!C91*Inputs!C20,0)/1000 -> 0 | N19: =IF(AND(Inputs!C87=1,11>=Inputs!C88),MIN(Deployment_36M!N21,Inputs!C89)*Inputs!C90*N6*Inputs!C91*Inputs!C20,0)/1000 -> 0 | O19: =IF(AND(Inputs!C87=1,12>=Inputs!C88),MIN(Deployment_36M!O21,Inputs!C89)*Inputs!C90*O6*Inputs!C91*Inputs!C20,0)/1000 -> 0 | P19: =IF(AND(Inputs!C87=1,13>=Inputs!C88),MIN(Deployment_36M!P21,Inputs!C89)*Inputs!C90*P6*Inputs!C91*Inputs!C20,0)/1000 -> 0 | Q19: =IF(AND(Inputs!C87=1,14>=Inputs!C88),MIN(Deployment_36M!Q21,Inputs!C89)*Inputs!C90*Q6*Inputs!C91*Inputs!C20,0)/1000 -> 0 | R19: =IF(AND(Inputs!C87=1,15>=Inputs!C88),MIN(Deployment_36M!R21,Inputs!C89)*Inputs!C90*R6*Inputs!C91*Inputs!C20,0)/1000 -> 0 | S19: =IF(AND(Inputs!C87=1,16>=Inputs!C88),MIN(Deployment_36M!S21,Inputs!C89)*Inputs!C90*S6*Inputs!C91*Inputs!C20,0)/1000 -> 0 | T19: =IF(AND(Inputs!C87=1,17>=Inputs!C88),MIN(Deployment_36M!T21,Inputs!C89)*Inputs!C90*T6*Inputs!C91*Inputs!C20,0)/1000 -> 0 | U19: =IF(AND(Inputs!C87=1,18>=Inputs!C88),MIN(Deployment_36M!U21,Inputs!C89)*Inputs!C90*U6*Inputs!C91*Inputs!C20,0)/1000 -> 0 | V19: =IF(AND(Inputs!C87=1,19>=Inputs!C88),MIN(Deployment_36M!V21,Inputs!C89)*Inputs!C90*V6*Inputs!C91*Inputs!C20,0)/1000 -> 0 | W19: =IF(AND(Inputs!C87=1,20>=Inputs!C88),MIN(Deployment_36M!W21,Inputs!C89)*Inputs!C90*W6*Inputs!C91*Inputs!C20,0)/1000 -> 0 | X19: =IF(AND(Inputs!C87=1,21>=Inputs!C88),MIN(Deployment_36M!X21,Inputs!C89)*Inputs!C90*X6*Inputs!C91*Inputs!C20,0)/1000 -> 0 | Y19: =IF(AND(Inputs!C87=1,22>=Inputs!C88),MIN(Deployment_36M!Y21,Inputs!C89)*Inputs!C90*Y6*Inputs!C91*Inputs!C20,0)/1000 -> 0 | Z19: =IF(AND(Inputs!C87=1,23>=Inputs!C88),MIN(Deployment_36M!Z21,Inputs!C89)*Inputs!C90*Z6*Inputs!C91*Inputs!C20,0)/1000 -> 0 | AA19: =IF(AND(Inputs!C87=1,24>=Inputs!C88),MIN(Deployment_36M!AA21,Inputs!C89)*Inputs!C90*AA6*Inputs!C91*Inputs!C20,0)/1000 -> 0 | AB19: =IF(AND(Inputs!C87=1,25>=Inputs!C88),MIN(Deployment_36M!AB21,Inputs!C89)*Inputs!C90*AB6*Inputs!C91*Inputs!C20,0)/1000 -> 0 | AC19: =IF(AND(Inputs!C87=1,26>=Inputs!C88),MIN(Deployment_36M!AC21,Inputs!C89)*Inputs!C90*AC6*Inputs!C91*Inputs!C20,0)/1000 -> 0 | AD19: =IF(AND(Inputs!C87=1,27>=Inputs!C88),MIN(Deployment_36M!AD21,Inputs!C89)*Inputs!C90*AD6*Inputs!C91*Inputs!C20,0)/1000 -> 0 | AE19: =IF(AND(Inputs!C87=1,28>=Inputs!C88),MIN(Deployment_36M!AE21,Inputs!C89)*Inputs!C90*AE6*Inputs!C91*Inputs!C20,0)/1000 -> 0 | AF19: =IF(AND(Inputs!C87=1,29>=Inputs!C88),MIN(Deployment_36M!AF21,Inputs!C89)*Inputs!C90*AF6*Inputs!C91*Inputs!C20,0)/1000 -> 0 | AG19: =IF(AND(Inputs!C87=1,30>=Inputs!C88),MIN(Deployment_36M!AG21,Inputs!C89)*Inputs!C90*AG6*Inputs!C91*Inputs!C20,0)/1000 -> 0 | AH19: =IF(AND(Inputs!C87=1,31>=Inputs!C88),MIN(Deployment_36M!AH21,Inputs!C89)*Inputs!C90*AH6*Inputs!C91*Inputs!C20,0)/1000 -> 0 | AI19: =IF(AND(Inputs!C87=1,32>=Inputs!C88),MIN(Deployment_36M!AI21,Inputs!C89)*Inputs!C90*AI6*Inputs!C91*Inputs!C20,0)/1000 -> 0 | AJ19: =IF(AND(Inputs!C87=1,33>=Inputs!C88),MIN(Deployment_36M!AJ21,Inputs!C89)*Inputs!C90*AJ6*Inputs!C91*Inputs!C20,0)/1000 -> 0 | AK19: =IF(AND(Inputs!C87=1,34>=Inputs!C88),MIN(Deployment_36M!AK21,Inputs!C89)*Inputs!C90*AK6*Inputs!C91*Inputs!C20,0)/1000 -> 0 | AL19: =IF(AND(Inputs!C87=1,35>=Inputs!C88),MIN(Deployment_36M!AL21,Inputs!C89)*Inputs!C90*AL6*Inputs!C91*Inputs!C20,0)/1000 -> 0 | AM19: =IF(AND(Inputs!C87=1,36>=Inputs!C88),MIN(Deployment_36M!AM21,Inputs!C89)*Inputs!C90*AM6*Inputs!C91*Inputs!C20,0)/1000 -> 0
A20: Total revenue - base case | B20: ZAR'000 | C20: Base case used in Funding sheet | D20: =D17 -> 0 | E20: =E17 -> 0 | F20: =F17 -> 3781.8816 | G20: =G17 -> 11767.342 | H20: =H17 -> 19050.021 | I20: =I17 -> 27481.688 | J20: =J17 -> 31369.672 | K20: =K17 -> 28439.05 | ... AM20: =AM17 -> 33800.542
A21: Total revenue - with optionality | B21: ZAR'000 | C21: BTC + toggled optionality | D21: =D17+D18+D19 -> 0 | E21: =E17+E18+E19 -> 0 | F21: =F17+F18+F19 -> 3781.8816 | G21: =G17+G18+G19 -> 11767.342 | H21: =H17+H18+H19 -> 19050.021 | I21: =I17+I18+I19 -> 27481.688 | J21: =J17+J18+J19 -> 31369.672 | K21: =K17+K18+K19 -> 28439.05 | ... AM21: =AM17+AM18+AM19 -> 33800.542

Sheet Opex_36M
A1: Opex_36M | Site energy, people and recurring operating costs
A2: Energy cost is the dominant driver. Payroll and recurring overheads remain visible but simplified.
A4: Metric | B4: Unit | C4: Notes
A5: Date | B5: date | C5: Linked from deployment | D5: =Deployment_36M!D5 -> 46204 | E5: =Deployment_36M!E5 -> 46235 | F5: =Deployment_36M!F5 -> 46266 | G5: =Deployment_36M!G5 -> 46296 | H5: =Deployment_36M!H5 -> 46327 | I5: =Deployment_36M!I5 -> 46357 | J5: =Deployment_36M!J5 -> 46388 | K5: =Deployment_36M!K5 -> 46419 | ... AM5: =Deployment_36M!AM5 -> 47270
A6: Days in month | B6: days | C6: Linked from deployment | D6: =Deployment_36M!D6 -> 31 | E6: =Deployment_36M!E6 -> 31 | F6: =Deployment_36M!F6 -> 30 | G6: =Deployment_36M!G6 -> 31 | H6: =Deployment_36M!H6 -> 30 | I6: =Deployment_36M!I6 -> 31 | J6: =Deployment_36M!J6 -> 31 | K6: =Deployment_36M!K6 -> 28 | ... AM6: =Deployment_36M!AM6 -> 30
A8: Grootvlei electricity cost | B8: ZAR'000 | C8: Gross MW x hours/day x tariff x uptime | D8: =Deployment_36M!D18*Inputs!C12*D6*1000*Inputs!C29*Inputs!C10/1000 -> 0 | E8: =Deployment_36M!E18*Inputs!C12*E6*1000*Inputs!C29*Inputs!C10/1000 -> 0 | F8: =Deployment_36M!F18*Inputs!C12*F6*1000*Inputs!C29*Inputs!C10/1000 -> 1617 | G8: =Deployment_36M!G18*Inputs!C12*G6*1000*Inputs!C29*Inputs!C10/1000 -> 5012.7 | H8: =Deployment_36M!H18*Inputs!C12*H6*1000*Inputs!C29*Inputs!C10/1000 -> 8085 | I8: =Deployment_36M!I18*Inputs!C12*I6*1000*Inputs!C29*Inputs!C10/1000 -> 10025.4 | J8: =Deployment_36M!J18*Inputs!C12*J6*1000*Inputs!C29*Inputs!C10/1000 -> 10025.4 | K8: =Deployment_36M!K18*Inputs!C12*K6*1000*Inputs!C29*Inputs!C10/1000 -> 9055.2 | L8: =Deployment_36M!L18*Inputs!C12*L6*1000*Inputs!C29*Inputs!C10/1000 -> 10025.4 | M8: =Deployment_36M!M18*Inputs!C12*M6*1000*Inputs!C29*Inputs!C10/1000 -> 9702 | N8: =Deployment_36M!N18*Inputs!C12*N6*1000*Inputs!C29*Inputs!C10/1000 -> 10025.4 | O8: =Deployment_36M!O18*Inputs!C12*O6*1000*Inputs!C29*Inputs!C10/1000 -> 9702 | P8: =Deployment_36M!P18*Inputs!C12*P6*1000*Inputs!C30*Inputs!C10/1000 -> 9524.13 | Q8: =Deployment_36M!Q18*Inputs!C12*Q6*1000*Inputs!C30*Inputs!C10/1000 -> 9524.13 | R8: =Deployment_36M!R18*Inputs!C12*R6*1000*Inputs!C30*Inputs!C10/1000 -> 9216.9 | S8: =Deployment_36M!S18*Inputs!C12*S6*1000*Inputs!C30*Inputs!C10/1000 -> 9524.13 | T8: =Deployment_36M!T18*Inputs!C12*T6*1000*Inputs!C30*Inputs!C10/1000 -> 9216.9 | U8: =Deployment_36M!U18*Inputs!C12*U6*1000*Inputs!C30*Inputs!C10/1000 -> 9524.13 | V8: =Deployment_36M!V18*Inputs!C12*V6*1000*Inputs!C30*Inputs!C10/1000 -> 9524.13 | W8: =Deployment_36M!W18*Inputs!C12*W6*1000*Inputs!C30*Inputs!C10/1000 -> 8909.67 | X8: =Deployment_36M!X18*Inputs!C12*X6*1000*Inputs!C30*Inputs!C10/1000 -> 9524.13 | Y8: =Deployment_36M!Y18*Inputs!C12*Y6*1000*Inputs!C30*Inputs!C10/1000 -> 9216.9 | Z8: =Deployment_36M!Z18*Inputs!C12*Z6*1000*Inputs!C30*Inputs!C10/1000 -> 9524.13 | AA8: =Deployment_36M!AA18*Inputs!C12*AA6*1000*Inputs!C30*Inputs!C10/1000 -> 9216.9 | AB8: =Deployment_36M!AB18*Inputs!C12*AB6*1000*Inputs!C31*Inputs!C10/1000 -> 9022.86 | AC8: =Deployment_36M!AC18*Inputs!C12*AC6*1000*Inputs!C31*Inputs!C10/1000 -> 9022.86 | AD8: =Deployment_36M!AD18*Inputs!C12*AD6*1000*Inputs!C31*Inputs!C10/1000 -> 8731.8 | AE8: =Deployment_36M!AE18*Inputs!C12*AE6*1000*Inputs!C31*Inputs!C10/1000 -> 9022.86 | AF8: =Deployment_36M!AF18*Inputs!C12*AF6*1000*Inputs!C31*Inputs!C10/1000 -> 8731.8 | AG8: =Deployment_36M!AG18*Inputs!C12*AG6*1000*Inputs!C31*Inputs!C10/1000 -> 9022.86 | AH8: =Deployment_36M!AH18*Inputs!C12*AH6*1000*Inputs!C31*Inputs!C10/1000 -> 9022.86 | AI8: =Deployment_36M!AI18*Inputs!C12*AI6*1000*Inputs!C31*Inputs!C10/1000 -> 8149.68 | AJ8: =Deployment_36M!AJ18*Inputs!C12*AJ6*1000*Inputs!C31*Inputs!C10/1000 -> 9022.86 | AK8: =Deployment_36M!AK18*Inputs!C12*AK6*1000*Inputs!C31*Inputs!C10/1000 -> 8731.8 | AL8: =Deployment_36M!AL18*Inputs!C12*AL6*1000*Inputs!C31*Inputs!C10/1000 -> 9022.86 | AM8: =Deployment_36M!AM18*Inputs!C12*AM6*1000*Inputs!C31*Inputs!C10/1000 -> 8731.8
