Workbook

Sheet Dashboard
A1: PHASE 1 UNDERWRITING MODEL · ENERGY THAT YIELDS
A2: 20MW proof-of-execution case: 10MW Grootvlei + 10MW AMSA Vanderbijlpark | Funding, commissioning and debt-case underwrite
A4: Selected Case | D4: Phase 1 MW | G4: Site Split | J4: Total Capex
A5: =Controls!$C$4 -> Debt Case | D5: =Controls!$B$32 -> 20 | G5: =Controls!$B$33&" / "&Controls!$B$34&" MW" -> 10 / 10 MW | J5: =SUM(Capex_36M!$O$2:$O$37) -> 511456.86
A6: underwriting scenario | D6: MW (10 GVL + 10 AMSA) | G6: GVL / AMSA | J6: ZAR '000
A9: Peak Funding Req. | D9: Total Equity Drawn | G9: Total Debt Drawn | J9: Peak Debt Balance
A10: =SUM(Funding_36M!$J$2:$J$37)+SUM(Funding_36M!$K$2:$K$37) -> 535535.9 | D10: =SUM(Funding_36M!$J$2:$J$37) -> 68000 | G10: =SUM(Funding_36M!$K$2:$K$37) -> 467535.9 | J10: =MAX(Funding_36M!$T$2:$T$37) -> 482022.09
A11: ZAR '000 (total external) | D11: ZAR '000 | G11: ZAR '000 | J11: ZAR '000
A14: Year-1 EBITDA | D14: 36M Revenue | G14: 36M BTC Mined | J14: Break-even BTC Y1
A15: =Annual_Summary!$C$11 -> 100722.52 | D15: =SUM(Revenue_36M!$P$2:$P$37) -> 578669.44 | G15: =SUM(Revenue_36M!$H$2:$H$37) -> 426.54126 | J15: =Sensitivity!$B$11 -> 42463.035
A16: ZAR '000 | D16: ZAR '000 | G16: BTC | J16: USD/BTC
A19: Min DSCR (12M) | D19: DSCR Covenant | G19: Unlevered IRR | J19: Equity IRR
A20: =MIN(Funding_36M!$AA$14:$AA$37) -> 0.50405629 | D20: =Annual_Summary!$B$26 -> 1.5 | G20: =IFERROR((1+IRR(Funding_36M!$AC$2:$AC$37,0.01))^12-1,"n/a") -> 0.1974839 | J20: =IFERROR((1+IRR(Funding_36M!$AD$2:$AD$37,0.01))^12-1,"n/a") -> 0.31458689
A21: trailing 12-month | D21: indicative minimum | G21: incl. continuation value | J21: levered, continuation value
A24: Closing Cash M36 | D24: Closing Debt M36 | G24: DSRA Funded | J24: Facility Headroom
A25: =INDEX(Funding_36M!$Q$2:$Q$37,36) -> 131624.43 | D25: =INDEX(Funding_36M!$T$2:$T$37,36) -> 482022.09 | G25: =Controls!$B$111 -> 27212.5 | J25: =(Controls!$B$100+Controls!$B$101+Controls!$B$104)-(SUM(Funding_36M!$J$2:$J$37)+SUM(Funding_36M!$K$2:$K$37)) -> 20464.102
A26: ZAR '000 (incl. DSRA) | D26: ZAR '000 | G26: ZAR '000 (restricted) | J26: ZAR '000 vs committed
A29: Capital stack — committed vs drawn (Debt Case)
A30: Tranche | D30: Committed | F30: Drawn | H30: Headroom | J30: Terms
A31: Sponsor equity | D31: =Controls!$B$100 -> 68000 | F31: =SUM(Funding_36M!$J$2:$J$37) -> 68000 | H31: =D31-F31 -> 0 | J31: Drawn first; USD$4M @ R17
A32: Antalpha (asset-backed) | D32: =Controls!$B$101 -> 238000 | F32: =SUM(Funding_36M!$U$2:$U$37) -> 238000 | H32: =D32-F32 -> 0 | J32: 10% USD, 24-mo bullet, Bitmain collateral
A33: DMTN Tranche 1 | D33: =Controls!$B$104 -> 250000 | F33: =SUM(Funding_36M!$V$2:$V$37) -> 229535.9 | H33: =D33-F33 -> 20464.102 | J33: 12.25%, 5yr, convertible to equity at IPO
A34: Total committed | D34: =Controls!$B$100+Controls!$B$101+Controls!$B$104 -> 556000 | F34: =F31+F32+F33 -> 535535.9 | H34: =D34-F34 -> 20464.102 | J34: vs total external funding requirement
A37: Phase 1 capex reconciliation — this model vs deck (p30)
A38: Capex line | D38: This model | F38: Deck (p30) | H38: Variance | J38: Note
A39: ASIC hardware (S21 XP-class) | D39: =SUM(Capex_36M!$G$2:$G$37) -> 218895.24 | F39: 374000 | H39: =D39-F39 -> -155104.76 | J39: Model uses lower USD/TH (see below)
A40: Hydro containers + cooling | D40: =SUM(Capex_36M!$H$2:$H$37) -> 65450 | F40: 102000 | H40: =D40-F40 -> -36550 | J40: Containers only here; cooling in EPC
A41: Electrical / site EPC | D41: =SUM(Capex_36M!$I$2:$I$37) -> 126872 | F41: 51000 | H41: =D41-F41 -> 75872 | J41: Model carries fuller EPC scope
A42: Solar PV (AMSA) | D42: =SUM(Capex_36M!$J$2:$J$37) -> 70000 | F42: 0 | H42: =D42-F42 -> 70000 | J42: Added in model; not in deck p30
A43: Spares + tools + setup | D43: =SUM(Capex_36M!$K$2:$K$37)+SUM(Capex_36M!$L$2:$L$37) -> 8712.9048 | F43: 0 | H43: =D43-F43 -> 8712.9048 | J43: Itemised in model
A44: Logistics + duties | D44: =SUM(Capex_36M!$M$2:$M$37) -> 21526.714 | F44: 0 | H44: =D44-F44 -> 21526.714 | J44: Freight, clearing, duty, insurance
A45: Total Phase 1 capex | D45: =SUM(Capex_36M!$O$2:$O$37) -> 511456.86 | F45: 527000 | H45: =D45-F45 -> -15543.143 | J45: Totals within ~3%; mix differs
A46: Hardware cost basis (USD/TH) | D46: =Controls!$B$46/Controls!$B$43 -> 8.45 | F46: ~$11-15 mkt | J46: Model hardware is optimistic; stress in Sensitivity
A49: Structuring flags and underwriting framing
A50: ■ Antalpha R238m facility is a 24-month BULLET (interest-only). Balance incl. capitalised grace interest ≈ R246m falls due in Month 24 and must be refinanced or converted ahead of the Year-3 thin period.
A51: ■ Min trailing-12M DSCR of ~0.50x in Year 3 is BELOW the indicative 1.50x covenant on a standalone BTC-only basis (block-subsidy halving + rising network difficulty compress EBITDA).
A52: Mitigants modelled / available: 24-month Antalpha bullet retired or refinanced before Year 3; DMTN equitised at IPO (conversion toggle in Controls); first-ranking ASIC / container security; funded DSRA of ~R27m; and demand-response + tariff-relief upside in the Sponsor and Upside cases (DR/AI are off in this Debt Case).
A54: Scope: deliberately limited to the initial 20MW proof phase (10MW Grootvlei + 10MW AMSA Vanderbijlpark). Not the 10-year acceleration case; excludes owned-inference GPU economics (Layer 5). Purpose: show funders procurement, commissioning, capex, the actual capital stack, coverage and milestone gates before scale-up capital is released.
A56: IRR note: Unlevered ~20% / Equity ~31% are indicative and depend on the continuation (terminal) value input in Controls — the proven 20MW platform’s value as it scales per the 10-year master model. At zero continuation value the standalone 36-month BTC-only project does not return capital. IRR is shown across continuation values in the Sensitivity tab.
A58: Charts — annual P&L · monthly funding & cash · 20MW deployment ramp

Sheet Controls
A1: BitMach Phase 1 Underwriting Model
A2: Purpose: lender/infrastructure-fund underwriting model for the initial 20MW proof-of-execution phase. Values are in ZAR '000 unless otherwise stated.
A4: Scenario selector | B4: Selected case | C4: Debt Case | D4: Change via dropdown / type exact case name | G4: Scenario table
G5: Case | H5: BTC growth p.a. | I5: Network growth p.a. | J5: Uptime | K5: DR enabled | L5: DR start month | M5: DR recognition factor | N5: AI/DC pilot enabled | O5: AI start month | P5: Equity share | Q5: Debt rate
A6: Timing | G6: Debt Case | H6: 0.05 | I6: 0.2 | J6: 0.96 | K6: 0 | L6: 99 | M6: 0 | N6: 0 | O6: 99 | P6: 0.35 | Q6: 0.13
A7: Start date | B7: 46204 | C7: Date | D7: First month of Phase 1 funding / rollout schedule. | G7: Sponsor Case | H7: 0.1 | I7: 0.15 | J7: 0.97 | K7: 1 | L7: 13 | M7: 0.35 | N7: 0 | O7: 99 | P7: 0.35 | Q7: 0.13
A8: Scenario BTC growth p.a. | B8: =INDEX($H$6:$H$8,MATCH($C$4,$G$6:$G$8,0)) -> 0.05 | C8: % | D8: Linked to selected scenario. | G8: Upside Case | H8: 0.12 | I8: 0.1 | J8: 0.98 | K8: 1 | L8: 7 | M8: 0.6 | N8: 1 | O8: 18 | P8: 0.3 | Q8: 0.11
A9: Scenario network hash growth p.a. | B9: =INDEX($I$6:$I$8,MATCH($C$4,$G$6:$G$8,0)) -> 0.2 | C9: % | D9: Linked to selected scenario; higher values reduce BitMach share of network rewards.
A10: Scenario uptime | B10: =INDEX($J$6:$J$8,MATCH($C$4,$G$6:$G$8,0)) -> 0.96 | C10: % | D10: Technical uptime assumption before strategic curtailment.
A11: DR enabled | B11: =INDEX($K$6:$K$8,MATCH($C$4,$G$6:$G$8,0)) -> 0 | C11: 0/1 | D11: 0 = excluded from debt underwriting; 1 = included in selected scenario.
A12: DR start month | B12: =INDEX($L$6:$L$8,MATCH($C$4,$G$6:$G$8,0)) -> 99 | C12: Month # | D12: Month when DR revenue is allowed to start in selected scenario.
A13: DR recognition factor | B13: =INDEX($M$6:$M$8,MATCH($C$4,$G$6:$G$8,0)) -> 0 | C13: % | D13: Probability / evidence weighting applied to illustrative DR mechanisms.
A14: AI/DC pilot enabled | B14: =INDEX($N$6:$N$8,MATCH($C$4,$G$6:$G$8,0)) -> 0 | C14: 0/1 | D14: Kept off in underwriting cases; shows optional small pilot only in upside.
A15: AI start month | B15: =INDEX($O$6:$O$8,MATCH($C$4,$G$6:$G$8,0)) -> 99 | C15: Month # | D15: Month when optional AI/DC pilot revenue starts in upside case.
A16: Equity share | B16: =INDEX($P$6:$P$8,MATCH($C$4,$G$6:$G$8,0)) -> 0.35 | C16: % | D16: Equity share of external cash funding requirement.
A17: Debt share | B17: =1-B16 -> 0.65 | C17: % | D17: Debt share of external cash funding requirement.
A18: Debt interest rate | B18: =INDEX($Q$6:$Q$8,MATCH($C$4,$G$6:$G$8,0)) -> 0.13 | C18: % | D18: Indicative senior / structured debt rate.
A19: Debt grace period | B19: 12 | C19: Months | D19: Interest capitalises during grace period; debt service starts after month 12.
A20: Debt tenor | B20: 60 | C20: Months | D20: Indicative amortisation tenor for project debt.
A21: Arrangement fee | B21: 0.01 | C21: % | D21: Deducted from gross debt draw in funding schedule.
A22: Minimum cash buffer | B22: 5000 | C22: ZAR '000 | D22: Minimum operating cash buffer held through the forecast (separate from DSRA below).
A23: BTC / protocol
A24: BTC price start | B24: 75000 | C24: USD/BTC | D24: Starting spot price assumption; stress in Sensitivity tab.
A25: FX rate | B25: 17 | C25: ZAR/USD | D25: Used for BTC revenue and USD-denominated capex.
A26: Network hash start | B26: 900000000 | C26: TH/s | D26: Bitcoin network hash rate starting point.
A27: Block subsidy start | B27: 3.125 | C27: BTC/block | D27: Current subsidy before next halving.
A28: Next halving month | B28: 23 | C28: Month # | D28: Approximate month of next halving within 36-month forecast.
A29: Fee contribution start | B29: 0.12 | C29: % of subsidy | D29: Transaction fee contribution as % of subsidy equivalent in month 1.
A30: Fee contribution monthly increase | B30: 0.0025 | C30: % points | D30: Gradual increase in transaction fee contribution over forecast.
A31: Power / deployment
A32: Phase 1 total mining MW | B32: 20 | C32: MW | D32: Fixed to 10MW Grootvlei + 10MW AMSA Vanderbijlpark.
A33: Grootvlei mining MW | B33: 10 | C33: MW | D33: Phase 1 underwriting site split.
A34: AMSA mining MW | B34: 10 | C34: MW | D34: Phase 1 underwriting site split.
A35: AMSA solar MW | B35: 10 | C35: MW | D35: Solar capacity available for Phase 1 blended power at AMSA.
A36: Mining operating hours | B36: 19 | C36: hours/day | D36: Interruptible mining load profile under Eskom arrangement.
A37: AMSA solar hours | B37: 9 | C37: hours/day | D37: Average solar energy hours used to offset AMSA grid purchases.
A38: Initial Eskom tariff | B38: 1.2 | C38: R/kWh | D38: Agreed / initial tariff assumption for first 18 months.
A39: Post-initial Eskom tariff | B39: 0.6 | C39: R/kWh | D39: Target tariff after initial period.
A40: Initial tariff period | B40: 18 | C40: Months | D40: First 18 months at R1.20/kWh; thereafter R0.60/kWh.
A41: Solar O&M | B41: 0.02 | C41: % capex p.a. | D41: Annual operating cost as % of solar capex.
...

Sheet Monthly_Deployment
A1: Month # | B1: Date | C1: Month | D1: GVL Close MW | E1: AMSA Close MW | F1: Solar Close MW | G1: GVL Open MW | H1: AMSA Open MW | I1: Solar Open MW | J1: Total Close MW | K1: Avg GVL MW | L1: Avg AMSA MW | M1: Avg Solar MW | N1: Total Avg MW | O1: New Mining MW | P1: New Solar MW | Q1: Active Sites | R1: New Containers | S1: Avg Miners | T1: Effective Hashrate TH/s | U1: GVL Grid MWh | V1: AMSA Grid MWh | W1: AMSA Solar MWh
A2: 1 | B2: =EDATE(Controls!$B$7,A2-1) -> 46204 | C2: =TEXT(B2,"mmm-yy") -> Jul-26 | D2: =IF(A2<2,0,IF(A2=2,Controls!$B$33/2,Controls!$B$33)) -> 0 | E2: =IF(A2<3,0,IF(A2=3,Controls!$B$34/2,Controls!$B$34)) -> 0 | F2: =IF(A2<4,0,Controls!$B$35) -> 0 | G2: =0 -> 0 | H2: =0 -> 0 | I2: =0 -> 0 | J2: =D2+E2 -> 0 | K2: =(G2+D2)/2 -> 0 | L2: =(H2+E2)/2 -> 0 | M2: =(I2+F2)/2 -> 0 | N2: =K2+L2 -> 0 | O2: =MAX(J2,0) -> 0 | P2: =MAX(F2,0) -> 0 | Q2: =--(K2>0)+--(L2>0) -> 0 | R2: =CEILING(O2/Controls!$B$49,1) -> 0 | S2: =IF(Controls!$B$45=0,0,N2/(1+Controls!$B$47)*1000000/Controls!$B$45) -> 0 | T2: =S2*Controls!$B$43*(Controls!$B$36/24)*Controls!$B$10 -> 0 | U2: =K2*Controls!$B$36*DAY(EOMONTH(B2,0))*Controls!$B$10 -> 0 | V2: =MAX(L2*Controls!$B$36-MIN(L2,M2)*Controls!$B$37,0)*DAY(EOMONTH(B2,0))*Controls!$B$10 -> 0 | W2: =MIN(L2,M2)*Controls!$B$37*DAY(EOMONTH(B2,0))*Controls!$B$10 -> 0
A3: 2 | B3: =EDATE(Controls!$B$7,A3-1) -> 46235 | C3: =TEXT(B3,"mmm-yy") -> Aug-26 | D3: =IF(A3<2,0,IF(A3=2,Controls!$B$33/2,Controls!$B$33)) -> 5 | E3: =IF(A3<3,0,IF(A3=3,Controls!$B$34/2,Controls!$B$34)) -> 0 | F3: =IF(A3<4,0,Controls!$B$35) -> 0 | G3: =D2 -> 0 | H3: =E2 -> 0 | I3: =F2 -> 0 | J3: =D3+E3 -> 5 | K3: =(G3+D3)/2 -> 2.5 | L3: =(H3+E3)/2 -> 0 | M3: =(I3+F3)/2 -> 0 | N3: =K3+L3 -> 2.5 | O3: =MAX(J3-J2,0) -> 5 | P3: =MAX(F3-F2,0) -> 0 | Q3: =--(K3>0)+--(L3>0) -> 1 | R3: =CEILING(O3/Controls!$B$49,1) -> 3 | S3: =IF(Controls!$B$45=0,0,N3/(1+Controls!$B$47)*1000000/Controls!$B$45) -> 272.10884 | T3: =S3*Controls!$B$43*(Controls!$B$36/24)*Controls!$B$10 -> 144761.9 | U3: =K3*Controls!$B$36*DAY(EOMONTH(B3,0))*Controls!$B$10 -> 1413.6 | V3: =MAX(L3*Controls!$B$36-MIN(L3,M3)*Controls!$B$37,0)*DAY(EOMONTH(B3,0))*Controls!$B$10 -> 0 | W3: =MIN(L3,M3)*Controls!$B$37*DAY(EOMONTH(B3,0))*Controls!$B$10 -> 0
A4: 3 | B4: =EDATE(Controls!$B$7,A4-1) -> 46266 | C4: =TEXT(B4,"mmm-yy") -> Sept-26 | D4: =IF(A4<2,0,IF(A4=2,Controls!$B$33/2,Controls!$B$33)) -> 10 | E4: =IF(A4<3,0,IF(A4=3,Controls!$B$34/2,Controls!$B$34)) -> 5 | F4: =IF(A4<4,0,Controls!$B$35) -> 0 | G4: =D3 -> 5 | H4: =E3 -> 0 | I4: =F3 -> 0 | J4: =D4+E4 -> 15 | K4: =(G4+D4)/2 -> 7.5 | L4: =(H4+E4)/2 -> 2.5 | M4: =(I4+F4)/2 -> 0 | N4: =K4+L4 -> 10 | O4: =MAX(J4-J3,0) -> 10 | P4: =MAX(F4-F3,0) -> 0 | Q4: =--(K4>0)+--(L4>0) -> 2 | R4: =CEILING(O4/Controls!$B$49,1) -> 5 | S4: =IF(Controls!$B$45=0,0,N4/(1+Controls!$B$47)*1000000/Controls!$B$45) -> 1088.4354 | T4: =S4*Controls!$B$43*(Controls!$B$36/24)*Controls!$B$10 -> 579047.62 | U4: =K4*Controls!$B$36*DAY(EOMONTH(B4,0))*Controls!$B$10 -> 4104 | V4: =MAX(L4*Controls!$B$36-MIN(L4,M4)*Controls!$B$37,0)*DAY(EOMONTH(B4,0))*Controls!$B$10 -> 1368 | W4: =MIN(L4,M4)*Controls!$B$37*DAY(EOMONTH(B4,0))*Controls!$B$10 -> 0
A5: 4 | B5: =EDATE(Controls!$B$7,A5-1) -> 46296 | C5: =TEXT(B5,"mmm-yy") -> Oct-26 | D5: =IF(A5<2,0,IF(A5=2,Controls!$B$33/2,Controls!$B$33)) -> 10 | E5: =IF(A5<3,0,IF(A5=3,Controls!$B$34/2,Controls!$B$34)) -> 10 | F5: =IF(A5<4,0,Controls!$B$35) -> 10 | G5: =D4 -> 10 | H5: =E4 -> 5 | I5: =F4 -> 0 | J5: =D5+E5 -> 20 | K5: =(G5+D5)/2 -> 10 | L5: =(H5+E5)/2 -> 7.5 | M5: =(I5+F5)/2 -> 5 | N5: =K5+L5 -> 17.5 | O5: =MAX(J5-J4,0) -> 5 | P5: =MAX(F5-F4,0) -> 10 | Q5: =--(K5>0)+--(L5>0) -> 2 | R5: =CEILING(O5/Controls!$B$49,1) -> 3 | S5: =IF(Controls!$B$45=0,0,N5/(1+Controls!$B$47)*1000000/Controls!$B$45) -> 1904.7619 | T5: =S5*Controls!$B$43*(Controls!$B$36/24)*Controls!$B$10 -> 1013333.3 | U5: =K5*Controls!$B$36*DAY(EOMONTH(B5,0))*Controls!$B$10 -> 5654.4 | V5: =MAX(L5*Controls!$B$36-MIN(L5,M5)*Controls!$B$37,0)*DAY(EOMONTH(B5,0))*Controls!$B$10 -> 2901.6 | W5: =MIN(L5,M5)*Controls!$B$37*DAY(EOMONTH(B5,0))*Controls!$B$10 -> 1339.2
A6: 5 | B6: =EDATE(Controls!$B$7,A6-1) -> 46327 | C6: =TEXT(B6,"mmm-yy") -> Nov-26 | D6: =IF(A6<2,0,IF(A6=2,Controls!$B$33/2,Controls!$B$33)) -> 10 | E6: =IF(A6<3,0,IF(A6=3,Controls!$B$34/2,Controls!$B$34)) -> 10 | F6: =IF(A6<4,0,Controls!$B$35) -> 10 | G6: =D5 -> 10 | H6: =E5 -> 10 | I6: =F5 -> 10 | J6: =D6+E6 -> 20 | K6: =(G6+D6)/2 -> 10 | L6: =(H6+E6)/2 -> 10 | M6: =(I6+F6)/2 -> 10 | N6: =K6+L6 -> 20 | O6: =MAX(J6-J5,0) -> 0 | P6: =MAX(F6-F5,0) -> 0 | Q6: =--(K6>0)+--(L6>0) -> 2 | R6: =CEILING(O6/Controls!$B$49,1) -> 0 | S6: =IF(Controls!$B$45=0,0,N6/(1+Controls!$B$47)*1000000/Controls!$B$45) -> 2176.8707 | T6: =S6*Controls!$B$43*(Controls!$B$36/24)*Controls!$B$10 -> 1158095.2 | U6: =K6*Controls!$B$36*DAY(EOMONTH(B6,0))*Controls!$B$10 -> 5472 | V6: =MAX(L6*Controls!$B$36-MIN(L6,M6)*Controls!$B$37,0)*DAY(EOMONTH(B6,0))*Controls!$B$10 -> 2880 | W6: =MIN(L6,M6)*Controls!$B$37*DAY(EOMONTH(B6,0))*Controls!$B$10 -> 2592
A7: 6 | B7: =EDATE(Controls!$B$7,A7-1) -> 46357 | C7: =TEXT(B7,"mmm-yy") -> Dec-26 | D7: =IF(A7<2,0,IF(A7=2,Controls!$B$33/2,Controls!$B$33)) -> 10 | E7: =IF(A7<3,0,IF(A7=3,Controls!$B$34/2,Controls!$B$34)) -> 10 | F7: =IF(A7<4,0,Controls!$B$35) -> 10 | G7: =D6 -> 10 | H7: =E6 -> 10 | I7: =F6 -> 10 | J7: =D7+E7 -> 20 | K7: =(G7+D7)/2 -> 10 | L7: =(H7+E7)/2 -> 10 | M7: =(I7+F7)/2 -> 10 | N7: =K7+L7 -> 20 | O7: =MAX(J7-J6,0) -> 0 | P7: =MAX(F7-F6,0) -> 0 | Q7: =--(K7>0)+--(L7>0) -> 2 | R7: =CEILING(O7/Controls!$B$49,1) -> 0 | S7: =IF(Controls!$B$45=0,0,N7/(1+Controls!$B$47)*1000000/Controls!$B$45) -> 2176.8707 | T7: =S7*Controls!$B$43*(Controls!$B$36/24)*Controls!$B$10 -> 1158095.2 | U7: =K7*Controls!$B$36*DAY(EOMONTH(B7,0))*Controls!$B$10 -> 5654.4 | V7: =MAX(L7*Controls!$B$36-MIN(L7,M7)*Controls!$B$37,0)*DAY(EOMONTH(B7,0))*Controls!$B$10 -> 2976 | W7: =MIN(L7,M7)*Controls!$B$37*DAY(EOMONTH(B7,0))*Controls!$B$10 -> 2678.4
A8: 7 | B8: =EDATE(Controls!$B$7,A8-1) -> 46388 | C8: =TEXT(B8,"mmm-yy") -> Jan-27 | D8: =IF(A8<2,0,IF(A8=2,Controls!$B$33/2,Controls!$B$33)) -> 10 | E8: =IF(A8<3,0,IF(A8=3,Controls!$B$34/2,Controls!$B$34)) -> 10 | F8: =IF(A8<4,0,Controls!$B$35) -> 10 | G8: =D7 -> 10 | H8: =E7 -> 10 | I8: =F7 -> 10 | J8: =D8+E8 -> 20 | K8: =(G8+D8)/2 -> 10 | L8: =(H8+E8)/2 -> 10 | M8: =(I8+F8)/2 -> 10 | N8: =K8+L8 -> 20 | O8: =MAX(J8-J7,0) -> 0 | P8: =MAX(F8-F7,0) -> 0 | Q8: =--(K8>0)+--(L8>0) -> 2 | R8: =CEILING(O8/Controls!$B$49,1) -> 0 | S8: =IF(Controls!$B$45=0,0,N8/(1+Controls!$B$47)*1000000/Controls!$B$45) -> 2176.8707 | T8: =S8*Controls!$B$43*(Controls!$B$36/24)*Controls!$B$10 -> 1158095.2 | U8: =K8*Controls!$B$36*DAY(EOMONTH(B8,0))*Controls!$B$10 -> 5654.4 | V8: =MAX(L8*Controls!$B$36-MIN(L8,M8)*Controls!$B$37,0)*DAY(EOMONTH(B8,0))*Controls!$B$10 -> 2976 | W8: =MIN(L8,M8)*Controls!$B$37*DAY(EOMONTH(B8,0))*Controls!$B$10 -> 2678.4
A9: 8 | B9: =EDATE(Controls!$B$7,A9-1) -> 46419 | C9: =TEXT(B9,"mmm-yy") -> Feb-27 | D9: =IF(A9<2,0,IF(A9=2,Controls!$B$33/2,Controls!$B$33)) -> 10 | E9: =IF(A9<3,0,IF(A9=3,Controls!$B$34/2,Controls!$B$34)) -> 10 | F9: =IF(A9<4,0,Controls!$B$35) -> 10 | G9: =D8 -> 10 | H9: =E8 -> 10 | I9: =F8 -> 10 | J9: =D9+E9 -> 20 | K9: =(G9+D9)/2 -> 10 | L9: =(H9+E9)/2 -> 10 | M9: =(I9+F9)/2 -> 10 | N9: =K9+L9 -> 20 | O9: =MAX(J9-J8,0) -> 0 | P9: =MAX(F9-F8,0) -> 0 | Q9: =--(K9>0)+--(L9>0) -> 2 | R9: =CEILING(O9/Controls!$B$49,1) -> 0 | S9: =IF(Controls!$B$45=0,0,N9/(1+Controls!$B$47)*1000000/Controls!$B$45) -> 2176.8707 | T9: =S9*Controls!$B$43*(Controls!$B$36/24)*Controls!$B$10 -> 1158095.2 | U9: =K9*Controls!$B$36*DAY(EOMONTH(B9,0))*Controls!$B$10 -> 5107.2 | V9: =MAX(L9*Controls!$B$36-MIN(L9,M9)*Controls!$B$37,0)*DAY(EOMONTH(B9,0))*Controls!$B$10 -> 2688 | W9: =MIN(L9,M9)*Controls!$B$37*DAY(EOMONTH(B9,0))*Controls!$B$10 -> 2419.2
A10: 9 | B10: =EDATE(Controls!$B$7,A10-1) -> 46447 | C10: =TEXT(B10,"mmm-yy") -> Mar-27 | D10: =IF(A10<2,0,IF(A10=2,Controls!$B$33/2,Controls!$B$33)) -> 10 | E10: =IF(A10<3,0,IF(A10=3,Controls!$B$34/2,Controls!$B$34)) -> 10 | F10: =IF(A10<4,0,Controls!$B$35) -> 10 | G10: =D9 -> 10 | H10: =E9 -> 10 | I10: =F9 -> 10 | J10: =D10+E10 -> 20 | K10: =(G10+D10)/2 -> 10 | L10: =(H10+E10)/2 -> 10 | M10: =(I10+F10)/2 -> 10 | N10: =K10+L10 -> 20 | O10: =MAX(J10-J9,0) -> 0 | P10: =MAX(F10-F9,0) -> 0 | Q10: =--(K10>0)+--(L10>0) -> 2 | R10: =CEILING(O10/Controls!$B$49,1) -> 0 | S10: =IF(Controls!$B$45=0,0,N10/(1+Controls!$B$47)*1000000/Controls!$B$45) -> 2176.8707 | T10: =S10*Controls!$B$43*(Controls!$B$36/24)*Controls!$B$10 -> 1158095.2 | U10: =K10*Controls!$B$36*DAY(EOMONTH(B10,0))*Controls!$B$10 -> 5654.4 | V10: =MAX(L10*Controls!$B$36-MIN(L10,M10)*Controls!$B$37,0)*DAY(EOMONTH(B10,0))*Controls!$B$10 -> 2976 | W10: =MIN(L10,M10)*Controls!$B$37*DAY(EOMONTH(B10,0))*Controls!$B$10 -> 2678.4
A11: 10 | B11: =EDATE(Controls!$B$7,A11-1) -> 46478 | C11: =TEXT(B11,"mmm-yy") -> Apr-27 | D11: =IF(A11<2,0,IF(A11=2,Controls!$B$33/2,Controls!$B$33)) -> 10 | E11: =IF(A11<3,0,IF(A11=3,Controls!$B$34/2,Controls!$B$34)) -> 10 | F11: =IF(A11<4,0,Controls!$B$35) -> 10 | G11: =D10 -> 10 | H11: =E10 -> 10 | I11: =F10 -> 10 | J11: =D11+E11 -> 20 | K11: =(G11+D11)/2 -> 10 | L11: =(H11+E11)/2 -> 10 | M11: =(I11+F11)/2 -> 10 | N11: =K11+L11 -> 20 | O11: =MAX(J11-J10,0) -> 0 | P11: =MAX(F11-F10,0) -> 0 | Q11: =--(K11>0)+--(L11>0) -> 2 | R11: =CEILING(O11/Controls!$B$49,1) -> 0 | S11: =IF(Controls!$B$45=0,0,N11/(1+Controls!$B$47)*1000000/Controls!$B$45) -> 2176.8707 | T11: =S11*Controls!$B$43*(Controls!$B$36/24)*Controls!$B$10 -> 1158095.2 | U11: =K11*Controls!$B$36*DAY(EOMONTH(B11,0))*Controls!$B$10 -> 5472 | V11: =MAX(L11*Controls!$B$36-MIN(L11,M11)*Controls!$B$37,0)*DAY(EOMONTH(B11,0))*Controls!$B$10 -> 2880 | W11: =MIN(L11,M11)*Controls!$B$37*DAY(EOMONTH(B11,0))*Controls!$B$10 -> 2592
A12: 11 | B12: =EDATE(Controls!$B$7,A12-1) -> 46508 | C12: =TEXT(B12,"mmm-yy") -> May-27 | D12: =IF(A12<2,0,IF(A12=2,Controls!$B$33/2,Controls!$B$33)) -> 10 | E12: =IF(A12<3,0,IF(A12=3,Controls!$B$34/2,Controls!$B$34)) -> 10 | F12: =IF(A12<4,0,Controls!$B$35) -> 10 | G12: =D11 -> 10 | H12: =E11 -> 10 | I12: =F11 -> 10 | J12: =D12+E12 -> 20 | K12: =(G12+D12)/2 -> 10 | L12: =(H12+E12)/2 -> 10 | M12: =(I12+F12)/2 -> 10 | N12: =K12+L12 -> 20 | O12: =MAX(J12-J11,0) -> 0 | P12: =MAX(F12-F11,0) -> 0 | Q12: =--(K12>0)+--(L12>0) -> 2 | R12: =CEILING(O12/Controls!$B$49,1) -> 0 | S12: =IF(Controls!$B$45=0,0,N12/(1+Controls!$B$47)*1000000/Controls!$B$45) -> 2176.8707 | T12: =S12*Controls!$B$43*(Controls!$B$36/24)*Controls!$B$10 -> 1158095.2 | U12: =K12*Controls!$B$36*DAY(EOMONTH(B12,0))*Controls!$B$10 -> 5654.4 | V12: =MAX(L12*Controls!$B$36-MIN(L12,M12)*Controls!$B$37,0)*DAY(EOMONTH(B12,0))*Controls!$B$10 -> 2976 | W12: =MIN(L12,M12)*Controls!$B$37*DAY(EOMONTH(B12,0))*Controls!$B$10 -> 2678.4
A13: 12 | B13: =EDATE(Controls!$B$7,A13-1) -> 46539 | C13: =TEXT(B13,"mmm-yy") -> Jun-27 | D13: =IF(A13<2,0,IF(A13=2,Controls!$B$33/2,Controls!$B$33)) -> 10 | E13: =IF(A13<3,0,IF(A13=3,Controls!$B$34/2,Controls!$B$34)) -> 10 | F13: =IF(A13<4,0,Controls!$B$35) -> 10 | G13: =D12 -> 10 | H13: =E12 -> 10 | I13: =F12 -> 10 | J13: =D13+E13 -> 20 | K13: =(G13+D13)/2 -> 10 | L13: =(H13+E13)/2 -> 10 | M13: =(I13+F13)/2 -> 10 | N13: =K13+L13 -> 20 | O13: =MAX(J13-J12,0) -> 0 | P13: =MAX(F13-F12,0) -> 0 | Q13: =--(K13>0)+--(L13>0) -> 2 | R13: =CEILING(O13/Controls!$B$49,1) -> 0 | S13: =IF(Controls!$B$45=0,0,N13/(1+Controls!$B$47)*1000000/Controls!$B$45) -> 2176.8707 | T13: =S13*Controls!$B$43*(Controls!$B$36/24)*Controls!$B$10 -> 1158095.2 | U13: =K13*Controls!$B$36*DAY(EOMONTH(B13,0))*Controls!$B$10 -> 5472 | V13: =MAX(L13*Controls!$B$36-MIN(L13,M13)*Controls!$B$37,0)*DAY(EOMONTH(B13,0))*Controls!$B$10 -> 2880 | W13: =MIN(L13,M13)*Controls!$B$37*DAY(EOMONTH(B13,0))*Controls!$B$10 -> 2592
A14: 13 | B14: =EDATE(Controls!$B$7,A14-1) -> 46569 | C14: =TEXT(B14,"mmm-yy") -> Jul-27 | D14: =IF(A14<2,0,IF(A14=2,Controls!$B$33/2,Controls!$B$33)) -> 10 | E14: =IF(A14<3,0,IF(A14=3,Controls!$B$34/2,Controls!$B$34)) -> 10 | F14: =IF(A14<4,0,Controls!$B$35) -> 10 | G14: =D13 -> 10 | H14: =E13 -> 10 | I14: =F13 -> 10 | J14: =D14+E14 -> 20 | K14: =(G14+D14)/2 -> 10 | L14: =(H14+E14)/2 -> 10 | M14: =(I14+F14)/2 -> 10 | N14: =K14+L14 -> 20 | O14: =MAX(J14-J13,0) -> 0 | P14: =MAX(F14-F13,0) -> 0 | Q14: =--(K14>0)+--(L14>0) -> 2 | R14: =CEILING(O14/Controls!$B$49,1) -> 0 | S14: =IF(Controls!$B$45=0,0,N14/(1+Controls!$B$47)*1000000/Controls!$B$45) -> 2176.8707 | T14: =S14*Controls!$B$43*(Controls!$B$36/24)*Controls!$B$10 -> 1158095.2 | U14: =K14*Controls!$B$36*DAY(EOMONTH(B14,0))*Controls!$B$10 -> 5654.4 | V14: =MAX(L14*Controls!$B$36-MIN(L14,M14)*Controls!$B$37,0)*DAY(EOMONTH(B14,0))*Controls!$B$10 -> 2976 | W14: =MIN(L14,M14)*Controls!$B$37*DAY(EOMONTH(B14,0))*Controls!$B$10 -> 2678.4
... A37: 36 | B37: =EDATE(Controls!$B$7,A37-1) -> 47270 | C37: =TEXT(B37,"mmm-yy") -> Jun-29 | D37: =IF(A37<2,0,IF(A37=2,Controls!$B$33/2,Controls!$B$33)) -> 10 | E37: =IF(A37<3,0,IF(A37=3,Controls!$B$34/2,Controls!$B$34)) -> 10 | F37: =IF(A37<4,0,Controls!$B$35) -> 10 | G37: =D36 -> 10 | H37: =E36 -> 10 | I37: =F36 -> 10 | J37: =D37+E37 -> 20 | K37: =(G37+D37)/2 -> 10 | L37: =(H37+E37)/2 -> 10 | M37: =(I37+F37)/2 -> 10 | N37: =K37+L37 -> 20 | O37: =MAX(J37-J36,0) -> 0 | P37: =MAX(F37-F36,0) -> 0 | Q37: =--(K37>0)+--(L37>0) -> 2 | R37: =CEILING(O37/Controls!$B$49,1) -> 0 | S37: =IF(Controls!$B$45=0,0,N37/(1+Controls!$B$47)*1000000/Controls!$B$45) -> 2176.8707 | T37: =S37*Controls!$B$43*(Controls!$B$36/24)*Controls!$B$10 -> 1158095.2 | U37: =K37*Controls!$B$36*DAY(EOMONTH(B37,0))*Controls!$B$10 -> 5472 | V37: =MAX(L37*Controls!$B$36-MIN(L37,M37)*Controls!$B$37,0)*DAY(EOMONTH(B37,0))*Controls!$B$10 -> 2880 | W37: =MIN(L37,M37)*Controls!$B$37*DAY(EOMONTH(B37,0))*Controls!$B$10 -> 2592

Sheet Revenue_36M
A1: Month # | B1: Month | C1: BTC Price USD | D1: Network Hash TH/s | E1: Subsidy BTC/block | F1: Fee % | G1: Network BTC | H1: BitMach BTC | I1: BTC Revenue | J1: DR Eligible MW | K1: IDR Standby | L1: DDMP-style Incentive | M1: Event Value | N1: Total DR | O1: AI/DC Pilot | P1: Total Revenue
A2: 1 | B2: =Monthly_Deployment!C2 -> Jul-26 | C2: =Controls!$B$24*(1+Controls!$B$8)^((A2-1)/12) -> 75000 | D2: =Controls!$B$26*(1+Controls!$B$9)^((A2-1)/12) -> 900000000 | E2: =IF(A2<Controls!$B$28,Controls!$B$27,Controls!$B$27/2) -> 3.125 | F2: =Controls!$B$29+Controls!$B$30*(A2-1) -> 0.12 | G2: =DAY(EOMONTH(Monthly_Deployment!B2,0))*144*E2*(1+F2) -> 15624 | H2: =IF(D2=0,0,Monthly_Deployment!T2/D2*G2) -> 0 | I2: =H2*C2*Controls!$B$25/1000 -> 0 | J2: =IF(AND(Controls!$B$11=1,A2>=Controls!$B$12),Monthly_Deployment!N2,0) -> 0 | K2: =J2*Controls!$B$88*Controls!$B$13 -> 0 | L2: =J2*Controls!$B$89/Controls!$B$90*Controls!$B$13 -> 0 | M2: =J2*Controls!$B$91*Controls!$B$92*Controls!$B$13 -> 0 | N2: =K2+L2+M2 -> 0 | O2: =IF(AND(Controls!$B$14=1,A2>=Controls!$B$15),Controls!$B$94*24*DAY(EOMONTH(Monthly_Deployment!B2,0))*Controls!$B$95+Controls!$B$94*Controls!$B$97,0) -> 0 | P2: =I2+N2+O2 -> 0
A3: 2 | B3: =Monthly_Deployment!C3 -> Aug-26 | C3: =Controls!$B$24*(1+Controls!$B$8)^((A3-1)/12) -> 75305.559 | D3: =Controls!$B$26*(1+Controls!$B$9)^((A3-1)/12) -> 9.1377852e+08 | E3: =IF(A3<Controls!$B$28,Controls!$B$27,Controls!$B$27/2) -> 3.125 | F3: =Controls!$B$29+Controls!$B$30*(A3-1) -> 0.1225 | G3: =DAY(EOMONTH(Monthly_Deployment!B3,0))*144*E3*(1+F3) -> 15658.875 | H3: =IF(D3=0,0,Monthly_Deployment!T3/D3*G3) -> 2.480698 | I3: =H3*C3*Controls!$B$25/1000 -> 3175.776 | J3: =IF(AND(Controls!$B$11=1,A3>=Controls!$B$12),Monthly_Deployment!N3,0) -> 0 | K3: =J3*Controls!$B$88*Controls!$B$13 -> 0 | L3: =J3*Controls!$B$89/Controls!$B$90*Controls!$B$13 -> 0 | M3: =J3*Controls!$B$91*Controls!$B$92*Controls!$B$13 -> 0 | N3: =K3+L3+M3 -> 0 | O3: =IF(AND(Controls!$B$14=1,A3>=Controls!$B$15),Controls!$B$94*24*DAY(EOMONTH(Monthly_Deployment!B3,0))*Controls!$B$95+Controls!$B$94*Controls!$B$97,0) -> 0 | P3: =I3+N3+O3 -> 3175.776
A4: 3 | B4: =Monthly_Deployment!C4 -> Sept-26 | C4: =Controls!$B$24*(1+Controls!$B$8)^((A4-1)/12) -> 75612.363 | D4: =Controls!$B$26*(1+Controls!$B$9)^((A4-1)/12) -> 9.2776799e+08 | E4: =IF(A4<Controls!$B$28,Controls!$B$27,Controls!$B$27/2) -> 3.125 | F4: =Controls!$B$29+Controls!$B$30*(A4-1) -> 0.125 | G4: =DAY(EOMONTH(Monthly_Deployment!B4,0))*144*E4*(1+F4) -> 15187.5 | H4: =IF(D4=0,0,Monthly_Deployment!T4/D4*G4) -> 9.4789708 | I4: =H4*C4*Controls!$B$25/1000 -> 12184.366 | J4: =IF(AND(Controls!$B$11=1,A4>=Controls!$B$12),Monthly_Deployment!N4,0) -> 0 | K4: =J4*Controls!$B$88*Controls!$B$13 -> 0 | L4: =J4*Controls!$B$89/Controls!$B$90*Controls!$B$13 -> 0 | M4: =J4*Controls!$B$91*Controls!$B$92*Controls!$B$13 -> 0 | N4: =K4+L4+M4 -> 0 | O4: =IF(AND(Controls!$B$14=1,A4>=Controls!$B$15),Controls!$B$94*24*DAY(EOMONTH(Monthly_Deployment!B4,0))*Controls!$B$95+Controls!$B$94*Controls!$B$97,0) -> 0 | P4: =I4+N4+O4 -> 12184.366
A5: 4 | B5: =Monthly_Deployment!C5 -> Oct-26 | C5: =Controls!$B$24*(1+Controls!$B$8)^((A5-1)/12) -> 75920.418 | D5: =Controls!$B$26*(1+Controls!$B$9)^((A5-1)/12) -> 9.4197163e+08 | E5: =IF(A5<Controls!$B$28,Controls!$B$27,Controls!$B$27/2) -> 3.125 | F5: =Controls!$B$29+Controls!$B$30*(A5-1) -> 0.1275 | G5: =DAY(EOMONTH(Monthly_Deployment!B5,0))*144*E5*(1+F5) -> 15728.625 | H5: =IF(D5=0,0,Monthly_Deployment!T5/D5*G5) -> 16.920191 | I5: =H5*C5*Controls!$B$25/1000 -> 21837.996 | J5: =IF(AND(Controls!$B$11=1,A5>=Controls!$B$12),Monthly_Deployment!N5,0) -> 0 | K5: =J5*Controls!$B$88*Controls!$B$13 -> 0 | L5: =J5*Controls!$B$89/Controls!$B$90*Controls!$B$13 -> 0 | M5: =J5*Controls!$B$91*Controls!$B$92*Controls!$B$13 -> 0 | N5: =K5+L5+M5 -> 0 | O5: =IF(AND(Controls!$B$14=1,A5>=Controls!$B$15),Controls!$B$94*24*DAY(EOMONTH(Monthly_Deployment!B5,0))*Controls!$B$95+Controls!$B$94*Controls!$B$97,0) -> 0 | P5: =I5+N5+O5 -> 21837.996
A6: 5 | B6: =Monthly_Deployment!C6 -> Nov-26 | C6: =Controls!$B$24*(1+Controls!$B$8)^((A6-1)/12) -> 76229.727 | D6: =Controls!$B$26*(1+Controls!$B$9)^((A6-1)/12) -> 9.5639271e+08 | E6: =IF(A6<Controls!$B$28,Controls!$B$27,Controls!$B$27/2) -> 3.125 | F6: =Controls!$B$29+Controls!$B$30*(A6-1) -> 0.13 | G6: =DAY(EOMONTH(Monthly_Deployment!B6,0))*144*E6*(1+F6) -> 15255 | H6: =IF(D6=0,0,Monthly_Deployment!T6/D6*G6) -> 18.472268 | I6: =H6*C6*Controls!$B$25/1000 -> 23938.312 | J6: =IF(AND(Controls!$B$11=1,A6>=Controls!$B$12),Monthly_Deployment!N6,0) -> 0 | K6: =J6*Controls!$B$88*Controls!$B$13 -> 0 | L6: =J6*Controls!$B$89/Controls!$B$90*Controls!$B$13 -> 0 | M6: =J6*Controls!$B$91*Controls!$B$92*Controls!$B$13 -> 0 | N6: =K6+L6+M6 -> 0 | O6: =IF(AND(Controls!$B$14=1,A6>=Controls!$B$15),Controls!$B$94*24*DAY(EOMONTH(Monthly_Deployment!B6,0))*Controls!$B$95+Controls!$B$94*Controls!$B$97,0) -> 0 | P6: =I6+N6+O6 -> 23938.312
A7: 6 | B7: =Monthly_Deployment!C7 -> Dec-26 | C7: =Controls!$B$24*(1+Controls!$B$8)^((A7-1)/12) -> 76540.296 | D7: =Controls!$B$26*(1+Controls!$B$9)^((A7-1)/12) -> 9.7103458e+08 | E7: =IF(A7<Controls!$B$28,Controls!$B$27,Controls!$B$27/2) -> 3.125 | F7: =Controls!$B$29+Controls!$B$30*(A7-1) -> 0.1325 | G7: =DAY(EOMONTH(Monthly_Deployment!B7,0))*144*E7*(1+F7) -> 15798.375 | H7: =IF(D7=0,0,Monthly_Deployment!T7/D7*G7) -> 18.841783 | I7: =H7*C7*Controls!$B$25/1000 -> 24516.646 | J7: =IF(AND(Controls!$B$11=1,A7>=Controls!$B$12),Monthly_Deployment!N7,0) -> 0 | K7: =J7*Controls!$B$88*Controls!$B$13 -> 0 | L7: =J7*Controls!$B$89/Controls!$B$90*Controls!$B$13 -> 0 | M7: =J7*Controls!$B$91*Controls!$B$92*Controls!$B$13 -> 0 | N7: =K7+L7+M7 -> 0 | O7: =IF(AND(Controls!$B$14=1,A7>=Controls!$B$15),Controls!$B$94*24*DAY(EOMONTH(Monthly_Deployment!B7,0))*Controls!$B$95+Controls!$B$94*Controls!$B$97,0) -> 0 | P7: =I7+N7+O7 -> 24516.646
A8: 7 | B8: =Monthly_Deployment!C8 -> Jan-27 | C8: =Controls!$B$24*(1+Controls!$B$8)^((A8-1)/12) -> 76852.131 | D8: =Controls!$B$26*(1+Controls!$B$9)^((A8-1)/12) -> 9.859006e+08 | E8: =IF(A8<Controls!$B$28,Controls!$B$27,Controls!$B$27/2) -> 3.125 | F8: =Controls!$B$29+Controls!$B$30*(A8-1) -> 0.135 | G8: =DAY(EOMONTH(Monthly_Deployment!B8,0))*144*E8*(1+F8) -> 15833.25 | H8: =IF(D8=0,0,Monthly_Deployment!T8/D8*G8) -> 18.598641 | I8: =H8*C8*Controls!$B$25/1000 -> 24298.868 | J8: =IF(AND(Controls!$B$11=1,A8>=Controls!$B$12),Monthly_Deployment!N8,0) -> 0 | K8: =J8*Controls!$B$88*Controls!$B$13 -> 0 | L8: =J8*Controls!$B$89/Controls!$B$90*Controls!$B$13 -> 0 | M8: =J8*Controls!$B$91*Controls!$B$92*Controls!$B$13 -> 0 | N8: =K8+L8+M8 -> 0 | O8: =IF(AND(Controls!$B$14=1,A8>=Controls!$B$15),Controls!$B$94*24*DAY(EOMONTH(Monthly_Deployment!B8,0))*Controls!$B$95+Controls!$B$94*Controls!$B$97,0) -> 0 | P8: =I8+N8+O8 -> 24298.868
A9: 8 | B9: =Monthly_Deployment!C9 -> Feb-27 | C9: =Controls!$B$24*(1+Controls!$B$8)^((A9-1)/12) -> 77165.236 | D9: =Controls!$B$26*(1+Controls!$B$9)^((A9-1)/12) -> 1.0009942e+09 | E9: =IF(A9<Controls!$B$28,Controls!$B$27,Controls!$B$27/2) -> 3.125 | F9: =Controls!$B$29+Controls!$B$30*(A9-1) -> 0.1375 | G9: =DAY(EOMONTH(Monthly_Deployment!B9,0))*144*E9*(1+F9) -> 14332.5 | H9: =IF(D9=0,0,Monthly_Deployment!T9/D9*G9) -> 16.581914 | I9: =H9*C9*Controls!$B$25/1000 -> 21752.304 | J9: =IF(AND(Controls!$B$11=1,A9>=Controls!$B$12),Monthly_Deployment!N9,0) -> 0 | K9: =J9*Controls!$B$88*Controls!$B$13 -> 0 | L9: =J9*Controls!$B$89/Controls!$B$90*Controls!$B$13 -> 0 | M9: =J9*Controls!$B$91*Controls!$B$92*Controls!$B$13 -> 0 | N9: =K9+L9+M9 -> 0 | O9: =IF(AND(Controls!$B$14=1,A9>=Controls!$B$15),Controls!$B$94*24*DAY(EOMONTH(Monthly_Deployment!B9,0))*Controls!$B$95+Controls!$B$94*Controls!$B$97,0) -> 0 | P9: =I9+N9+O9 -> 21752.304
A10: 9 | B10: =Monthly_Deployment!C10 -> Mar-27 | C10: =Controls!$B$24*(1+Controls!$B$8)^((A10-1)/12) -> 77479.617 | D10: =Controls!$B$26*(1+Controls!$B$9)^((A10-1)/12) -> 1.0163189e+09 | E10: =IF(A10<Controls!$B$28,Controls!$B$27,Controls!$B$27/2) -> 3.125 | F10: =Controls!$B$29+Controls!$B$30*(A10-1) -> 0.14 | G10: =DAY(EOMONTH(Monthly_Deployment!B10,0))*144*E10*(1+F10) -> 15903 | H10: =IF(D10=0,0,Monthly_Deployment!T10/D10*G10) -> 18.121466 | I10: =H10*C10*Controls!$B$25/1000 -> 23868.752 | J10: =IF(AND(Controls!$B$11=1,A10>=Controls!$B$12),Monthly_Deployment!N10,0) -> 0 | K10: =J10*Controls!$B$88*Controls!$B$13 -> 0 | L10: =J10*Controls!$B$89/Controls!$B$90*Controls!$B$13 -> 0 | M10: =J10*Controls!$B$91*Controls!$B$92*Controls!$B$13 -> 0 | N10: =K10+L10+M10 -> 0 | O10: =IF(AND(Controls!$B$14=1,A10>=Controls!$B$15),Controls!$B$94*24*DAY(EOMONTH(Monthly_Deployment!B10,0))*Controls!$B$95+Controls!$B$94*Controls!$B$97,0) -> 0 | P10: =I10+N10+O10 -> 23868.752
A11: 10 | B11: =Monthly_Deployment!C11 -> Apr-27 | C11: =Controls!$B$24*(1+Controls!$B$8)^((A11-1)/12) -> 77795.278 | D11: =Controls!$B$26*(1+Controls!$B$9)^((A11-1)/12) -> 1.0318782e+09 | E11: =IF(A11<Controls!$B$28,Controls!$B$27,Controls!$B$27/2) -> 3.125 | F11: =Controls!$B$29+Controls!$B$30*(A11-1) -> 0.1425 | G11: =DAY(EOMONTH(Monthly_Deployment!B11,0))*144*E11*(1+F11) -> 15423.75 | H11: =IF(D11=0,0,Monthly_Deployment!T11/D11*G11) -> 17.310348 | I11: =H11*C11*Controls!$B$25/1000 -> 22893.277 | J11: =IF(AND(Controls!$B$11=1,A11>=Controls!$B$12),Monthly_Deployment!N11,0) -> 0 | K11: =J11*Controls!$B$88*Controls!$B$13 -> 0 | L11: =J11*Controls!$B$89/Controls!$B$90*Controls!$B$13 -> 0 | M11: =J11*Controls!$B$91*Controls!$B$92*Controls!$B$13 -> 0 | N11: =K11+L11+M11 -> 0 | O11: =IF(AND(Controls!$B$14=1,A11>=Controls!$B$15),Controls!$B$94*24*DAY(EOMONTH(Monthly_Deployment!B11,0))*Controls!$B$95+Controls!$B$94*Controls!$B$97,0) -> 0 | P11: =I11+N11+O11 -> 22893.277
A12: 11 | B12: =Monthly_Deployment!C12 -> May-27 | C12: =Controls!$B$24*(1+Controls!$B$8)^((A12-1)/12) -> 78112.226 | D12: =Controls!$B$26*(1+Controls!$B$9)^((A12-1)/12) -> 1.0476757e+09 | E12: =IF(A12<Controls!$B$28,Controls!$B$27,Controls!$B$27/2) -> 3.125 | F12: =Controls!$B$29+Controls!$B$30*(A12-1) -> 0.145 | G12: =DAY(EOMONTH(Monthly_Deployment!B12,0))*144*E12*(1+F12) -> 15972.75 | H12: =IF(D12=0,0,Monthly_Deployment!T12/D12*G12) -> 17.656194 | I12: =H12*C12*Controls!$B$25/1000 -> 23445.798 | J12: =IF(AND(Controls!$B$11=1,A12>=Controls!$B$12),Monthly_Deployment!N12,0) -> 0 | K12: =J12*Controls!$B$88*Controls!$B$13 -> 0 | L12: =J12*Controls!$B$89/Controls!$B$90*Controls!$B$13 -> 0 | M12: =J12*Controls!$B$91*Controls!$B$92*Controls!$B$13 -> 0 | N12: =K12+L12+M12 -> 0 | O12: =IF(AND(Controls!$B$14=1,A12>=Controls!$B$15),Controls!$B$94*24*DAY(EOMONTH(Monthly_Deployment!B12,0))*Controls!$B$95+Controls!$B$94*Controls!$B$97,0) -> 0 | P12: =I12+N12+O12 -> 23445.798
A13: 12 | B13: =Monthly_Deployment!C13 -> Jun-27 | C13: =Controls!$B$24*(1+Controls!$B$8)^((A13-1)/12) -> 78430.465 | D13: =Controls!$B$26*(1+Controls!$B$9)^((A13-1)/12) -> 1.0637151e+09 | E13: =IF(A13<Controls!$B$28,Controls!$B$27,Controls!$B$27/2) -> 3.125 | F13: =Controls!$B$29+Controls!$B$30*(A13-1) -> 0.1475 | G13: =DAY(EOMONTH(Monthly_Deployment!B13,0))*144*E13*(1+F13) -> 15491.25 | H13: =IF(D13=0,0,Monthly_Deployment!T13/D13*G13) -> 16.865741 | I13: =H13*C13*Controls!$B$25/1000 -> 22487.394 | J13: =IF(AND(Controls!$B$11=1,A13>=Controls!$B$12),Monthly_Deployment!N13,0) -> 0 | K13: =J13*Controls!$B$88*Controls!$B$13 -> 0 | L13: =J13*Controls!$B$89/Controls!$B$90*Controls!$B$13 -> 0 | M13: =J13*Controls!$B$91*Controls!$B$92*Controls!$B$13 -> 0 | N13: =K13+L13+M13 -> 0 | O13: =IF(AND(Controls!$B$14=1,A13>=Controls!$B$15),Controls!$B$94*24*DAY(EOMONTH(Monthly_Deployment!B13,0))*Controls!$B$95+Controls!$B$94*Controls!$B$97,0) -> 0 | P13: =I13+N13+O13 -> 22487.394
... A37: 36 | B37: =Monthly_Deployment!C37 -> Jun-29 | C37: =Controls!$B$24*(1+Controls!$B$8)^((A37-1)/12) -> 86469.587 | D37: =Controls!$B$26*(1+Controls!$B$9)^((A37-1)/12) -> 1.5317497e+09 | E37: =IF(A37<Controls!$B$28,Controls!$B$27,Controls!$B$27/2) -> 1.5625 | F37: =Controls!$B$29+Controls!$B$30*(A37-1) -> 0.2075 | G37: =DAY(EOMONTH(Monthly_Deployment!B37,0))*144*E37*(1+F37) -> 8150.625 | H37: =IF(D37=0,0,Monthly_Deployment!T37/D37*G37) -> 6.1623644 | I37: =H37*C37*Controls!$B$25/1000 -> 9058.5708 | J37: =IF(AND(Controls!$B$11=1,A37>=Controls!$B$12),Monthly_Deployment!N37,0) -> 0 | K37: =J37*Controls!$B$88*Controls!$B$13 -> 0 | L37: =J37*Controls!$B$89/Controls!$B$90*Controls!$B$13 -> 0 | M37: =J37*Controls!$B$91*Controls!$B$92*Controls!$B$13 -> 0 | N37: =K37+L37+M37 -> 0 | O37: =IF(AND(Controls!$B$14=1,A37>=Controls!$B$15),Controls!$B$94*24*DAY(EOMONTH(Monthly_Deployment!B37,0))*Controls!$B$95+Controls!$B$94*Controls!$B$97,0) -> 0 | P37: =I37+N37+O37 -> 9058.5708

Sheet Opex_36M
A1: Month # | B1: Month | C1: Tariff R/kWh | D1: GVL Grid Cost | E1: AMSA Grid Cost | F1: Solar O&M | G1: Total Energy Cost | H1: Corporate Payroll | I1: Site Payroll | J1: Benefits | K1: Travel | L1: Software/Storage | M1: Legal | N1: Office | O1: Tools/Security/Utilities | P1: Total Cash Opex
A2: 1 | B2: =Monthly_Deployment!C2 -> Jul-26 | C2: =IF(A2<=Controls!$B$40,Controls!$B$38,Controls!$B$39) -> 1.2 | D2: =Monthly_Deployment!U2*C2 -> 0 | E2: =Monthly_Deployment!V2*C2 -> 0 | F2: =Monthly_Deployment!M2*Controls!$B$54*Controls!$B$41/12 -> 0 | G2: =D2+E2+F2 -> 0 | H2: =Controls!$B$68*Controls!$B$69/12 -> 333.33333 | I2: =Monthly_Deployment!Q2*Controls!$B$70*Controls!$B$71/12+Monthly_Deployment!N2*Controls!$B$72*Controls!$B$73/12+Monthly_Deployment!N2*Controls!$B$74*Controls!$B$75/12 -> 0 | J2: =(H2+I2)*Controls!$B$76 -> 66.666667 | K2: =(H2+I2)*Controls!$B$77+Monthly_Deployment!Q2*Controls!$B$78 -> 20 | L2: =(Controls!$B$79*(Controls!$B$68+Monthly_Deployment!Q2*Controls!$B$70+Monthly_Deployment!N2*Controls!$B$72+Monthly_Deployment!N2*Controls!$B$74))+Monthly_Deployment!Q2*Controls!$B$80+Controls!$B$83 -> 18 | M2: =Controls!$B$81 -> 75 | N2: =Controls!$B$82 -> 10 | O2: =Monthly_Deployment!N2*(Controls!$B$84+Controls!$B$86)+Monthly_Deployment!Q2*Controls!$B$85 -> 0 | P2: =G2+H2+I2+J2+K2+L2+M2+N2+O2 -> 523
A3: 2 | B3: =Monthly_Deployment!C3 -> Aug-26 | C3: =IF(A3<=Controls!$B$40,Controls!$B$38,Controls!$B$39) -> 1.2 | D3: =Monthly_Deployment!U3*C3 -> 1696.32 | E3: =Monthly_Deployment!V3*C3 -> 0 | F3: =Monthly_Deployment!M3*Controls!$B$54*Controls!$B$41/12 -> 0 | G3: =D3+E3+F3 -> 1696.32 | H3: =Controls!$B$68*Controls!$B$69/12 -> 333.33333 | I3: =Monthly_Deployment!Q3*Controls!$B$70*Controls!$B$71/12+Monthly_Deployment!N3*Controls!$B$72*Controls!$B$73/12+Monthly_Deployment!N3*Controls!$B$74*Controls!$B$75/12 -> 149.6875 | J3: =(H3+I3)*Controls!$B$76 -> 96.604167 | K3: =(H3+I3)*Controls!$B$77+Monthly_Deployment!Q3*Controls!$B$78 -> 278.98125 | L3: =(Controls!$B$79*(Controls!$B$68+Monthly_Deployment!Q3*Controls!$B$70+Monthly_Deployment!N3*Controls!$B$72+Monthly_Deployment!N3*Controls!$B$74))+Monthly_Deployment!Q3*Controls!$B$80+Controls!$B$83 -> 68.7625 | M3: =Controls!$B$81 -> 75 | N3: =Controls!$B$82 -> 10 | O3: =Monthly_Deployment!N3*(Controls!$B$84+Controls!$B$86)+Monthly_Deployment!Q3*Controls!$B$85 -> 85 | P3: =G3+H3+I3+J3+K3+L3+M3+N3+O3 -> 2793.6887
A4: 3 | B4: =Monthly_Deployment!C4 -> Sept-26 | C4: =IF(A4<=Controls!$B$40,Controls!$B$38,Controls!$B$39) -> 1.2 | D4: =Monthly_Deployment!U4*C4 -> 4924.8 | E4: =Monthly_Deployment!V4*C4 -> 1641.6 | F4: =Monthly_Deployment!M4*Controls!$B$54*Controls!$B$41/12 -> 0 | G4: =D4+E4+F4 -> 6566.4 | H4: =Controls!$B$68*Controls!$B$69/12 -> 333.33333 | I4: =Monthly_Deployment!Q4*Controls!$B$70*Controls!$B$71/12+Monthly_Deployment!N4*Controls!$B$72*Controls!$B$73/12+Monthly_Deployment!N4*Controls!$B$74*Controls!$B$75/12 -> 365.41667 | J4: =(H4+I4)*Controls!$B$76 -> 139.75 | K4: =(H4+I4)*Controls!$B$77+Monthly_Deployment!Q4*Controls!$B$78 -> 541.925 | L4: =(Controls!$B$79*(Controls!$B$68+Monthly_Deployment!Q4*Controls!$B$70+Monthly_Deployment!N4*Controls!$B$72+Monthly_Deployment!N4*Controls!$B$74))+Monthly_Deployment!Q4*Controls!$B$80+Controls!$B$83 -> 127.05 | M4: =Controls!$B$81 -> 75 | N4: =Controls!$B$82 -> 10 | O4: =Monthly_Deployment!N4*(Controls!$B$84+Controls!$B$86)+Monthly_Deployment!Q4*Controls!$B$85 -> 260 | P4: =G4+H4+I4+J4+K4+L4+M4+N4+O4 -> 8418.875
A5: 4 | B5: =Monthly_Deployment!C5 -> Oct-26 | C5: =IF(A5<=Controls!$B$40,Controls!$B$38,Controls!$B$39) -> 1.2 | D5: =Monthly_Deployment!U5*C5 -> 6785.28 | E5: =Monthly_Deployment!V5*C5 -> 3481.92 | F5: =Monthly_Deployment!M5*Controls!$B$54*Controls!$B$41/12 -> 58.333333 | G5: =D5+E5+F5 -> 10325.533 | H5: =Controls!$B$68*Controls!$B$69/12 -> 333.33333 | I5: =Monthly_Deployment!Q5*Controls!$B$70*Controls!$B$71/12+Monthly_Deployment!N5*Controls!$B$72*Controls!$B$73/12+Monthly_Deployment!N5*Controls!$B$74*Controls!$B$75/12 -> 464.47917 | J5: =(H5+I5)*Controls!$B$76 -> 159.5625 | K5: =(H5+I5)*Controls!$B$77+Monthly_Deployment!Q5*Controls!$B$78 -> 547.86875 | L5: =(Controls!$B$79*(Controls!$B$68+Monthly_Deployment!Q5*Controls!$B$70+Monthly_Deployment!N5*Controls!$B$72+Monthly_Deployment!N5*Controls!$B$74))+Monthly_Deployment!Q5*Controls!$B$80+Controls!$B$83 -> 138.3375 | M5: =Controls!$B$81 -> 75 | N5: =Controls!$B$82 -> 10 | O5: =Monthly_Deployment!N5*(Controls!$B$84+Controls!$B$86)+Monthly_Deployment!Q5*Controls!$B$85 -> 395 | P5: =G5+H5+I5+J5+K5+L5+M5+N5+O5 -> 12449.115
A6: 5 | B6: =Monthly_Deployment!C6 -> Nov-26 | C6: =IF(A6<=Controls!$B$40,Controls!$B$38,Controls!$B$39) -> 1.2 | D6: =Monthly_Deployment!U6*C6 -> 6566.4 | E6: =Monthly_Deployment!V6*C6 -> 3456 | F6: =Monthly_Deployment!M6*Controls!$B$54*Controls!$B$41/12 -> 116.66667 | G6: =D6+E6+F6 -> 10139.067 | H6: =Controls!$B$68*Controls!$B$69/12 -> 333.33333 | I6: =Monthly_Deployment!Q6*Controls!$B$70*Controls!$B$71/12+Monthly_Deployment!N6*Controls!$B$72*Controls!$B$73/12+Monthly_Deployment!N6*Controls!$B$74*Controls!$B$75/12 -> 497.5 | J6: =(H6+I6)*Controls!$B$76 -> 166.16667 | K6: =(H6+I6)*Controls!$B$77+Monthly_Deployment!Q6*Controls!$B$78 -> 549.85 | L6: =(Controls!$B$79*(Controls!$B$68+Monthly_Deployment!Q6*Controls!$B$70+Monthly_Deployment!N6*Controls!$B$72+Monthly_Deployment!N6*Controls!$B$74))+Monthly_Deployment!Q6*Controls!$B$80+Controls!$B$83 -> 142.1 | M6: =Controls!$B$81 -> 75 | N6: =Controls!$B$82 -> 10 | O6: =Monthly_Deployment!N6*(Controls!$B$84+Controls!$B$86)+Monthly_Deployment!Q6*Controls!$B$85 -> 440 | P6: =G6+H6+I6+J6+K6+L6+M6+N6+O6 -> 12353.017
A7: 6 | B7: =Monthly_Deployment!C7 -> Dec-26 | C7: =IF(A7<=Controls!$B$40,Controls!$B$38,Controls!$B$39) -> 1.2 | D7: =Monthly_Deployment!U7*C7 -> 6785.28 | E7: =Monthly_Deployment!V7*C7 -> 3571.2 | F7: =Monthly_Deployment!M7*Controls!$B$54*Controls!$B$41/12 -> 116.66667 | G7: =D7+E7+F7 -> 10473.147 | H7: =Controls!$B$68*Controls!$B$69/12 -> 333.33333 | I7: =Monthly_Deployment!Q7*Controls!$B$70*Controls!$B$71/12+Monthly_Deployment!N7*Controls!$B$72*Controls!$B$73/12+Monthly_Deployment!N7*Controls!$B$74*Controls!$B$75/12 -> 497.5 | J7: =(H7+I7)*Controls!$B$76 -> 166.16667 | K7: =(H7+I7)*Controls!$B$77+Monthly_Deployment!Q7*Controls!$B$78 -> 549.85 | L7: =(Controls!$B$79*(Controls!$B$68+Monthly_Deployment!Q7*Controls!$B$70+Monthly_Deployment!N7*Controls!$B$72+Monthly_Deployment!N7*Controls!$B$74))+Monthly_Deployment!Q7*Controls!$B$80+Controls!$B$83 -> 142.1 | M7: =Controls!$B$81 -> 75 | N7: =Controls!$B$82 -> 10 | O7: =Monthly_Deployment!N7*(Controls!$B$84+Controls!$B$86)+Monthly_Deployment!Q7*Controls!$B$85 -> 440 | P7: =G7+H7+I7+J7+K7+L7+M7+N7+O7 -> 12687.097
A8: 7 | B8: =Monthly_Deployment!C8 -> Jan-27 | C8: =IF(A8<=Controls!$B$40,Controls!$B$38,Controls!$B$39) -> 1.2 | D8: =Monthly_Deployment!U8*C8 -> 6785.28 | E8: =Monthly_Deployment!V8*C8 -> 3571.2 | F8: =Monthly_Deployment!M8*Controls!$B$54*Controls!$B$41/12 -> 116.66667 | G8: =D8+E8+F8 -> 10473.147 | H8: =Controls!$B$68*Controls!$B$69/12 -> 333.33333 | I8: =Monthly_Deployment!Q8*Controls!$B$70*Controls!$B$71/12+Monthly_Deployment!N8*Controls!$B$72*Controls!$B$73/12+Monthly_Deployment!N8*Controls!$B$74*Controls!$B$75/12 -> 497.5 | J8: =(H8+I8)*Controls!$B$76 -> 166.16667 | K8: =(H8+I8)*Controls!$B$77+Monthly_Deployment!Q8*Controls!$B$78 -> 549.85 | L8: =(Controls!$B$79*(Controls!$B$68+Monthly_Deployment!Q8*Controls!$B$70+Monthly_Deployment!N8*Controls!$B$72+Monthly_Deployment!N8*Controls!$B$74))+Monthly_Deployment!Q8*Controls!$B$80+Controls!$B$83 -> 142.1 | M8: =Controls!$B$81 -> 75 | N8: =Controls!$B$82 -> 10 | O8: =Monthly_Deployment!N8*(Controls!$B$84+Controls!$B$86)+Monthly_Deployment!Q8*Controls!$B$85 -> 440 | P8: =G8+H8+I8+J8+K8+L8+M8+N8+O8 -> 12687.097
A9: 8 | B9: =Monthly_Deployment!C9 -> Feb-27 | C9: =IF(A9<=Controls!$B$40,Controls!$B$38,Controls!$B$39) -> 1.2 | D9: =Monthly_Deployment!U9*C9 -> 6128.64 | E9: =Monthly_Deployment!V9*C9 -> 3225.6 | F9: =Monthly_Deployment!M9*Controls!$B$54*Controls!$B$41/12 -> 116.66667 | G9: =D9+E9+F9 -> 9470.9067 | H9: =Controls!$B$68*Controls!$B$69/12 -> 333.33333 | I9: =Monthly_Deployment!Q9*Controls!$B$70*Controls!$B$71/12+Monthly_Deployment!N9*Controls!$B$72*Controls!$B$73/12+Monthly_Deployment!N9*Controls!$B$74*Controls!$B$75/12 -> 497.5 | J9: =(H9+I9)*Controls!$B$76 -> 166.16667 | K9: =(H9+I9)*Controls!$B$77+Monthly_Deployment!Q9*Controls!$B$78 -> 549.85 | L9: =(Controls!$B$79*(Controls!$B$68+Monthly_Deployment!Q9*Controls!$B$70+Monthly_Deployment!N9*Controls!$B$72+Monthly_Deployment!N9*Controls!$B$74))+Monthly_Deployment!Q9*Controls!$B$80+Controls!$B$83 -> 142.1 | M9: =Controls!$B$81 -> 75 | N9: =Controls!$B$82 -> 10 | O9: =Monthly_Deployment!N9*(Controls!$B$84+Controls!$B$86)+Monthly_Deployment!Q9*Controls!$B$85 -> 440 | P9: =G9+H9+I9+J9+K9+L9+M9+N9+O9 -> 11684.857
A10: 9 | B10: =Monthly_Deployment!C10 -> Mar-27 | C10: =IF(A10<=Controls!$B$40,Controls!$B$38,Controls!$B$39) -> 1.2 | D10: =Monthly_Deployment!U10*C10 -> 6785.28 | E10: =Monthly_Deployment!V10*C10 -> 3571.2 | F10: =Monthly_Deployment!M10*Controls!$B$54*Controls!$B$41/12 -> 116.66667 | G10: =D10+E10+F10 -> 10473.147 | H10: =Controls!$B$68*Controls!$B$69/12 -> 333.33333 | I10: =Monthly_Deployment!Q10*Controls!$B$70*Controls!$B$71/12+Monthly_Deployment!N10*Controls!$B$72*Controls!$B$73/12+Monthly_Deployment!N10*Controls!$B$74*Controls!$B$75/12 -> 497.5 | J10: =(H10+I10)*Controls!$B$76 -> 166.16667 | K10: =(H10+I10)*Controls!$B$77+Monthly_Deployment!Q10*Controls!$B$78 -> 549.85 | L10: =(Controls!$B$79*(Controls!$B$68+Monthly_Deployment!Q10*Controls!$B$70+Monthly_Deployment!N10*Controls!$B$72+Monthly_Deployment!N10*Controls!$B$74))+Monthly_Deployment!Q10*Controls!$B$80+Controls!$B$83 -> 142.1 | M10: =Controls!$B$81 -> 75 | N10: =Controls!$B$82 -> 10 | O10: =Monthly_Deployment!N10*(Controls!$B$84+Controls!$B$86)+Monthly_Deployment!Q10*Controls!$B$85 -> 440 | P10: =G10+H10+I10+J10+K10+L10+M10+N10+O10 -> 12687.097
A11: 10 | B11: =Monthly_Deployment!C11 -> Apr-27 | C11: =IF(A11<=Controls!$B$40,Controls!$B$38,Controls!$B$39) -> 1.2 | D11: =Monthly_Deployment!U11*C11 -> 6566.4 | E11: =Monthly_Deployment!V11*C11 -> 3456 | F11: =Monthly_Deployment!M11*Controls!$B$54*Controls!$B$41/12 -> 116.66667 | G11: =D11+E11+F11 -> 10139.067 | H11: =Controls!$B$68*Controls!$B$69/12 -> 333.33333 | I11: =Monthly_Deployment!Q11*Controls!$B$70*Controls!$B$71/12+Monthly_Deployment!N11*Controls!$B$72*Controls!$B$73/12+Monthly_Deployment!N11*Controls!$B$74*Controls!$B$75/12 -> 497.5 | J11: =(H11+I11)*Controls!$B$76 -> 166.16667 | K11: =(H11+I11)*Controls!$B$77+Monthly_Deployment!Q11*Controls!$B$78 -> 549.85 | L11: =(Controls!$B$79*(Controls!$B$68+Monthly_Deployment!Q11*Controls!$B$70+Monthly_Deployment!N11*Controls!$B$72+Monthly_Deployment!N11*Controls!$B$74))+Monthly_Deployment!Q11*Controls!$B$80+Controls!$B$83 -> 142.1 | M11: =Controls!$B$81 -> 75 | N11: =Controls!$B$82 -> 10 | O11: =Monthly_Deployment!N11*(Controls!$B$84+Controls!$B$86)+Monthly_Deployment!Q11*Controls!$B$85 -> 440 | P11: =G11+H11+I11+J11+K11+L11+M11+N11+O11 -> 12353.017
A12: 11 | B12: =Monthly_Deployment!C12 -> May-27 | C12: =IF(A12<=Controls!$B$40,Controls!$B$38,Controls!$B$39) -> 1.2 | D12: =Monthly_Deployment!U12*C12 -> 6785.28 | E12: =Monthly_Deployment!V12*C12 -> 3571.2 | F12: =Monthly_Deployment!M12*Controls!$B$54*Controls!$B$41/12 -> 116.66667 | G12: =D12+E12+F12 -> 10473.147 | H12: =Controls!$B$68*Controls!$B$69/12 -> 333.33333 | I12: =Monthly_Deployment!Q12*Controls!$B$70*Controls!$B$71/12+Monthly_Deployment!N12*Controls!$B$72*Controls!$B$73/12+Monthly_Deployment!N12*Controls!$B$74*Controls!$B$75/12 -> 497.5 | J12: =(H12+I12)*Controls!$B$76 -> 166.16667 | K12: =(H12+I12)*Controls!$B$77+Monthly_Deployment!Q12*Controls!$B$78 -> 549.85 | L12: =(Controls!$B$79*(Controls!$B$68+Monthly_Deployment!Q12*Controls!$B$70+Monthly_Deployment!N12*Controls!$B$72+Monthly_Deployment!N12*Controls!$B$74))+Monthly_Deployment!Q12*Controls!$B$80+Controls!$B$83 -> 142.1 | M12: =Controls!$B$81 -> 75 | N12: =Controls!$B$82 -> 10 | O12: =Monthly_Deployment!N12*(Controls!$B$84+Controls!$B$86)+Monthly_Deployment!Q12*Controls!$B$85 -> 440 | P12: =G12+H12+I12+J12+K12+L12+M12+N12+O12 -> 12687.097
A13: 12 | B13: =Monthly_Deployment!C13 -> Jun-27 | C13: =IF(A13<=Controls!$B$40,Controls!$B$38,Controls!$B$39) -> 1.2 | D13: =Monthly_Deployment!U13*C13 -> 6566.4 | E13: =Monthly_Deployment!V13*C13 -> 3456 | F13: =Monthly_Deployment!M13*Controls!$B$54*Controls!$B$41/12 -> 116.66667 | G13: =D13+E13+F13 -> 10139.067 | H13: =Controls!$B$68*Controls!$B$69/12 -> 333.33333 | I13: =Monthly_Deployment!Q13*Controls!$B$70*Controls!$B$71/12+Monthly_Deployment!N13*Controls!$B$72*Controls!$B$73/12+Monthly_Deployment!N13*Controls!$B$74*Controls!$B$75/12 -> 497.5 | J13: =(H13+I13)*Controls!$B$76 -> 166.16667 | K13: =(H13+I13)*Controls!$B$77+Monthly_Deployment!Q13*Controls!$B$78 -> 549.85 | L13: =(Controls!$B$79*(Controls!$B$68+Monthly_Deployment!Q13*Controls!$B$70+Monthly_Deployment!N13*Controls!$B$72+Monthly_Deployment!N13*Controls!$B$74))+Monthly_Deployment!Q13*Controls!$B$80+Controls!$B$83 -> 142.1 | M13: =Controls!$B$81 -> 75 | N13: =Controls!$B$82 -> 10 | O13: =Monthly_Deployment!N13*(Controls!$B$84+Controls!$B$86)+Monthly_Deployment!Q13*Controls!$B$85 -> 440 | P13: =G13+H13+I13+J13+K13+L13+M13+N13+O13 -> 12353.017
... A37: 36 | B37: =Monthly_Deployment!C37 -> Jun-29 | C37: =IF(A37<=Controls!$B$40,Controls!$B$38,Controls!$B$39) -> 0.6 | D37: =Monthly_Deployment!U37*C37 -> 3283.2 | E37: =Monthly_Deployment!V37*C37 -> 1728 | F37: =Monthly_Deployment!M37*Controls!$B$54*Controls!$B$41/12 -> 116.66667 | G37: =D37+E37+F37 -> 5127.8667 | H37: =Controls!$B$68*Controls!$B$69/12 -> 333.33333 | I37: =Monthly_Deployment!Q37*Controls!$B$70*Controls!$B$71/12+Monthly_Deployment!N37*Controls!$B$72*Controls!$B$73/12+Monthly_Deployment!N37*Controls!$B$74*Controls!$B$75/12 -> 497.5 | J37: =(H37+I37)*Controls!$B$76 -> 166.16667 | K37: =(H37+I37)*Controls!$B$77+Monthly_Deployment!Q37*Controls!$B$78 -> 549.85 | L37: =(Controls!$B$79*(Controls!$B$68+Monthly_Deployment!Q37*Controls!$B$70+Monthly_Deployment!N37*Controls!$B$72+Monthly_Deployment!N37*Controls!$B$74))+Monthly_Deployment!Q37*Controls!$B$80+Controls!$B$83 -> 142.1 | M37: =Controls!$B$81 -> 75 | N37: =Controls!$B$82 -> 10 | O37: =Monthly_Deployment!N37*(Controls!$B$84+Controls!$B$86)+Monthly_Deployment!Q37*Controls!$B$85 -> 440 | P37: =G37+H37+I37+J37+K37+L37+M37+N37+O37 -> 7341.8167

Sheet Capex_36M
A1: Month # | B1: Month | C1: New Mining MW | D1: New Solar MW | E1: New Containers | F1: Site Starts | G1: ASIC Hardware | H1: Containers | I1: Electrical EPC | J1: Solar PV | K1: Spares | L1: Tools/Staff/Setup | M1: Logistics/Duties | N1: Total Capex Basis | O1: Capex Cash Spend
A2: 1 | B2: =Monthly_Deployment!C2 -> Jul-26 | C2: =Monthly_Deployment!O2 -> 0 | D2: =Monthly_Deployment!P2 -> 0 | E2: =Monthly_Deployment!R2 -> 0 | F2: =IF(AND(Monthly_Deployment!G2=0,Monthly_Deployment!D2>0),1,0)+IF(AND(Monthly_Deployment!H2=0,Monthly_Deployment!E2>0),1,0) -> 0 | G2: =IF(Controls!$B$45=0,0,C2/(1+Controls!$B$47)*1000000/Controls!$B$45*Controls!$B$46*Controls!$B$25/1000) -> 0 | H2: =E2*Controls!$B$50*Controls!$B$25/1000 -> 0 | I2: =F2*Controls!$B$52+C2*Controls!$B$53 -> 0 | J2: =D2*Controls!$B$54 -> 0 | K2: =G2*Controls!$B$55 -> 0 | L2: =F2*Controls!$B$56+Monthly_Deployment!R2*Controls!$B$57+IF(A2=1,Controls!$B$64+Controls!$B$65+Controls!$B$66,0) -> 2450 | M2: =E2*(Controls!$B$58*Controls!$B$25/1000+Controls!$B$59+Controls!$B$60+Controls!$B$61)+(G2+H2)*(Controls!$B$62+Controls!$B$63) -> 0 | N2: =SUM(G2:M2) -> 2450 | O2: =N2 -> 2450
A3: 2 | B3: =Monthly_Deployment!C3 -> Aug-26 | C3: =Monthly_Deployment!O3 -> 5 | D3: =Monthly_Deployment!P3 -> 0 | E3: =Monthly_Deployment!R3 -> 3 | F3: =IF(AND(Monthly_Deployment!G3=0,Monthly_Deployment!D3>0),1,0)+IF(AND(Monthly_Deployment!H3=0,Monthly_Deployment!E3>0),1,0) -> 1 | G3: =IF(Controls!$B$45=0,0,C3/(1+Controls!$B$47)*1000000/Controls!$B$45*Controls!$B$46*Controls!$B$25/1000) -> 54723.81 | H3: =E3*Controls!$B$50*Controls!$B$25/1000 -> 17850 | I3: =F3*Controls!$B$52+C3*Controls!$B$53 -> 44406 | J3: =D3*Controls!$B$54 -> 0 | K3: =G3*Controls!$B$55 -> 1094.4762 | L3: =F3*Controls!$B$56+Monthly_Deployment!R3*Controls!$B$57+IF(A3=1,Controls!$B$64+Controls!$B$65+Controls!$B$66,0) -> 855 | M3: =E3*(Controls!$B$58*Controls!$B$25/1000+Controls!$B$59+Controls!$B$60+Controls!$B$61)+(G3+H3)*(Controls!$B$62+Controls!$B$63) -> 5572.4286 | N3: =SUM(G3:M3) -> 124501.71 | O3: =N3 -> 124501.71
A4: 3 | B4: =Monthly_Deployment!C4 -> Sept-26 | C4: =Monthly_Deployment!O4 -> 10 | D4: =Monthly_Deployment!P4 -> 0 | E4: =Monthly_Deployment!R4 -> 5 | F4: =IF(AND(Monthly_Deployment!G4=0,Monthly_Deployment!D4>0),1,0)+IF(AND(Monthly_Deployment!H4=0,Monthly_Deployment!E4>0),1,0) -> 1 | G4: =IF(Controls!$B$45=0,0,C4/(1+Controls!$B$47)*1000000/Controls!$B$45*Controls!$B$46*Controls!$B$25/1000) -> 109447.62 | H4: =E4*Controls!$B$50*Controls!$B$25/1000 -> 29750 | I4: =F4*Controls!$B$52+C4*Controls!$B$53 -> 63436 | J4: =D4*Controls!$B$54 -> 0 | K4: =G4*Controls!$B$55 -> 2188.9524 | L4: =F4*Controls!$B$56+Monthly_Deployment!R4*Controls!$B$57+IF(A4=1,Controls!$B$64+Controls!$B$65+Controls!$B$66,0) -> 925 | M4: =E4*(Controls!$B$58*Controls!$B$25/1000+Controls!$B$59+Controls!$B$60+Controls!$B$61)+(G4+H4)*(Controls!$B$62+Controls!$B$63) -> 10381.857 | N4: =SUM(G4:M4) -> 216129.43 | O4: =N4 -> 216129.43
A5: 4 | B5: =Monthly_Deployment!C5 -> Oct-26 | C5: =Monthly_Deployment!O5 -> 5 | D5: =Monthly_Deployment!P5 -> 10 | E5: =Monthly_Deployment!R5 -> 3 | F5: =IF(AND(Monthly_Deployment!G5=0,Monthly_Deployment!D5>0),1,0)+IF(AND(Monthly_Deployment!H5=0,Monthly_Deployment!E5>0),1,0) -> 0 | G5: =IF(Controls!$B$45=0,0,C5/(1+Controls!$B$47)*1000000/Controls!$B$45*Controls!$B$46*Controls!$B$25/1000) -> 54723.81 | H5: =E5*Controls!$B$50*Controls!$B$25/1000 -> 17850 | I5: =F5*Controls!$B$52+C5*Controls!$B$53 -> 19030 | J5: =D5*Controls!$B$54 -> 70000 | K5: =G5*Controls!$B$55 -> 1094.4762 | L5: =F5*Controls!$B$56+Monthly_Deployment!R5*Controls!$B$57+IF(A5=1,Controls!$B$64+Controls!$B$65+Controls!$B$66,0) -> 105 | M5: =E5*(Controls!$B$58*Controls!$B$25/1000+Controls!$B$59+Controls!$B$60+Controls!$B$61)+(G5+H5)*(Controls!$B$62+Controls!$B$63) -> 5572.4286 | N5: =SUM(G5:M5) -> 168375.71 | O5: =N5 -> 168375.71
A6: 5 | B6: =Monthly_Deployment!C6 -> Nov-26 | C6: =Monthly_Deployment!O6 -> 0 | D6: =Monthly_Deployment!P6 -> 0 | E6: =Monthly_Deployment!R6 -> 0 | F6: =IF(AND(Monthly_Deployment!G6=0,Monthly_Deployment!D6>0),1,0)+IF(AND(Monthly_Deployment!H6=0,Monthly_Deployment!E6>0),1,0) -> 0 | G6: =IF(Controls!$B$45=0,0,C6/(1+Controls!$B$47)*1000000/Controls!$B$45*Controls!$B$46*Controls!$B$25/1000) -> 0 | H6: =E6*Controls!$B$50*Controls!$B$25/1000 -> 0 | I6: =F6*Controls!$B$52+C6*Controls!$B$53 -> 0 | J6: =D6*Controls!$B$54 -> 0 | K6: =G6*Controls!$B$55 -> 0 | L6: =F6*Controls!$B$56+Monthly_Deployment!R6*Controls!$B$57+IF(A6=1,Controls!$B$64+Controls!$B$65+Controls!$B$66,0) -> 0 | M6: =E6*(Controls!$B$58*Controls!$B$25/1000+Controls!$B$59+Controls!$B$60+Controls!$B$61)+(G6+H6)*(Controls!$B$62+Controls!$B$63) -> 0 | N6: =SUM(G6:M6) -> 0 | O6: =N6 -> 0
A7: 6 | B7: =Monthly_Deployment!C7 -> Dec-26 | C7: =Monthly_Deployment!O7 -> 0 | D7: =Monthly_Deployment!P7 -> 0 | E7: =Monthly_Deployment!R7 -> 0 | F7: =IF(AND(Monthly_Deployment!G7=0,Monthly_Deployment!D7>0),1,0)+IF(AND(Monthly_Deployment!H7=0,Monthly_Deployment!E7>0),1,0) -> 0 | G7: =IF(Controls!$B$45=0,0,C7/(1+Controls!$B$47)*1000000/Controls!$B$45*Controls!$B$46*Controls!$B$25/1000) -> 0 | H7: =E7*Controls!$B$50*Controls!$B$25/1000 -> 0 | I7: =F7*Controls!$B$52+C7*Controls!$B$53 -> 0 | J7: =D7*Controls!$B$54 -> 0 | K7: =G7*Controls!$B$55 -> 0 | L7: =F7*Controls!$B$56+Monthly_Deployment!R7*Controls!$B$57+IF(A7=1,Controls!$B$64+Controls!$B$65+Controls!$B$66,0) -> 0 | M7: =E7*(Controls!$B$58*Controls!$B$25/1000+Controls!$B$59+Controls!$B$60+Controls!$B$61)+(G7+H7)*(Controls!$B$62+Controls!$B$63) -> 0 | N7: =SUM(G7:M7) -> 0 | O7: =N7 -> 0
A8: 7 | B8: =Monthly_Deployment!C8 -> Jan-27 | C8: =Monthly_Deployment!O8 -> 0 | D8: =Monthly_Deployment!P8 -> 0 | E8: =Monthly_Deployment!R8 -> 0 | F8: =IF(AND(Monthly_Deployment!G8=0,Monthly_Deployment!D8>0),1,0)+IF(AND(Monthly_Deployment!H8=0,Monthly_Deployment!E8>0),1,0) -> 0 | G8: =IF(Controls!$B$45=0,0,C8/(1+Controls!$B$47)*1000000/Controls!$B$45*Controls!$B$46*Controls!$B$25/1000) -> 0 | H8: =E8*Controls!$B$50*Controls!$B$25/1000 -> 0 | I8: =F8*Controls!$B$52+C8*Controls!$B$53 -> 0 | J8: =D8*Controls!$B$54 -> 0 | K8: =G8*Controls!$B$55 -> 0 | L8: =F8*Controls!$B$56+Monthly_Deployment!R8*Controls!$B$57+IF(A8=1,Controls!$B$64+Controls!$B$65+Controls!$B$66,0) -> 0 | M8: =E8*(Controls!$B$58*Controls!$B$25/1000+Controls!$B$59+Controls!$B$60+Controls!$B$61)+(G8+H8)*(Controls!$B$62+Controls!$B$63) -> 0 | N8: =SUM(G8:M8) -> 0 | O8: =N8 -> 0
A9: 8 | B9: =Monthly_Deployment!C9 -> Feb-27 | C9: =Monthly_Deployment!O9 -> 0 | D9: =Monthly_Deployment!P9 -> 0 | E9: =Monthly_Deployment!R9 -> 0 | F9: =IF(AND(Monthly_Deployment!G9=0,Monthly_Deployment!D9>0),1,0)+IF(AND(Monthly_Deployment!H9=0,Monthly_Deployment!E9>0),1,0) -> 0 | G9: =IF(Controls!$B$45=0,0,C9/(1+Controls!$B$47)*1000000/Controls!$B$45*Controls!$B$46*Controls!$B$25/1000) -> 0 | H9: =E9*Controls!$B$50*Controls!$B$25/1000 -> 0 | I9: =F9*Controls!$B$52+C9*Controls!$B$53 -> 0 | J9: =D9*Controls!$B$54 -> 0 | K9: =G9*Controls!$B$55 -> 0 | L9: =F9*Controls!$B$56+Monthly_Deployment!R9*Controls!$B$57+IF(A9=1,Controls!$B$64+Controls!$B$65+Controls!$B$66,0) -> 0 | M9: =E9*(Controls!$B$58*Controls!$B$25/1000+Controls!$B$59+Controls!$B$60+Controls!$B$61)+(G9+H9)*(Controls!$B$62+Controls!$B$63) -> 0 | N9: =SUM(G9:M9) -> 0 | O9: =N9 -> 0
