Workbook

Sheet Dashboard
A1: 10-YEAR MASTER MODEL · ENERGY THAT YIELDS
A2: Investment case = Core Platform (Layers 1-4). Phase 1: 10MW Grootvlei + 10MW AMSA. Layer 5 (owned inference / GPUs) is held as a separate strategic option / potential SPV and is NOT modelled in this case.
A4: HEADLINE OUTPUTS - CORE PLATFORM (LAYERS 1-4)
A5: Metric | B5: Value | C5: Unit | D5: Interpretation
A6: 2035 Revenue | B6: =Financing_DCF!K4 -> 29033.666 | C6: R'm | D6: Layers 1-4 only; no owned-inference revenue.
A7: 2035 EBITDA | B7: =Financing_DCF!K15 -> 18635.257 | C7: R'm | D7: Strong operating leverage once capacity is deployed.
A8: 10Y Capex (Layers 1-4) | B8: =Capex_Model!K22 -> 85910 | C8: R'm | D8: Excludes Layer 5 GPU / owned-inference capex.
A9: NPV / EV (unlevered) | B9: =Financing_DCF!N4 -> 45538.63 | C9: R'm | D9: Discounted FCF + terminal value (8x 2035 EBITDA) at 15%.
A10: Unlevered IRR | B10: =Financing_DCF!N5 -> 0.38486848 | C10: % | D10: Project IRR on Layers 1-4.
A11: Peak connected MW | B11: =MAX(Load_Tariff!B4:K4) -> 2400 | C11: MW | D11: Incl. ~250MW reserved as headroom for the Layer 5 option.
A13: LAYER 5 - OWNED INFERENCE (GPUs): STRATEGIC OPTION - NOT IN THE INVESTMENT CASE
A14: Owned inference (buying and operating our own GPU / accelerator fleet) is deliberately excluded from this infrastructure investment case and from the model’s capex, revenue and valuation.
A15: Rationale: GPU fleets carry a 24-36 month obsolescence cycle and venture-style technology risk that does not fit an infrastructure mandate. This case funds the power, electrical, cooling and hosting platform (the PropCo, Layers 1-4) - it does not fund the GPUs.
A16: Stance: the Layer 5 business case will be evaluated later in the business cycle - only once AI/DC hosting demand, GPU / vendor financing and utilisation evidence are proven. If pursued, it is expected to be ring-fenced in a separate SPV / OpCo with venture or vendor / equipment financing.
A17: The five-layer revenue-stack concept is retained in the narrative; Layer 5’s chip capex and inference revenue are intentionally not modelled here. Indicative-only parameters sit on the Layer5_Option tab and can be switched on via Scenario_Control!B54 for evaluation.
A19: 2035 REVENUE MIX - CORE PLATFORM | F19: 10Y CAPEX BRIDGE - CORE PLATFORM (LAYERS 1-4)
A20: Layer | B20: 2035 Rev (R'm) | C20: % total | D20: Note | F20: Component | G20: 10Y Capex (R'm) | H20: Share | I20: Note
A21: BTC anchor | B21: =Revenue_Bridge!K4 -> 10542.76 | C21: =B21/Revenue_Bridge!$K$10 -> 0.36312191 | D21: Liquid, interruptible anchor load. | F21: Mining infrastructure | G21: =SUM(Capex_Model!B9:K9) -> 36400 | H21: =G21/Capex_Model!$K$22 -> 0.42369922 | I21: Flexible ASIC load; BTC anchor + DR buffer.
A22: DR / grid services | B22: =Revenue_Bridge!K5+Revenue_Bridge!K7 -> 2205.84 | C22: =B22/Revenue_Bridge!$K$10 -> 0.075975248 | D22: Flexible-demand & grid-stabilisation services. | F22: Electrical / site | G22: =SUM(Capex_Model!B10:K10) -> 12000 | H22: =G22/Capex_Model!$K$22 -> 0.13968106 | I22: Grid integration & site enablement.
A23: AI/DC resale + hosting | B23: =Revenue_Bridge!K8+Revenue_Bridge!K9 -> 16285.066 | C23: =B23/Revenue_Bridge!$K$10 -> 0.56090284 | D23: Core AI infra layer (no GPU ownership). | F23: Solar | G23: =SUM(Capex_Model!B11:K11) -> 10500 | H23: =G23/Capex_Model!$K$22 -> 0.12222093 | I23: Tariff optimisation / green compute.
A24: Layer 5 - owned inference | B24: Not modelled | C24: - | D24: Strategic option / potential SPV. | F24: AI/DC host infrastructure | G24: =SUM(Capex_Model!B12:K12) -> 19200 | H24: =G24/Capex_Model!$K$22 -> 0.2234897 | I24: Non-GPU hosting; can be partner-funded.
A25: Total (Layers 1-4) | B25: =SUM(B21:B23) -> 29033.666 | C25: =SUM(C21:C23) -> 1 | F25: Contingency | G25: =Capex_Model!K22-SUM(Capex_Model!B9:K12) -> 7810 | H25: =G25/Capex_Model!$K$22 -> 0.090909091 | I25: Programme reserve (10%).
F26: Total (Layers 1-4) | G26: =SUM(G21:G25) -> 85910 | H26: =SUM(H21:H25) -> 1
F27: Memo: Layer 5 GPU capex (EXCLUDED) | G27: Not funded by infra vehicle | H27: Separate SPV / venture financing.
A29: MILESTONE-GATED CAPITAL UNLOCKS - CORE PLATFORM
A30: Gate | B30: Timing | C30: Capacity | D30: Indicative unlock | F30: Key condition
A31: 1 | B31: Q1-26 | C31: 20 MW | D31: R0.6bn | F31: Phase 1 funded and energised (10MW Grootvlei + 10MW AMSA).
A32: 2 | B32: Q2-26 | C32: 160 MW | D32: R3.2bn | F32: DR proven to Eskom/NTCSA; tariff path to <=R0.80/kWh.
A33: 3 | B33: Q3-Q4 26 | C33: 550 MW | D33: R8.8bn | F33: AMSA/Grootvlei scale; first AI/DC 5MW contracted.
A34: 4 | B34: Q1-Q2 27 | C34: 1,200 MW | D34: R14.0bn | F34: Additional node; essential-load approvals for AI/DC.
A35: 5 | B35: Q3-Q4 27 | C35: 2,000 MW | D35: R20.0bn | F35: Net tariff <=R0.50/kWh; grid-stabilisation value recognised.
A36: 6 | B36: 2028 | C36: 2,400 MW | D36: R20.0bn | F36: AI/DC client base >=100MW (creditworthy offtake).
A37: Layer 5 (owned inference) gates are NOT part of this case - they would be evaluated separately and, if pursued, funded via a dedicated SPV / OpCo (see Layer5_Option tab).

Sheet Scenario_Control
A1: BitMach 10-Year Master Model v7 - Scenario Control
A3: Control / Input | B3: Value | C3: Unit | D3: Explanation / investor interpretation
A4: Selected ramp case | B4: Full Platform Acceleration | D4: Default case for investor brief: no capital shortage, fastest practical milestone-gated scale path.
A5: Selected revenue case | B5: Integrated Energy Infrastructure | D5: Uses BTC anchor, DR/grid services, AI/DC power resale and hosting. Owned inference is shown separately as Layer 5.
A6: Selected funding case | B6: Infrastructure Funded | D6: Assumes a deep-pocketed infrastructure investor plus project debt, vendor/partner funding and equipment finance.
A7: Phase 1 configuration | B7: 10 MW Grootvlei + 10 MW AMSA | D7: Fixed per latest direction. Useful for DR qualification and two-node proof of execution.
A8: FX rate | B8: 17 | C8: ZAR/USD | D8: Used to translate USD-priced hardware, BTC price and AI references into ZAR.
A9: Discount rate | B9: 0.15 | C9: % | D9: Equity/infrastructure discount rate for NPV. Change to test valuation sensitivity.
A10: Terminal EBITDA multiple | B10: 8 | C10: x | D10: Applied to final-year EBITDA for terminal value. Infrastructure/compute hybrid valuation lens.
A11: Corporate tax rate | B11: 0.27 | C11: % | D11: South African corporate tax assumption.
A12: BTC price - start | B12: 75000 | C12: USD/BTC | D12: Starting BTC price assumption.
A13: BTC price growth | B13: 0.12 | C13: % p.a. | D13: Long-run BTC price growth case. Sensitise heavily.
A14: Network hash growth | B14: 0.12 | C14: % p.a. | D14: Network difficulty/hash growth. Higher value reduces BTC mined per TH/s.
A15: BTC fees - initial | B15: 0.15 | C15: % of subsidy | D15: Transaction-fee contribution as % of block subsidy in 2026.
A16: BTC fee growth | B16: 0.075 | C16: % pts p.a. | D16: Fee contribution increases over time to partly offset protocol issuance decline.
A17: Uptime | B17: 0.98 | C17: % | D17: Technical availability across load categories. Hydro-cooled architecture and industrial operations target high uptime.
A18: Mining hours per day | B18: 19 | C18: hours/day | D18: Interruptible mining load operating profile under Eskom pilot/tariff framework.
A19: Essential load hours per day | B19: 24 | C19: hours/day | D19: AI/DC and inference are essential load and run 24/7.
... A54: Layer 5 (owned inference) - model in base case? | B54: 0 | C54: 1=Yes / 0=No | D54: Owned inference (GPUs) is held as a separate strategic option / potential SPV and is EXCLUDED from the base infrastructure investment case. Set to 1 to switch the Layer 5 business case back on for evaluation.
A56: Blue = editable input. Yellow = key value-driving assumption (sensitise these).

Sheet Case_Ramp_Annual
A1: Case Ramp Annual - Connected Capacity by Site (MW)
A3: Ramp Case / Site | B3: 2026 | C3: 2027 | D3: 2028 | E3: 2029 | F3: 2030 | G3: 2031 | H3: 2032 | I3: 2033 | J3: 2034 | K3: 2035
A4: Full Platform Acceleration
A5: Grootvlei | B5: 20 | C5: 100 | D5: 200 | E5: 200 | F5: 200 | G5: 200 | H5: 200 | I5: 200 | J5: 200 | K5: 200
A6: AMSA Vanderbijlpark | B6: 20 | C6: 350 | D6: 350 | E6: 350 | F6: 350 | G6: 350 | H6: 350 | I6: 350 | J6: 350 | K6: 350
A7: AMSA Newcastle | B7: 0 | C7: 450 | D7: 450 | E7: 450 | F7: 450 | G7: 450 | H7: 450 | I7: 450 | J7: 450 | K7: 450
A8: Saldanha | B8: 0 | C8: 350 | D8: 350 | E8: 350 | F8: 350 | G8: 350 | H8: 350 | I8: 350 | J8: 350 | K8: 350
A9: Komati / Eskom Nodes | B9: 0 | C9: 100 | D9: 650 | E9: 850 | F9: 1050 | G9: 1050 | H9: 1050 | I9: 1050 | J9: 1050 | K9: 1050
A10: Total Connected MW | B10: 40 | C10: 1350 | D10: 2000 | E10: 2200 | F10: 2400 | G10: 2400 | H10: 2400 | I10: 2400 | J10: 2400 | K10: 2400
A12: Institutional Growth
A13: Grootvlei | B13: 20 | C13: 80 | D13: 120 | E13: 160 | F13: 200 | G13: 200 | H13: 200 | I13: 200 | J13: 200 | K13: 200
A14: AMSA Vanderbijlpark | B14: 20 | C14: 100 | D14: 200 | E14: 280 | F14: 350 | G14: 350 | H14: 350 | I14: 350 | J14: 350 | K14: 350
A15: AMSA Newcastle | B15: 0 | C15: 0 | D15: 150 | E15: 300 | F15: 450 | G15: 450 | H15: 450 | I15: 450 | J15: 450 | K15: 450
A16: Saldanha | B16: 0 | C16: 0 | D16: 0 | E16: 150 | F16: 300 | G16: 350 | H16: 350 | I16: 350 | J16: 350 | K16: 350
A17: Komati / Eskom Nodes | B17: 0 | C17: 20 | D17: 130 | E17: 300 | F17: 500 | G17: 650 | H17: 850 | I17: 950 | J17: 1050 | K17: 1050
A18: Total Connected MW | B18: 40 | C18: 200 | D18: 600 | E18: 1190 | F18: 1800 | G18: 2000 | H18: 2200 | I18: 2300 | J18: 2400 | K18: 2400
A20: Phase 1 Underwriting
A21: Grootvlei | B21: 10 | C21: 20 | D21: 30 | E21: 40 | F21: 50 | G21: 60 | H21: 70 | I21: 80 | J21: 90 | K21: 100
A22: AMSA Vanderbijlpark | B22: 10 | C22: 20 | D22: 40 | E22: 60 | F22: 80 | G22: 100 | H22: 120 | I22: 140 | J22: 160 | K22: 180
A23: AMSA Newcastle | B23: 0 | C23: 0 | D23: 0 | E23: 50 | F23: 100 | G23: 150 | H23: 200 | I23: 250 | J23: 300 | K23: 350
A24: Saldanha | B24: 0 | C24: 0 | D24: 0 | E24: 0 | F24: 50 | G24: 100 | H24: 150 | I24: 200 | J24: 250 | K24: 300
A25: Komati / Eskom Nodes | B25: 0 | C25: 0 | D25: 20 | E25: 40 | F25: 80 | G25: 120 | H25: 180 | I25: 240 | J25: 300 | K25: 400
A26: Total Connected MW | B26: 20 | C26: 40 | D26: 90 | E26: 190 | F26: 360 | G26: 530 | H26: 720 | I26: 910 | J26: 1100 | K26: 1330

Sheet Quarterly_Ramp
A1: Full Platform Acceleration - 36 Month Ramp & Capital Unlocks
A3: Metric | B3: Q1-26 | C3: Q2-26 | D3: Q3-26 | E3: Q4-26 | F3: Q1-27 | G3: Q2-27 | H3: Q3-27 | I3: Q4-27 | J3: Q1-28 | K3: Q2-28 | L3: Q3-28 | M3: Q4-28
A4: Grootvlei MW | B4: 20 | C4: 60 | D4: 100 | E4: 100 | F4: 150 | G4: 200 | H4: 200 | I4: 200 | J4: 200 | K4: 200 | L4: 200 | M4: 200
A5: AMSA Vanderbijlpark MW | B5: 20 | C5: 100 | D5: 200 | E5: 350 | F5: 350 | G5: 350 | H5: 350 | I5: 350 | J5: 350 | K5: 350 | L5: 350 | M5: 350
A6: AMSA Newcastle MW | B6: 0 | C6: 0 | D6: 0 | E6: 50 | F6: 150 | G6: 300 | H6: 450 | I6: 450 | J6: 450 | K6: 450 | L6: 450 | M6: 450
A7: Saldanha MW | B7: 0 | C7: 0 | D7: 0 | E7: 0 | F7: 50 | G7: 150 | H7: 275 | I7: 350 | J7: 350 | K7: 350 | L7: 350 | M7: 350
A8: Komati / Eskom Nodes MW | B8: 0 | C8: 0 | D8: 0 | E8: 50 | F8: 100 | G8: 200 | H8: 275 | I8: 650 | J8: 800 | K8: 850 | L8: 850 | M8: 850
A9: Total Connected MW | B9: 40 | C9: 160 | D9: 300 | E9: 550 | F9: 800 | G9: 1200 | H9: 1550 | I9: 2000 | J9: 2150 | K9: 2200 | L9: 2200 | M9: 2200
A10: AI/DC Customer MW | B10: 0 | C10: 0 | D10: 5 | E10: 20 | F10: 50 | G10: 100 | H10: 150 | I10: 250 | J10: 350 | K10: 450 | L10: 550 | M10: 600
A11: Reserved Layer-5 MW (option - separate SPV) | B11: 0 | C11: 0 | D11: 0 | E11: 0 | F11: 5 | G11: 25 | H11: 50 | I11: 100 | J11: 150 | K11: 200 | L11: 225 | M11: 250
A12: Milestone / Gate | B12: Phase 1 funded | C12: DR proof + tariff <=R0.80 | D12: AMSA/GVL buildout | E12: AI/DC 5MW contracted | F12: New node active | G12: Net tariff <=R0.50 | H12: AI/DC >=100MW | I12: 1GW+ achieved | J12: Own inference 5MW stable | K12: 2GW+ achieved | L12: Own inference 250MW path | M12: Full acceleration stabilisation
A13: Capital unlock this quarter (Rbn) | B13: 0.6 | C13: 3.2 | D13: 2.8 | E13: 6 | F13: 6 | G13: 8 | H13: 8 | I13: 12 | J13: 8 | K13: 6 | L13: 4 | M13: 2

Sheet Site_Master
A1: Site Master - Capacity, Status and Commercial Role
A3: Site | B3: Grid Capacity MW | C3: Solar PV MW | D3: Phase Role | E3: Acceleration Timing | F3: Primary Revenue Role | G3: Milestone / dependency | H3: Source / context | I3: Investor note
A4: Grootvlei | B4: 200 | C4: 0 | D4: Phase 1 + scale node | E4: Q1-26 to Q2-27 | F4: BTC anchor, DR proof, grid services | G4: Eskom tariff / DR proof, self-build EPC | H4: Concept design, EPC quote, Eskom pilot materials | I4: Repurposed power-station node with existing grid infrastructure.
A5: AMSA Vanderbijlpark | B5: 350 | C5: 500 | D5: Phase 1 + industrial platform | E5: Q1-26 to Q4-26 | F5: BTC anchor, solar blending, AI/DC hosting | G5: AMSA definitive agreement, solar rights, 10MW initial block | H5: AMSA term sheet / investor materials | I5: Industrial precinct with solar and customer adjacency.
A6: AMSA Newcastle | B6: 450 | C6: 500 | D6: Phase 3 scale node | E6: Q4-26 to Q3-27 | F6: BTC, DR, AI/DC hosting | G6: AMSA Newcastle unlock, grid and solar due diligence | H6: AMSA term sheet / management roadmap | I6: Large industrial node for rapid scale.
A7: Saldanha | B7: 350 | C7: 450 | D7: Phase 4 coastal node | E7: Q1-27 to Q4-27 | F7: BTC, solar, AI/DC hosting | G7: Saldanha site rights and grid/solar confirmation | H7: AMSA term sheet / management roadmap | I7: Strategic coastal / industrial energy node.
A8: Komati / additional Eskom nodes | B8: 1050 | C8: 0 | D8: Eskom-node replication | E8: Q4-26 to Q4-28 | F8: BTC, DR, grid services, AI/DC expansion | G8: Eskom/NTCSA agreements; node-by-node approvals | H8: Eskom proposal history and platform plan | I8: Portfolio of power-station / grid nodes enabling 2GW+ scale.

Sheet Load_Tariff
A1: Load & Tariff Model - Interruptible Mining vs Essential AI/DC Load
A3: Metric | B3: 2026 | C3: 2027 | D3: 2028 | E3: 2029 | F3: 2030 | G3: 2031 | H3: 2032 | I3: 2033 | J3: 2034 | K3: 2035
A4: Closing connected MW | B4: =Case_Ramp_Annual!B10 -> 40 | C4: =Case_Ramp_Annual!C10 -> 1350 | D4: =Case_Ramp_Annual!D10 -> 2000 | E4: =Case_Ramp_Annual!E10 -> 2200 | F4: =Case_Ramp_Annual!F10 -> 2400 | G4: =Case_Ramp_Annual!G10 -> 2400 | H4: =Case_Ramp_Annual!H10 -> 2400 | I4: =Case_Ramp_Annual!I10 -> 2400 | ... K4: =Case_Ramp_Annual!K10 -> 2400
A5: Opening connected MW | B5: =0 -> 0 | C5: =B4 -> 40 | D5: =C4 -> 1350 | E5: =D4 -> 2000 | F5: =E4 -> 2200 | G5: =F4 -> 2400 | H5: =G4 -> 2400 | I5: =H4 -> 2400 | J5: =I4 -> 2400 | K5: =J4 -> 2400
A6: Average connected MW | B6: =AVERAGE(B4,B5) -> 20 | C6: =AVERAGE(C4,C5) -> 695 | D6: =AVERAGE(D4,D5) -> 1675 | E6: =AVERAGE(E4,E5) -> 2100 | F6: =AVERAGE(F4,F5) -> 2300 | G6: =AVERAGE(G4,G5) -> 2400 | H6: =AVERAGE(H4,H5) -> 2400 | I6: =AVERAGE(I4,I5) -> 2400 | ... K6: =AVERAGE(K4,K5) -> 2400
A7: AI/DC hosting essential load share | B7: =0 -> 0 | C7: =0.05 -> 0.05 | D7: =0.1 -> 0.1 | E7: =0.15 -> 0.15 | F7: =0.2 -> 0.2 | G7: =0.25 -> 0.25 | H7: =0.3 -> 0.3 | I7: =0.3 -> 0.3 | J7: =0.3 -> 0.3 | K7: =0.3 -> 0.3
A8: Reserved capacity for optional Layer 5 (MW) | B8: =0 -> 0 | C8: =0 -> 0 | D8: =5 -> 5 | E8: =50 -> 50 | F8: =100 -> 100 | G8: =250 -> 250 | H8: =250 -> 250 | I8: =250 -> 250 | J8: =250 -> 250 | K8: =250 -> 250
A9: AI/DC hosting MW | B9: =MAX(0,MIN(B4*0.3-B8,B4*0)) -> 0 | C9: =MAX(0,MIN(C4*0.3-C8,C4*0.05)) -> 67.5 | D9: =MAX(0,MIN(D4*0.3-D8,D4*0.1)) -> 200 | E9: =MAX(0,MIN(E4*0.3-E8,E4*0.15)) -> 330 | F9: =MAX(0,MIN(F4*0.3-F8,F4*0.2)) -> 480 | G9: =MAX(0,MIN(G4*0.3-G8,G4*0.25)) -> 470 | H9: =MAX(0,MIN(H4*0.3-H8,H4*0.3)) -> 470 | I9: =MAX(0,MIN(I4*0.3-I8,I4*0.3)) -> 470 | J9: =MAX(0,MIN(J4*0.3-J8,J4*0.3)) -> 470 | K9: =MAX(0,MIN(K4*0.3-K8,K4*0.3)) -> 470
A10: Total essential MW | B10: =B8+B9 -> 0 | C10: =C8+C9 -> 67.5 | D10: =D8+D9 -> 205 | E10: =E8+E9 -> 380 | F10: =F8+F9 -> 580 | G10: =G8+G9 -> 720 | H10: =H8+H9 -> 720 | I10: =I8+I9 -> 720 | ... K10: =K8+K9 -> 720
A11: Interruptible mining MW | B11: =MAX(0,B4-B10) -> 40 | C11: =MAX(0,C4-C10) -> 1282.5 | D11: =MAX(0,D4-D10) -> 1795 | E11: =MAX(0,E4-E10) -> 1820 | F11: =MAX(0,F4-F10) -> 1820 | G11: =MAX(0,G4-G10) -> 1680 | H11: =MAX(0,H4-H10) -> 1680 | I11: =MAX(0,I4-I10) -> 1680 | ... K11: =MAX(0,K4-K10) -> 1680
A12: Essential load cap check | B12: =B10/B4 -> 0 | C12: =C10/C4 -> 0.05 | D12: =D10/D4 -> 0.1025 | E12: =E10/E4 -> 0.17272727 | F12: =F10/F4 -> 0.24166667 | G12: =G10/G4 -> 0.3 | H12: =H10/H4 -> 0.3 | I12: =I10/I4 -> 0.3 | ... K12: =K10/K4 -> 0.3
A13: Mining energy (GWh) | B13: =B11*Scenario_Control!$B$18*365*Scenario_Control!$B$17/1000 -> 271.852 | C13: =C11*Scenario_Control!$B$18*365*Scenario_Control!$B$17/1000 -> 8716.2548 | D13: =D11*Scenario_Control!$B$18*365*Scenario_Control!$B$17/1000 -> 12199.359 | E13: =E11*Scenario_Control!$B$18*365*Scenario_Control!$B$17/1000 -> 12369.266 | F13: =F11*Scenario_Control!$B$18*365*Scenario_Control!$B$17/1000 -> 12369.266 | G13: =G11*Scenario_Control!$B$18*365*Scenario_Control!$B$17/1000 -> 11417.784 | H13: =H11*Scenario_Control!$B$18*365*Scenario_Control!$B$17/1000 -> 11417.784 | I13: =I11*Scenario_Control!$B$18*365*Scenario_Control!$B$17/1000 -> 11417.784 | ... K13: =K11*Scenario_Control!$B$18*365*Scenario_Control!$B$17/1000 -> 11417.784
A14: AI/DC host energy (GWh) | B14: =B9*Scenario_Control!$B$19*365*Scenario_Control!$B$17/1000 -> 0 | C14: =C9*Scenario_Control!$B$19*365*Scenario_Control!$B$17/1000 -> 579.474 | D14: =D9*Scenario_Control!$B$19*365*Scenario_Control!$B$17/1000 -> 1716.96 | E14: =E9*Scenario_Control!$B$19*365*Scenario_Control!$B$17/1000 -> 2832.984 | F14: =F9*Scenario_Control!$B$19*365*Scenario_Control!$B$17/1000 -> 4120.704 | G14: =G9*Scenario_Control!$B$19*365*Scenario_Control!$B$17/1000 -> 4034.856 | H14: =H9*Scenario_Control!$B$19*365*Scenario_Control!$B$17/1000 -> 4034.856 | I14: =I9*Scenario_Control!$B$19*365*Scenario_Control!$B$17/1000 -> 4034.856 | ... K14: =K9*Scenario_Control!$B$19*365*Scenario_Control!$B$17/1000 -> 4034.856
A15: Reserved / Layer-5 energy (GWh) - nil unless Layer 5 evaluated | B15: =B8*Scenario_Control!$B$19*365*Scenario_Control!$B$17/1000*Scenario_Control!$B$54 -> 0 | C15: =C8*Scenario_Control!$B$19*365*Scenario_Control!$B$17/1000*Scenario_Control!$B$54 -> 0 | D15: =D8*Scenario_Control!$B$19*365*Scenario_Control!$B$17/1000*Scenario_Control!$B$54 -> 0 | E15: =E8*Scenario_Control!$B$19*365*Scenario_Control!$B$17/1000*Scenario_Control!$B$54 -> 0 | F15: =F8*Scenario_Control!$B$19*365*Scenario_Control!$B$17/1000*Scenario_Control!$B$54 -> 0 | G15: =G8*Scenario_Control!$B$19*365*Scenario_Control!$B$17/1000*Scenario_Control!$B$54 -> 0 | H15: =H8*Scenario_Control!$B$19*365*Scenario_Control!$B$17/1000*Scenario_Control!$B$54 -> 0 | I15: =I8*Scenario_Control!$B$19*365*Scenario_Control!$B$17/1000*Scenario_Control!$B$54 -> 0 | ... K15: =K8*Scenario_Control!$B$19*365*Scenario_Control!$B$17/1000*Scenario_Control!$B$54 -> 0
A16: Interruptible tariff (R/kWh) | B16: =Scenario_Control!$B$20 -> 1.2 | C16: =Scenario_Control!$B$21 -> 0.8 | D16: =Scenario_Control!$B$22 -> 0.6 | E16: =Scenario_Control!$B$23 -> 0.5 | F16: =Scenario_Control!$B$23 -> 0.5 | G16: =Scenario_Control!$B$23 -> 0.5 | H16: =Scenario_Control!$B$23 -> 0.5 | I16: =Scenario_Control!$B$23 -> 0.5 | J16: =Scenario_Control!$B$23 -> 0.5 | K16: =Scenario_Control!$B$23 -> 0.5
A17: Essential import tariff (R/kWh) | B17: =B16+Scenario_Control!$B$24 -> 1.5 | C17: =C16+Scenario_Control!$B$24 -> 1.1 | D17: =D16+Scenario_Control!$B$24 -> 0.9 | E17: =E16+Scenario_Control!$B$24 -> 0.8 | F17: =F16+Scenario_Control!$B$24 -> 0.8 | G17: =G16+Scenario_Control!$B$24 -> 0.8 | H17: =H16+Scenario_Control!$B$24 -> 0.8 | I17: =I16+Scenario_Control!$B$24 -> 0.8 | ... K17: =K16+Scenario_Control!$B$24 -> 0.8
A18: AI/DC resale tariff (R/kWh) | B18: =Scenario_Control!$B$25*(1+Scenario_Control!$B$26)^(B$3-2026) -> 2.5 | C18: =Scenario_Control!$B$25*(1+Scenario_Control!$B$26)^(C$3-2026) -> 2.55 | D18: =Scenario_Control!$B$25*(1+Scenario_Control!$B$26)^(D$3-2026) -> 2.601 | E18: =Scenario_Control!$B$25*(1+Scenario_Control!$B$26)^(E$3-2026) -> 2.65302 | F18: =Scenario_Control!$B$25*(1+Scenario_Control!$B$26)^(F$3-2026) -> 2.7060804 | G18: =Scenario_Control!$B$25*(1+Scenario_Control!$B$26)^(G$3-2026) -> 2.760202 | H18: =Scenario_Control!$B$25*(1+Scenario_Control!$B$26)^(H$3-2026) -> 2.815406 | I18: =Scenario_Control!$B$25*(1+Scenario_Control!$B$26)^(I$3-2026) -> 2.8717142 | ... K18: =Scenario_Control!$B$25*(1+Scenario_Control!$B$26)^(K$3-2026) -> 2.9877314
A19: Mining power cost (R'm) | B19: =B13*B16 -> 326.2224 | C19: =C13*C16 -> 6973.0038 | D19: =D13*D16 -> 7319.6151 | E19: =E13*E16 -> 6184.633 | F19: =F13*F16 -> 6184.633 | G19: =G13*G16 -> 5708.892 | H19: =H13*H16 -> 5708.892 | I19: =I13*I16 -> 5708.892 | ... K19: =K13*K16 -> 5708.892
A20: AI/DC host power cost (R'm) | B20: =B14*B17 -> 0 | C20: =C14*C17 -> 637.4214 | D20: =D14*D17 -> 1545.264 | E20: =E14*E17 -> 2266.3872 | F20: =F14*F17 -> 3296.5632 | G20: =G14*G17 -> 3227.8848 | H20: =H14*H17 -> 3227.8848 | I20: =I14*I17 -> 3227.8848 | ... K20: =K14*K17 -> 3227.8848
A21: Own inference power cost (R'm) | B21: =B15*B17 -> 0 | C21: =C15*C17 -> 0 | D21: =D15*D17 -> 0 | E21: =E15*E17 -> 0 | F21: =F15*F17 -> 0 | G21: =G15*G17 -> 0 | H21: =H15*H17 -> 0 | I21: =I15*I17 -> 0 | ... K21: =K15*K17 -> 0
A22: AI/DC resale power revenue (R'm) | B22: =B14*B18 -> 0 | C22: =C14*C18 -> 1477.6587 | D22: =D14*D18 -> 4465.813 | E22: =E14*E18 -> 7515.9632 | F22: =F14*F18 -> 11150.956 | G22: =G14*G18 -> 11137.018 | H22: =H14*H18 -> 11359.758 | I22: =I14*I18 -> 11586.953 | ... K22: =K14*K18 -> 12055.066
A23: Power gross margin - host (R'm) | B23: =B22-B20 -> 0 | C23: =C22-C20 -> 840.2373 | D23: =D22-D20 -> 2920.549 | E23: =E22-E20 -> 5249.576 | F23: =F22-F20 -> 7854.3931 | G23: =G22-G20 -> 7909.1328 | H23: =H22-H20 -> 8131.8732 | I23: =I22-I20 -> 8359.0683 | ... K23: =K22-K20 -> 8827.1813
A24: Tariff relief vs R1.20 baseline (R'm) | B24: =MAX(0,Scenario_Control!$B$20-B16)*B13 -> 0 | C24: =MAX(0,Scenario_Control!$B$20-C16)*C13 -> 3486.5019 | D24: =MAX(0,Scenario_Control!$B$20-D16)*D13 -> 7319.6151 | E24: =MAX(0,Scenario_Control!$B$20-E16)*E13 -> 8658.4862 | F24: =MAX(0,Scenario_Control!$B$20-F16)*F13 -> 8658.4862 | G24: =MAX(0,Scenario_Control!$B$20-G16)*G13 -> 7992.4488 | H24: =MAX(0,Scenario_Control!$B$20-H16)*H13 -> 7992.4488 | I24: =MAX(0,Scenario_Control!$B$20-I16)*I13 -> 7992.4488 | ... K24: =MAX(0,Scenario_Control!$B$20-K16)*K13 -> 7992.4488

Sheet BTC_Model
A1: BTC Anchor Revenue Model - Halving, Fees and Network Difficulty
A3: Metric | B3: 2026 | C3: 2027 | D3: 2028 | E3: 2029 | F3: 2030 | G3: 2031 | H3: 2032 | I3: 2033 | J3: 2034 | K3: 2035
A4: BTC price (USD) | B4: =Scenario_Control!$B$12*(1+Scenario_Control!$B$13)^(B$3-2026) -> 75000 | C4: =Scenario_Control!$B$12*(1+Scenario_Control!$B$13)^(C$3-2026) -> 84000 | D4: =Scenario_Control!$B$12*(1+Scenario_Control!$B$13)^(D$3-2026) -> 94080 | E4: =Scenario_Control!$B$12*(1+Scenario_Control!$B$13)^(E$3-2026) -> 105369.6 | F4: =Scenario_Control!$B$12*(1+Scenario_Control!$B$13)^(F$3-2026) -> 118013.95 | G4: =Scenario_Control!$B$12*(1+Scenario_Control!$B$13)^(G$3-2026) -> 132175.63 | H4: =Scenario_Control!$B$12*(1+Scenario_Control!$B$13)^(H$3-2026) -> 148036.7 | I4: =Scenario_Control!$B$12*(1+Scenario_Control!$B$13)^(I$3-2026) -> 165801.11 | ... K4: =Scenario_Control!$B$12*(1+Scenario_Control!$B$13)^(K$3-2026) -> 207980.91
A5: Network hash (TH/s) | B5: =900000000*(1+Scenario_Control!$B$14)^(B$3-2026) -> 900000000 | C5: =900000000*(1+Scenario_Control!$B$14)^(C$3-2026) -> 1.008e+09 | D5: =900000000*(1+Scenario_Control!$B$14)^(D$3-2026) -> 1.12896e+09 | E5: =900000000*(1+Scenario_Control!$B$14)^(E$3-2026) -> 1.2644352e+09 | F5: =900000000*(1+Scenario_Control!$B$14)^(F$3-2026) -> 1.4161674e+09 | G5: =900000000*(1+Scenario_Control!$B$14)^(G$3-2026) -> 1.5861075e+09 | H5: =900000000*(1+Scenario_Control!$B$14)^(H$3-2026) -> 1.7764404e+09 | I5: =900000000*(1+Scenario_Control!$B$14)^(I$3-2026) -> 1.9896133e+09 | ... K5: =900000000*(1+Scenario_Control!$B$14)^(K$3-2026) -> 2.4957709e+09
A6: Block subsidy (BTC/block) | B6: =3.125 -> 3.125 | C6: =3.125 -> 3.125 | D6: =1.5625 -> 1.5625 | E6: =1.5625 -> 1.5625 | F6: =1.5625 -> 1.5625 | G6: =1.5625 -> 1.5625 | H6: =0.78125 -> 0.78125 | I6: =0.78125 -> 0.78125 | J6: =0.78125 -> 0.78125 | K6: =0.78125 -> 0.78125
A7: Transaction fees (% of subsidy) | B7: =MIN(1,Scenario_Control!$B$15+Scenario_Control!$B$16*(B$3-2026)) -> 0.15 | C7: =MIN(1,Scenario_Control!$B$15+Scenario_Control!$B$16*(C$3-2026)) -> 0.225 | D7: =MIN(1,Scenario_Control!$B$15+Scenario_Control!$B$16*(D$3-2026)) -> 0.3 | E7: =MIN(1,Scenario_Control!$B$15+Scenario_Control!$B$16*(E$3-2026)) -> 0.375 | F7: =MIN(1,Scenario_Control!$B$15+Scenario_Control!$B$16*(F$3-2026)) -> 0.45 | G7: =MIN(1,Scenario_Control!$B$15+Scenario_Control!$B$16*(G$3-2026)) -> 0.525 | H7: =MIN(1,Scenario_Control!$B$15+Scenario_Control!$B$16*(H$3-2026)) -> 0.6 | I7: =MIN(1,Scenario_Control!$B$15+Scenario_Control!$B$16*(I$3-2026)) -> 0.675 | ... K7: =MIN(1,Scenario_Control!$B$15+Scenario_Control!$B$16*(K$3-2026)) -> 0.825
A8: Effective BTC/block incl. fees | B8: =B6*(1+B7) -> 3.59375 | C8: =C6*(1+C7) -> 3.828125 | D8: =D6*(1+D7) -> 2.03125 | E8: =E6*(1+E7) -> 2.1484375 | F8: =F6*(1+F7) -> 2.265625 | G8: =G6*(1+G7) -> 2.3828125 | H8: =H6*(1+H7) -> 1.25 | I8: =I6*(1+I7) -> 1.3085938 | ... K8: =K6*(1+K7) -> 1.4257812
A9: Network BTC/year | B9: =B8*144*365 -> 188887.5 | C9: =C8*144*365 -> 201206.25 | D9: =D8*144*365 -> 106762.5 | E9: =E8*144*365 -> 112921.88 | F9: =F8*144*365 -> 119081.25 | G9: =G8*144*365 -> 125240.62 | H9: =H8*144*365 -> 65700 | I9: =I8*144*365 -> 68779.688 | ... K9: =K8*144*365 -> 74939.062
A10: Mining MW | B10: =Load_Tariff!B11 -> 40 | C10: =Load_Tariff!C11 -> 1282.5 | D10: =Load_Tariff!D11 -> 1795 | E10: =Load_Tariff!E11 -> 1820 | F10: =Load_Tariff!F11 -> 1820 | G10: =Load_Tariff!G11 -> 1680 | H10: =Load_Tariff!H11 -> 1680 | I10: =Load_Tariff!I11 -> 1680 | ... K10: =Load_Tariff!K11 -> 1680
A11: Effective BitMach hash (TH/s) | B11: =B10/(1+Scenario_Control!$B$34)*1000000/(Scenario_Control!$B$32*Scenario_Control!$B$33)*Scenario_Control!$B$32*(Scenario_Control!$B$18/24)*Scenario_Control!$B$17 -> 2364444.4 | C11: =C10/(1+Scenario_Control!$B$34)*1000000/(Scenario_Control!$B$32*Scenario_Control!$B$33)*Scenario_Control!$B$32*(Scenario_Control!$B$18/24)*Scenario_Control!$B$17 -> 75810000 | D11: =D10/(1+Scenario_Control!$B$34)*1000000/(Scenario_Control!$B$32*Scenario_Control!$B$33)*Scenario_Control!$B$32*(Scenario_Control!$B$18/24)*Scenario_Control!$B$17 -> 1.0610444e+08 | E11: =E10/(1+Scenario_Control!$B$34)*1000000/(Scenario_Control!$B$32*Scenario_Control!$B$33)*Scenario_Control!$B$32*(Scenario_Control!$B$18/24)*Scenario_Control!$B$17 -> 1.0758222e+08 | F11: =F10/(1+Scenario_Control!$B$34)*1000000/(Scenario_Control!$B$32*Scenario_Control!$B$33)*Scenario_Control!$B$32*(Scenario_Control!$B$18/24)*Scenario_Control!$B$17 -> 1.0758222e+08 | G11: =G10/(1+Scenario_Control!$B$34)*1000000/(Scenario_Control!$B$32*Scenario_Control!$B$33)*Scenario_Control!$B$32*(Scenario_Control!$B$18/24)*Scenario_Control!$B$17 -> 99306667 | H11: =H10/(1+Scenario_Control!$B$34)*1000000/(Scenario_Control!$B$32*Scenario_Control!$B$33)*Scenario_Control!$B$32*(Scenario_Control!$B$18/24)*Scenario_Control!$B$17 -> 99306667 | I11: =I10/(1+Scenario_Control!$B$34)*1000000/(Scenario_Control!$B$32*Scenario_Control!$B$33)*Scenario_Control!$B$32*(Scenario_Control!$B$18/24)*Scenario_Control!$B$17 -> 99306667 | ... K11: =K10/(1+Scenario_Control!$B$34)*1000000/(Scenario_Control!$B$32*Scenario_Control!$B$33)*Scenario_Control!$B$32*(Scenario_Control!$B$18/24)*Scenario_Control!$B$17 -> 99306667
A12: BTC mined | B12: =B11/B5*B9 -> 496.23778 | C12: =C11/C5*C9 -> 15132.387 | D12: =D11/D5*D9 -> 10033.992 | E12: =E11/E5*E9 -> 9607.7571 | F12: =F11/F5*F9 -> 9046.2648 | G12: =G11/G5*G9 -> 7841.3531 | H12: =H11/H5*H9 -> 3672.7649 | I12: =I11/I5*I9 -> 3432.9694 | ... K12: =K11/K5*K9 -> 2981.8236
A13: BTC revenue (R'm) | B13: =B12*B4*Scenario_Control!$B$8/1000000 -> 632.70317 | C13: =C12*C4*Scenario_Control!$B$8/1000000 -> 21609.048 | D13: =D12*D4*Scenario_Control!$B$8/1000000 -> 16047.966 | E13: =E12*E4*Scenario_Control!$B$8/1000000 -> 17210.214 | F13: =F12*F4*Scenario_Control!$B$8/1000000 -> 18148.953 | G13: =G12*G4*Scenario_Control!$B$8/1000000 -> 17619.408 | H13: =H12*H4*Scenario_Control!$B$8/1000000 -> 9242.968 | I13: =I12*I4*Scenario_Control!$B$8/1000000 -> 9676.2321 | ... K13: =K12*K4*Scenario_Control!$B$8/1000000 -> 10542.76

Sheet DR_Model
A1: Demand Response / Grid Services Model - Mechanism Stack
A3: Mechanism | B3: 2026 | C3: 2027 | D3: 2028 | E3: 2029 | F3: 2030 | G3: 2031 | H3: 2032 | I3: 2033 | J3: 2034 | K3: 2035
A4: Eligible interruptible MW | B4: =Load_Tariff!B11 -> 40 | C4: =Load_Tariff!C11 -> 1282.5 | D4: =Load_Tariff!D11 -> 1795 | E4: =Load_Tariff!E11 -> 1820 | F4: =Load_Tariff!F11 -> 1820 | G4: =Load_Tariff!G11 -> 1680 | H4: =Load_Tariff!H11 -> 1680 | I4: =Load_Tariff!I11 -> 1680 | ... K4: =Load_Tariff!K11 -> 1680
A5: New eligible MW | B5: =MAX(0,B4-0) -> 40 | C5: =MAX(0,C4-B4) -> 1242.5 | D5: =MAX(0,D4-C4) -> 512.5 | E5: =MAX(0,E4-D4) -> 25 | F5: =MAX(0,F4-E4) -> 0 | G5: =MAX(0,G4-F4) -> 0 | H5: =MAX(0,H4-G4) -> 0 | I5: =MAX(0,I4-H4) -> 0 | J5: =MAX(0,J4-I4) -> 0 | K5: =MAX(0,K4-J4) -> 0
A6: IDR / reserve standby revenue (R'm) | B6: =B4*1000*Scenario_Control!$B$28*12/1000000 -> 38.4 | C6: =C4*1000*Scenario_Control!$B$28*12/1000000 -> 1231.2 | D6: =D4*1000*Scenario_Control!$B$28*12/1000000 -> 1723.2 | E6: =E4*1000*Scenario_Control!$B$28*12/1000000 -> 1747.2 | F6: =F4*1000*Scenario_Control!$B$28*12/1000000 -> 1747.2 | G6: =G4*1000*Scenario_Control!$B$28*12/1000000 -> 1612.8 | H6: =H4*1000*Scenario_Control!$B$28*12/1000000 -> 1612.8 | I6: =I4*1000*Scenario_Control!$B$28*12/1000000 -> 1612.8 | ... K6: =K4*1000*Scenario_Control!$B$28*12/1000000 -> 1612.8
A7: DDMP-style incentive (R'm) | B7: =B5*Scenario_Control!$B$29/2 -> 60 | C7: =C5*Scenario_Control!$B$29/2+B5*Scenario_Control!$B$29/2 -> 1923.75 | D7: =D5*Scenario_Control!$B$29/2+C5*Scenario_Control!$B$29/2 -> 2632.5 | E7: =E5*Scenario_Control!$B$29/2+D5*Scenario_Control!$B$29/2 -> 806.25 | F7: =F5*Scenario_Control!$B$29/2+E5*Scenario_Control!$B$29/2 -> 37.5 | G7: =G5*Scenario_Control!$B$29/2+F5*Scenario_Control!$B$29/2 -> 0 | H7: =H5*Scenario_Control!$B$29/2+G5*Scenario_Control!$B$29/2 -> 0 | I7: =I5*Scenario_Control!$B$29/2+H5*Scenario_Control!$B$29/2 -> 0 | J7: =J5*Scenario_Control!$B$29/2+I5*Scenario_Control!$B$29/2 -> 0 | K7: =K5*Scenario_Control!$B$29/2+J5*Scenario_Control!$B$29/2 -> 0
A8: Event / curtailment value (R'm) | B8: =B4*Scenario_Control!$B$31*Scenario_Control!$B$30/1000 -> 2 | C8: =C4*Scenario_Control!$B$31*Scenario_Control!$B$30/1000 -> 64.125 | D8: =D4*Scenario_Control!$B$31*Scenario_Control!$B$30/1000 -> 89.75 | E8: =E4*Scenario_Control!$B$31*Scenario_Control!$B$30/1000 -> 91 | F8: =F4*Scenario_Control!$B$31*Scenario_Control!$B$30/1000 -> 91 | G8: =G4*Scenario_Control!$B$31*Scenario_Control!$B$30/1000 -> 84 | H8: =H4*Scenario_Control!$B$31*Scenario_Control!$B$30/1000 -> 84 | I8: =I4*Scenario_Control!$B$31*Scenario_Control!$B$30/1000 -> 84 | ... K8: =K4*Scenario_Control!$B$31*Scenario_Control!$B$30/1000 -> 84
A9: Total DR / grid services revenue (R'm) | B9: =SUM(B6:B8) -> 100.4 | C9: =SUM(C6:C8) -> 3219.075 | D9: =SUM(D6:D8) -> 4445.45 | E9: =SUM(E6:E8) -> 2644.45 | F9: =SUM(F6:F8) -> 1875.7 | G9: =SUM(G6:G8) -> 1696.8 | H9: =SUM(H6:H8) -> 1696.8 | I9: =SUM(I6:I8) -> 1696.8 | ... K9: =SUM(K6:K8) -> 1696.8
A10: Tariff relief / NPA value (R'm) | B10: =Load_Tariff!B24 -> 0 | C10: =Load_Tariff!C24 -> 3486.5019 | D10: =Load_Tariff!D24 -> 7319.6151 | E10: =Load_Tariff!E24 -> 8658.4862 | F10: =Load_Tariff!F24 -> 8658.4862 | G10: =Load_Tariff!G24 -> 7992.4488 | H10: =Load_Tariff!H24 -> 7992.4488 | I10: =Load_Tariff!I24 -> 7992.4488 | ... K10: =Load_Tariff!K24 -> 7992.4488
A11: Total grid-alignment economic value (R'm) | B11: =B9+B10 -> 100.4 | C11: =C9+C10 -> 6705.5769 | D11: =D9+D10 -> 11765.065 | E11: =E9+E10 -> 11302.936 | F11: =F9+F10 -> 10534.186 | G11: =G9+G10 -> 9689.2488 | H11: =H9+H10 -> 9689.2488 | I11: =I9+I10 -> 9689.2488 | ... K11: =K9+K10 -> 9689.2488
A12: Revenue status | B12: Milestone-linked; recurring platform value | C12: Milestone-linked; recurring platform value | D12: Milestone-linked; recurring platform value | E12: Milestone-linked; recurring platform value | F12: Milestone-linked; recurring platform value | G12: Milestone-linked; recurring platform value | H12: Milestone-linked; recurring platform value | I12: Milestone-linked; recurring platform value | J12: Milestone-linked; recurring platform value | K12: Milestone-linked; recurring platform value
A13: Milestone dependency | B13: NPA / market participation / dispatch performance | C13: NPA / market participation / dispatch performance | D13: NPA / market participation / dispatch performance | E13: NPA / market participation / dispatch performance | F13: NPA / market participation / dispatch performance | G13: NPA / market participation / dispatch performance | H13: NPA / market participation / dispatch performance | I13: NPA / market participation / dispatch performance | J13: NPA / market participation / dispatch performance | K13: NPA / market participation / dispatch performance

Sheet AI_DC_Model
A1: AI/DC Commercial Model - Power Resale, Hosting and Owned Inference
A3: Metric | B3: 2026 | C3: 2027 | D3: 2028 | E3: 2029 | F3: 2030 | G3: 2031 | H3: 2032 | I3: 2033 | J3: 2034 | K3: 2035
A4: AI/DC host MW | B4: =Load_Tariff!B9 -> 0 | C4: =Load_Tariff!C9 -> 67.5 | D4: =Load_Tariff!D9 -> 200 | E4: =Load_Tariff!E9 -> 330 | F4: =Load_Tariff!F9 -> 480 | G4: =Load_Tariff!G9 -> 470 | H4: =Load_Tariff!H9 -> 470 | I4: =Load_Tariff!I9 -> 470 | ... K4: =Load_Tariff!K9 -> 470
A5: Reserved Layer-5 MW | B5: =Load_Tariff!B8 -> 0 | C5: =Load_Tariff!C8 -> 0 | D5: =Load_Tariff!D8 -> 5 | E5: =Load_Tariff!E8 -> 50 | F5: =Load_Tariff!F8 -> 100 | G5: =Load_Tariff!G8 -> 250 | H5: =Load_Tariff!H8 -> 250 | I5: =Load_Tariff!I8 -> 250 | ... K5: =Load_Tariff!K8 -> 250
A6: AI/DC host energy (GWh) | B6: =Load_Tariff!B14 -> 0 | C6: =Load_Tariff!C14 -> 579.474 | D6: =Load_Tariff!D14 -> 1716.96 | E6: =Load_Tariff!E14 -> 2832.984 | F6: =Load_Tariff!F14 -> 4120.704 | G6: =Load_Tariff!G14 -> 4034.856 | H6: =Load_Tariff!H14 -> 4034.856 | I6: =Load_Tariff!I14 -> 4034.856 | ... K6: =Load_Tariff!K14 -> 4034.856
A7: Own inference energy (GWh) | B7: =Load_Tariff!B15 -> 0 | C7: =Load_Tariff!C15 -> 0 | D7: =Load_Tariff!D15 -> 0 | E7: =Load_Tariff!E15 -> 0 | F7: =Load_Tariff!F15 -> 0 | G7: =Load_Tariff!G15 -> 0 | H7: =Load_Tariff!H15 -> 0 | I7: =Load_Tariff!I15 -> 0 | ... K7: =Load_Tariff!K15 -> 0
A8: AI/DC power resale revenue (R'm) | B8: =Load_Tariff!B22 -> 0 | C8: =Load_Tariff!C22 -> 1477.6587 | D8: =Load_Tariff!D22 -> 4465.813 | E8: =Load_Tariff!E22 -> 7515.9632 | F8: =Load_Tariff!F22 -> 11150.956 | G8: =Load_Tariff!G22 -> 11137.018 | H8: =Load_Tariff!H22 -> 11359.758 | I8: =Load_Tariff!I22 -> 11586.953 | ... K8: =Load_Tariff!K22 -> 12055.066
A9: AI/DC power import cost (R'm) | B9: =Load_Tariff!B20 -> 0 | C9: =Load_Tariff!C20 -> 637.4214 | D9: =Load_Tariff!D20 -> 1545.264 | E9: =Load_Tariff!E20 -> 2266.3872 | F9: =Load_Tariff!F20 -> 3296.5632 | G9: =Load_Tariff!G20 -> 3227.8848 | H9: =Load_Tariff!H20 -> 3227.8848 | I9: =Load_Tariff!I20 -> 3227.8848 | ... K9: =Load_Tariff!K20 -> 3227.8848
A10: AI/DC power gross margin (R'm) | B10: =B8-B9 -> 0 | C10: =C8-C9 -> 840.2373 | D10: =D8-D9 -> 2920.549 | E10: =E8-E9 -> 5249.576 | F10: =F8-F9 -> 7854.3931 | G10: =G8-G9 -> 7909.1328 | H10: =H8-H9 -> 8131.8732 | I10: =I8-I9 -> 8359.0683 | ... K10: =K8-K9 -> 8827.1813
A11: AI/DC hosting / colocation revenue (R'm) | B11: =B4*Scenario_Control!$B$27*12 -> 0 | C11: =C4*Scenario_Control!$B$27*12 -> 607.5 | D11: =D4*Scenario_Control!$B$27*12 -> 1800 | E11: =E4*Scenario_Control!$B$27*12 -> 2970 | F11: =F4*Scenario_Control!$B$27*12 -> 4320 | G11: =G4*Scenario_Control!$B$27*12 -> 4230 | H11: =H4*Scenario_Control!$B$27*12 -> 4230 | I11: =I4*Scenario_Control!$B$27*12 -> 4230 | ... K11: =K4*Scenario_Control!$B$27*12 -> 4230
A12: AI/DC hosting operating cost (R'm) | B12: =B11*0.15 -> 0 | C12: =C11*0.15 -> 91.125 | D12: =D11*0.15 -> 270 | E12: =E11*0.15 -> 445.5 | F12: =F11*0.15 -> 648 | G12: =G11*0.15 -> 634.5 | H12: =H11*0.15 -> 634.5 | I12: =I11*0.15 -> 634.5 | ... K12: =K11*0.15 -> 634.5
A13: AI/DC hosting EBITDA (R'm) | B13: =B10+B11-B12 -> 0 | C13: =C10+C11-C12 -> 1356.6123 | D13: =D10+D11-D12 -> 4450.549 | E13: =E10+E11-E12 -> 7774.076 | F13: =F10+F11-F12 -> 11526.393 | G13: =G10+G11-G12 -> 11504.633 | H13: =H10+H11-H12 -> 11727.373 | I13: =I10+I11-I12 -> 11954.568 | ... K13: =K10+K11-K12 -> 12422.681
A14: Owned inference gross revenue (Layer 5 option - excluded from base case) (R'm) | B14: =B5*Scenario_Control!$B$40*(1-Scenario_Control!$B$41)^MAX(0,B$3-2028)*Scenario_Control!$B$54 -> 0 | C14: =C5*Scenario_Control!$B$40*(1-Scenario_Control!$B$41)^MAX(0,C$3-2028)*Scenario_Control!$B$54 -> 0 | D14: =D5*Scenario_Control!$B$40*(1-Scenario_Control!$B$41)^MAX(0,D$3-2028)*Scenario_Control!$B$54 -> 0 | E14: =E5*Scenario_Control!$B$40*(1-Scenario_Control!$B$41)^MAX(0,E$3-2028)*Scenario_Control!$B$54 -> 0 | F14: =F5*Scenario_Control!$B$40*(1-Scenario_Control!$B$41)^MAX(0,F$3-2028)*Scenario_Control!$B$54 -> 0 | G14: =G5*Scenario_Control!$B$40*(1-Scenario_Control!$B$41)^MAX(0,G$3-2028)*Scenario_Control!$B$54 -> 0 | H14: =H5*Scenario_Control!$B$40*(1-Scenario_Control!$B$41)^MAX(0,H$3-2028)*Scenario_Control!$B$54 -> 0 | I14: =I5*Scenario_Control!$B$40*(1-Scenario_Control!$B$41)^MAX(0,I$3-2028)*Scenario_Control!$B$54 -> 0 | ... K14: =K5*Scenario_Control!$B$40*(1-Scenario_Control!$B$41)^MAX(0,K$3-2028)*Scenario_Control!$B$54 -> 0
A15: Own inference non-power opex (R'm) | B15: =B14*Scenario_Control!$B$42 -> 0 | C15: =C14*Scenario_Control!$B$42 -> 0 | D15: =D14*Scenario_Control!$B$42 -> 0 | E15: =E14*Scenario_Control!$B$42 -> 0 | F15: =F14*Scenario_Control!$B$42 -> 0 | G15: =G14*Scenario_Control!$B$42 -> 0 | H15: =H14*Scenario_Control!$B$42 -> 0 | I15: =I14*Scenario_Control!$B$42 -> 0 | ... K15: =K14*Scenario_Control!$B$42 -> 0
A16: Own inference power cost (R'm) | B16: =Load_Tariff!B21 -> 0 | C16: =Load_Tariff!C21 -> 0 | D16: =Load_Tariff!D21 -> 0 | E16: =Load_Tariff!E21 -> 0 | F16: =Load_Tariff!F21 -> 0 | G16: =Load_Tariff!G21 -> 0 | H16: =Load_Tariff!H21 -> 0 | I16: =Load_Tariff!I21 -> 0 | ... K16: =Load_Tariff!K21 -> 0
A17: Own inference EBITDA (R'm) | B17: =B14-B15-B16 -> 0 | C17: =C14-C15-C16 -> 0 | D17: =D14-D15-D16 -> 0 | E17: =E14-E15-E16 -> 0 | F17: =F14-F15-F16 -> 0 | G17: =G14-G15-G16 -> 0 | H17: =H14-H15-H16 -> 0 | I17: =I14-I15-I16 -> 0 | ... K17: =K14-K15-K16 -> 0
A18: Total AI/DC + inference revenue (R'm) | B18: =B8+B11+B14 -> 0 | C18: =C8+C11+C14 -> 2085.1587 | D18: =D8+D11+D14 -> 6265.813 | E18: =E8+E11+E14 -> 10485.963 | F18: =F8+F11+F14 -> 15470.956 | G18: =G8+G11+G14 -> 15367.018 | H18: =H8+H11+H14 -> 15589.758 | I18: =I8+I11+I14 -> 15816.953 | ... K18: =K8+K11+K14 -> 16285.066
A19: Total AI/DC + inference EBITDA (R'm) | B19: =B13+B17 -> 0 | C19: =C13+C17 -> 1356.6123 | D19: =D13+D17 -> 4450.549 | E19: =E13+E17 -> 7774.076 | F19: =F13+F17 -> 11526.393 | G19: =G13+G17 -> 11504.633 | H19: =H13+H17 -> 11727.373 | I19: =I13+I17 -> 11954.568 | ... K19: =K13+K17 -> 12422.681
A20: AI/DC commercial status | B20: Pilot / partner discussions | C20: Pilot / partner discussions | D20: Contracted capacity target | E20: Contracted capacity target | F20: Scaled hosting + selective own inference | G20: Scaled hosting + selective own inference | H20: Scaled hosting + selective own inference | I20: Scaled hosting + selective own inference | J20: Scaled hosting + selective own inference | K20: Scaled hosting + selective own inference

Sheet Capex_Model
A1: Capex Model - Core Platform vs Optional Owned Inference
A3: Capex component | B3: 2026 | C3: 2027 | D3: 2028 | E3: 2029 | F3: 2030 | G3: 2031 | H3: 2032 | I3: 2033 | J3: 2034 | K3: 2035
A4: New connected MW | B4: =MAX(0,Load_Tariff!B4-0) -> 40 | C4: =MAX(0,Load_Tariff!C4-Load_Tariff!B4) -> 1310 | D4: =MAX(0,Load_Tariff!D4-Load_Tariff!C4) -> 650 | E4: =MAX(0,Load_Tariff!E4-Load_Tariff!D4) -> 200 | F4: =MAX(0,Load_Tariff!F4-Load_Tariff!E4) -> 200 | G4: =MAX(0,Load_Tariff!G4-Load_Tariff!F4) -> 0 | H4: =MAX(0,Load_Tariff!H4-Load_Tariff!G4) -> 0 | I4: =MAX(0,Load_Tariff!I4-Load_Tariff!H4) -> 0 | J4: =MAX(0,Load_Tariff!J4-Load_Tariff!I4) -> 0 | K4: =MAX(0,Load_Tariff!K4-Load_Tariff!J4) -> 0
A5: New interruptible mining MW | B5: =MAX(0,Load_Tariff!B11-0) -> 40 | C5: =MAX(0,Load_Tariff!C11-Load_Tariff!B11) -> 1242.5 | D5: =MAX(0,Load_Tariff!D11-Load_Tariff!C11) -> 512.5 | E5: =MAX(0,Load_Tariff!E11-Load_Tariff!D11) -> 25 | F5: =MAX(0,Load_Tariff!F11-Load_Tariff!E11) -> 0 | G5: =MAX(0,Load_Tariff!G11-Load_Tariff!F11) -> 0 | H5: =MAX(0,Load_Tariff!H11-Load_Tariff!G11) -> 0 | I5: =MAX(0,Load_Tariff!I11-Load_Tariff!H11) -> 0 | J5: =MAX(0,Load_Tariff!J11-Load_Tariff!I11) -> 0 | K5: =MAX(0,Load_Tariff!K11-Load_Tariff!J11) -> 0
A6: New AI/DC host MW | B6: =MAX(0,Load_Tariff!B9-0) -> 0 | C6: =MAX(0,Load_Tariff!C9-Load_Tariff!B9) -> 67.5 | D6: =MAX(0,Load_Tariff!D9-Load_Tariff!C9) -> 132.5 | E6: =MAX(0,Load_Tariff!E9-Load_Tariff!D9) -> 130 | F6: =MAX(0,Load_Tariff!F9-Load_Tariff!E9) -> 150 | G6: =MAX(0,Load_Tariff!G9-Load_Tariff!F9) -> 0 | H6: =MAX(0,Load_Tariff!H9-Load_Tariff!G9) -> 0 | I6: =MAX(0,Load_Tariff!I9-Load_Tariff!H9) -> 0 | J6: =MAX(0,Load_Tariff!J9-Load_Tariff!I9) -> 0 | K6: =MAX(0,Load_Tariff!K9-Load_Tariff!J9) -> 0
A7: Reserved Layer-5 MW additions | B7: =MAX(0,Load_Tariff!B8-0) -> 0 | C7: =MAX(0,Load_Tariff!C8-Load_Tariff!B8) -> 0 | D7: =MAX(0,Load_Tariff!D8-Load_Tariff!C8) -> 5 | E7: =MAX(0,Load_Tariff!E8-Load_Tariff!D8) -> 45 | F7: =MAX(0,Load_Tariff!F8-Load_Tariff!E8) -> 50 | G7: =MAX(0,Load_Tariff!G8-Load_Tariff!F8) -> 150 | H7: =MAX(0,Load_Tariff!H8-Load_Tariff!G8) -> 0 | I7: =MAX(0,Load_Tariff!I8-Load_Tariff!H8) -> 0 | J7: =MAX(0,Load_Tariff!J8-Load_Tariff!I8) -> 0 | K7: =MAX(0,Load_Tariff!K8-Load_Tariff!J8) -> 0
A8: New solar MW | B8: =20 -> 20 | C8: =230 -> 230 | D8: =350 -> 350 | E8: =600 -> 600 | F8: =200 -> 200 | G8: =100 -> 100 | H8: =0 -> 0 | I8: =0 -> 0 | J8: =0 -> 0 | K8: =0 -> 0
A9: Mining infrastructure capex (R'm) | B9: =B5*Scenario_Control!$B$35 -> 800 | C9: =C5*Scenario_Control!$B$35 -> 24850 | D9: =D5*Scenario_Control!$B$35 -> 10250 | E9: =E5*Scenario_Control!$B$35 -> 500 | F9: =F5*Scenario_Control!$B$35 -> 0 | G9: =G5*Scenario_Control!$B$35 -> 0 | H9: =H5*Scenario_Control!$B$35 -> 0 | I9: =I5*Scenario_Control!$B$35 -> 0 | ... K9: =K5*Scenario_Control!$B$35 -> 0
A10: Electrical / site capex (R'm) | B10: =B4*Scenario_Control!$B$36 -> 200 | C10: =C4*Scenario_Control!$B$36 -> 6550 | D10: =D4*Scenario_Control!$B$36 -> 3250 | E10: =E4*Scenario_Control!$B$36 -> 1000 | F10: =F4*Scenario_Control!$B$36 -> 1000 | G10: =G4*Scenario_Control!$B$36 -> 0 | H10: =H4*Scenario_Control!$B$36 -> 0 | I10: =I4*Scenario_Control!$B$36 -> 0 | ... K10: =K4*Scenario_Control!$B$36 -> 0
A11: Solar capex (R'm) | B11: =B8*Scenario_Control!$B$37 -> 140 | C11: =C8*Scenario_Control!$B$37 -> 1610 | D11: =D8*Scenario_Control!$B$37 -> 2450 | E11: =E8*Scenario_Control!$B$37 -> 4200 | F11: =F8*Scenario_Control!$B$37 -> 1400 | G11: =G8*Scenario_Control!$B$37 -> 700 | H11: =H8*Scenario_Control!$B$37 -> 0 | I11: =I8*Scenario_Control!$B$37 -> 0 | ... K11: =K8*Scenario_Control!$B$37 -> 0
A12: AI/DC hosting infrastructure capex (R'm) | B12: =B6*Scenario_Control!$B$38 -> 0 | C12: =C6*Scenario_Control!$B$38 -> 2700 | D12: =D6*Scenario_Control!$B$38 -> 5300 | E12: =E6*Scenario_Control!$B$38 -> 5200 | F12: =F6*Scenario_Control!$B$38 -> 6000 | G12: =G6*Scenario_Control!$B$38 -> 0 | H12: =H6*Scenario_Control!$B$38 -> 0 | I12: =I6*Scenario_Control!$B$38 -> 0 | ... K12: =K6*Scenario_Control!$B$38 -> 0
A13: Owned inference / GPU capex (Layer 5 option - excluded from base case) (R'm) | B13: =B7*Scenario_Control!$B$39*Scenario_Control!$B$54 -> 0 | C13: =C7*Scenario_Control!$B$39*Scenario_Control!$B$54 -> 0 | D13: =D7*Scenario_Control!$B$39*Scenario_Control!$B$54 -> 0 | E13: =E7*Scenario_Control!$B$39*Scenario_Control!$B$54 -> 0 | F13: =F7*Scenario_Control!$B$39*Scenario_Control!$B$54 -> 0 | G13: =G7*Scenario_Control!$B$39*Scenario_Control!$B$54 -> 0 | H13: =H7*Scenario_Control!$B$39*Scenario_Control!$B$54 -> 0 | I13: =I7*Scenario_Control!$B$39*Scenario_Control!$B$54 -> 0 | ... K13: =K7*Scenario_Control!$B$39*Scenario_Control!$B$54 -> 0
A14: Gross capex - Core Layers 1-4 (R'm) | B14: =SUM(B9:B12) -> 1140 | C14: =SUM(C9:C12) -> 35710 | D14: =SUM(D9:D12) -> 21250 | E14: =SUM(E9:E12) -> 10900 | F14: =SUM(F9:F12) -> 8400 | G14: =SUM(G9:G12) -> 700 | H14: =SUM(H9:H12) -> 0 | I14: =SUM(I9:I12) -> 0 | ... K14: =SUM(K9:K12) -> 0
A15: Gross capex - Full Stack incl. Layer 5 (R'm) | B15: =B14+B13 -> 1140 | C15: =C14+C13 -> 35710 | D15: =D14+D13 -> 21250 | E15: =E14+E13 -> 10900 | F15: =F14+F13 -> 8400 | G15: =G14+G13 -> 700 | H15: =H14+H13 -> 0 | I15: =I14+I13 -> 0 | ... K15: =K14+K13 -> 0
A16: Partner/vendor-funded AI/DC capex (R'm) | B16: =B12*Scenario_Control!$B$44 -> 0 | C16: =C12*Scenario_Control!$B$44 -> 1350 | D16: =D12*Scenario_Control!$B$44 -> 2650 | E16: =E12*Scenario_Control!$B$44 -> 2600 | F16: =F12*Scenario_Control!$B$44 -> 3000 | G16: =G12*Scenario_Control!$B$44 -> 0 | H16: =H12*Scenario_Control!$B$44 -> 0 | I16: =I12*Scenario_Control!$B$44 -> 0 | ... K16: =K12*Scenario_Control!$B$44 -> 0
A17: Partner/vendor-funded inference capex (R'm) | B17: =B13*Scenario_Control!$B$45 -> 0 | C17: =C13*Scenario_Control!$B$45 -> 0 | D17: =D13*Scenario_Control!$B$45 -> 0 | E17: =E13*Scenario_Control!$B$45 -> 0 | F17: =F13*Scenario_Control!$B$45 -> 0 | G17: =G13*Scenario_Control!$B$45 -> 0 | H17: =H13*Scenario_Control!$B$45 -> 0 | I17: =I13*Scenario_Control!$B$45 -> 0 | ... K17: =K13*Scenario_Control!$B$45 -> 0
A18: BitMach-funded core capex (R'm) | B18: =(B9+B10+B11)*(1-Scenario_Control!$B$48)+B12*(1-Scenario_Control!$B$44) -> 1026 | C18: =(C9+C10+C11)*(1-Scenario_Control!$B$48)+C12*(1-Scenario_Control!$B$44) -> 31059 | D18: =(D9+D10+D11)*(1-Scenario_Control!$B$48)+D12*(1-Scenario_Control!$B$44) -> 17005 | E18: =(E9+E10+E11)*(1-Scenario_Control!$B$48)+E12*(1-Scenario_Control!$B$44) -> 7730 | F18: =(F9+F10+F11)*(1-Scenario_Control!$B$48)+F12*(1-Scenario_Control!$B$44) -> 5160 | G18: =(G9+G10+G11)*(1-Scenario_Control!$B$48)+G12*(1-Scenario_Control!$B$44) -> 630 | H18: =(H9+H10+H11)*(1-Scenario_Control!$B$48)+H12*(1-Scenario_Control!$B$44) -> 0 | I18: =(I9+I10+I11)*(1-Scenario_Control!$B$48)+I12*(1-Scenario_Control!$B$44) -> 0 | ... K18: =(K9+K10+K11)*(1-Scenario_Control!$B$48)+K12*(1-Scenario_Control!$B$44) -> 0
A19: BitMach-funded owned inference capex (R'm) | B19: =B13*(1-Scenario_Control!$B$45) -> 0 | C19: =C13*(1-Scenario_Control!$B$45) -> 0 | D19: =D13*(1-Scenario_Control!$B$45) -> 0 | E19: =E13*(1-Scenario_Control!$B$45) -> 0 | F19: =F13*(1-Scenario_Control!$B$45) -> 0 | G19: =G13*(1-Scenario_Control!$B$45) -> 0 | H19: =H13*(1-Scenario_Control!$B$45) -> 0 | I19: =I13*(1-Scenario_Control!$B$45) -> 0 | ... K19: =K13*(1-Scenario_Control!$B$45) -> 0
A20: Contingency on gross capex (R'm) | B20: =B15*Scenario_Control!$B$43 -> 114 | C20: =C15*Scenario_Control!$B$43 -> 3571 | D20: =D15*Scenario_Control!$B$43 -> 2125 | E20: =E15*Scenario_Control!$B$43 -> 1090 | F20: =F15*Scenario_Control!$B$43 -> 840 | G20: =G15*Scenario_Control!$B$43 -> 70 | H20: =H15*Scenario_Control!$B$43 -> 0 | I20: =I15*Scenario_Control!$B$43 -> 0 | ... K20: =K15*Scenario_Control!$B$43 -> 0
A21: Total BitMach-funded capex incl. contingency (R'm) | B21: =B18+B19+B20 -> 1140 | C21: =C18+C19+C20 -> 34630 | D21: =D18+D19+D20 -> 19130 | E21: =E18+E19+E20 -> 8820 | F21: =F18+F19+F20 -> 6000 | G21: =G18+G19+G20 -> 700 | H21: =H18+H19+H20 -> 0 | I21: =I18+I19+I20 -> 0 | ... K21: =K18+K19+K20 -> 0
A22: Cumulative capex excl. owned inference (R'm) | B22: =SUM($B$14:B14)*(1+Scenario_Control!$B$43) -> 1254 | C22: =SUM($B$14:C14)*(1+Scenario_Control!$B$43) -> 40535 | D22: =SUM($B$14:D14)*(1+Scenario_Control!$B$43) -> 63910 | E22: =SUM($B$14:E14)*(1+Scenario_Control!$B$43) -> 75900 | F22: =SUM($B$14:F14)*(1+Scenario_Control!$B$43) -> 85140 | G22: =SUM($B$14:G14)*(1+Scenario_Control!$B$43) -> 85910 | H22: =SUM($B$14:H14)*(1+Scenario_Control!$B$43) -> 85910 | I22: =SUM($B$14:I14)*(1+Scenario_Control!$B$43) -> 85910 | ... K22: =SUM($B$14:K14)*(1+Scenario_Control!$B$43) -> 85910
A23: Cumulative capex incl. owned inference (R'm) | B23: =SUM($B$15:B15)*(1+Scenario_Control!$B$43) -> 1254 | C23: =SUM($B$15:C15)*(1+Scenario_Control!$B$43) -> 40535 | D23: =SUM($B$15:D15)*(1+Scenario_Control!$B$43) -> 63910 | E23: =SUM($B$15:E15)*(1+Scenario_Control!$B$43) -> 75900 | F23: =SUM($B$15:F15)*(1+Scenario_Control!$B$43) -> 85140 | G23: =SUM($B$15:G15)*(1+Scenario_Control!$B$43) -> 85910 | H23: =SUM($B$15:H15)*(1+Scenario_Control!$B$43) -> 85910 | I23: =SUM($B$15:I15)*(1+Scenario_Control!$B$43) -> 85910 | ... K23: =SUM($B$15:K15)*(1+Scenario_Control!$B$43) -> 85910
A24: Owned inference share of gross capex | B24: =IF(B15=0,0,B13/B15) -> 0 | C24: =IF(C15=0,0,C13/C15) -> 0 | D24: =IF(D15=0,0,D13/D15) -> 0 | E24: =IF(E15=0,0,E13/E15) -> 0 | F24: =IF(F15=0,0,F13/F15) -> 0 | G24: =IF(G15=0,0,G13/G15) -> 0 | H24: =IF(H15=0,0,H13/H15) -> 0 | I24: =IF(I15=0,0,I13/I15) -> 0 | ... K24: =IF(K15=0,0,K13/K15) -> 0

Sheet Revenue_Bridge
A1: Revenue Bridge - Layered Energy-to-Compute Platform
A3: Revenue Stream | B3: 2026 | C3: 2027 | D3: 2028 | E3: 2029 | F3: 2030 | G3: 2031 | H3: 2032 | I3: 2033 | J3: 2034 | K3: 2035
A4: Layer 1 - BTC anchor revenue (R'm) | B4: =BTC_Model!B13 -> 632.70317 | C4: =BTC_Model!C13 -> 21609.048 | D4: =BTC_Model!D13 -> 16047.966 | E4: =BTC_Model!E13 -> 17210.214 | F4: =BTC_Model!F13 -> 18148.953 | G4: =BTC_Model!G13 -> 17619.408 | H4: =BTC_Model!H13 -> 9242.968 | I4: =BTC_Model!I13 -> 9676.2321 | ... K4: =BTC_Model!K13 -> 10542.76
A5: Layer 2 - DR / grid services revenue (R'm) | B5: =DR_Model!B9 -> 100.4 | C5: =DR_Model!C9 -> 3219.075 | D5: =DR_Model!D9 -> 4445.45 | E5: =DR_Model!E9 -> 2644.45 | F5: =DR_Model!F9 -> 1875.7 | G5: =DR_Model!G9 -> 1696.8 | H5: =DR_Model!H9 -> 1696.8 | I5: =DR_Model!I9 -> 1696.8 | ... K5: =DR_Model!K9 -> 1696.8
A6: Layer 2 value - tariff relief / NPA value (R'm) | B6: =DR_Model!B10 -> 0 | C6: =DR_Model!C10 -> 3486.5019 | D6: =DR_Model!D10 -> 7319.6151 | E6: =DR_Model!E10 -> 8658.4862 | F6: =DR_Model!F10 -> 8658.4862 | G6: =DR_Model!G10 -> 7992.4488 | H6: =DR_Model!H10 -> 7992.4488 | I6: =DR_Model!I10 -> 7992.4488 | ... K6: =DR_Model!K10 -> 7992.4488
A7: Layer 3 - Energy market / balancing value (R'm) | B7: =IF(B$3<2028,0,DR_Model!B9*0.3) -> 30.12 | C7: =IF(C$3<2028,0,DR_Model!C9*0.3) -> 965.7225 | D7: =IF(D$3<2028,0,DR_Model!D9*0.3) -> 1333.635 | E7: =IF(E$3<2028,0,DR_Model!E9*0.3) -> 793.335 | F7: =IF(F$3<2028,0,DR_Model!F9*0.3) -> 562.71 | G7: =IF(G$3<2028,0,DR_Model!G9*0.3) -> 509.04 | H7: =IF(H$3<2028,0,DR_Model!H9*0.3) -> 509.04 | I7: =IF(I$3<2028,0,DR_Model!I9*0.3) -> 509.04 | ... K7: =IF(K$3<2028,0,DR_Model!K9*0.3) -> 509.04
A8: Layer 4A - AI/DC power resale revenue (R'm) | B8: =AI_DC_Model!B8 -> 0 | C8: =AI_DC_Model!C8 -> 1477.6587 | D8: =AI_DC_Model!D8 -> 4465.813 | E8: =AI_DC_Model!E8 -> 7515.9632 | F8: =AI_DC_Model!F8 -> 11150.956 | G8: =AI_DC_Model!G8 -> 11137.018 | H8: =AI_DC_Model!H8 -> 11359.758 | I8: =AI_DC_Model!I8 -> 11586.953 | ... K8: =AI_DC_Model!K8 -> 12055.066
A9: Layer 4B - AI/DC hosting / colocation revenue (R'm) | B9: =AI_DC_Model!B11 -> 0 | C9: =AI_DC_Model!C11 -> 607.5 | D9: =AI_DC_Model!D11 -> 1800 | E9: =AI_DC_Model!E11 -> 2970 | F9: =AI_DC_Model!F11 -> 4320 | G9: =AI_DC_Model!G11 -> 4230 | H9: =AI_DC_Model!H11 -> 4230 | I9: =AI_DC_Model!I11 -> 4230 | ... K9: =AI_DC_Model!K11 -> 4230
A10: Revenue Layers 1-4 excl. own inference (R'm) | B10: =SUM(B4:B5,B7:B9) -> 763.22317 | C10: =SUM(C4:C5,C7:C9) -> 27879.004 | D10: =SUM(D4:D5,D7:D9) -> 28092.864 | E10: =SUM(E4:E5,E7:E9) -> 31133.962 | F10: =SUM(F4:F5,F7:F9) -> 36058.319 | G10: =SUM(G4:G5,G7:G9) -> 35192.265 | H10: =SUM(H4:H5,H7:H9) -> 27038.566 | I10: =SUM(I4:I5,I7:I9) -> 27699.025 | ... K10: =SUM(K4:K5,K7:K9) -> 29033.666
A11: Layer 5 - Owned inference / token revenue (strategic option - NOT modelled in base case) (R'm) | B11: =AI_DC_Model!B14 -> 0 | C11: =AI_DC_Model!C14 -> 0 | D11: =AI_DC_Model!D14 -> 0 | E11: =AI_DC_Model!E14 -> 0 | F11: =AI_DC_Model!F14 -> 0 | G11: =AI_DC_Model!G14 -> 0 | H11: =AI_DC_Model!H14 -> 0 | I11: =AI_DC_Model!I14 -> 0 | ... K11: =AI_DC_Model!K14 -> 0
A12: Total revenue incl. Layer 5 (R'm) | B12: =B10+B11 -> 763.22317 | C12: =C10+C11 -> 27879.004 | D12: =D10+D11 -> 28092.864 | E12: =E10+E11 -> 31133.962 | F12: =F10+F11 -> 36058.319 | G12: =G10+G11 -> 35192.265 | H12: =H10+H11 -> 27038.566 | I12: =I10+I11 -> 27699.025 | ... K12: =K10+K11 -> 29033.666
A13: BTC share of full revenue | B13: =IF(B12=0,0,B4/B12) -> 0.82898842 | C13: =IF(C12=0,0,C4/C12) -> 0.77510114 | D13: =IF(D12=0,0,D4/D12) -> 0.57124706 | E13: =IF(E12=0,0,E4/E12) -> 0.55277943 | F13: =IF(F12=0,0,F4/F12) -> 0.50332221 | G13: =IF(G12=0,0,G4/G12) -> 0.50066137 | H13: =IF(H12=0,0,H4/H12) -> 0.34184387 | I13: =IF(I12=0,0,I4/I12) -> 0.34933475 | ... K13: =IF(K12=0,0,K4/K12) -> 0.36312191
A14: DR/grid share of full revenue | B14: =IF(B12=0,0,(B5+B7)/B12) -> 0.17101158 | C14: =IF(C12=0,0,(C5+C7)/C12) -> 0.1501057 | D14: =IF(D12=0,0,(D5+D7)/D12) -> 0.20571363 | E14: =IF(E12=0,0,(E5+E7)/E12) -> 0.11041913 | F14: =IF(F12=0,0,(F5+F7)/F12) -> 0.067624062 | G14: =IF(G12=0,0,(G5+G7)/G12) -> 0.062679682 | H14: =IF(H12=0,0,(H5+H7)/H12) -> 0.08158125 | I14: =IF(I12=0,0,(I5+I7)/I12) -> 0.079636015 | ... K14: =IF(K12=0,0,(K5+K7)/K12) -> 0.075975248
A15: AI/DC + inference share of full revenue | B15: =IF(B12=0,0,(B8+B9+B11)/B12) -> 0 | C15: =IF(C12=0,0,(C8+C9+C11)/C12) -> 0.074793155 | D15: =IF(D12=0,0,(D8+D9+D11)/D12) -> 0.22303931 | E15: =IF(E12=0,0,(E8+E9+E11)/E12) -> 0.33680144 | F15: =IF(F12=0,0,(F8+F9+F11)/F12) -> 0.42905373 | G15: =IF(G12=0,0,(G8+G9+G11)/G12) -> 0.43665895 | H15: =IF(H12=0,0,(H8+H9+H11)/H12) -> 0.57657488 | I15: =IF(I12=0,0,(I8+I9+I11)/I12) -> 0.57102923 | ... K15: =IF(K12=0,0,(K8+K9+K11)/K12) -> 0.56090284
A16: Revenue status / evidence | B16: Base contracted / protocol driven | C16: Milestone-linked commercial stack | D16: Milestone-linked commercial stack | E16: Scaled platform revenue mix | F16: Scaled platform revenue mix | G16: Scaled platform revenue mix | H16: Scaled platform revenue mix | I16: Scaled platform revenue mix | J16: Scaled platform revenue mix | K16: Scaled platform revenue mix

Sheet Financing_DCF
A1: Financing, DCF & Valuation - Core Platform (Layers 1-4)
A2: Layer 5 (owned inference / GPUs) is EXCLUDED from this case (Scenario_Control!B54=0). "incl. owned inference" rows therefore equal the core rows.
A3: Metric | B3: 2026 | C3: 2027 | D3: 2028 | E3: 2029 | F3: 2030 | G3: 2031 | H3: 2032 | I3: 2033 | J3: 2034 | K3: 2035 | M3: Valuation metric | N3: Core Platform (Layers 1-4) | O3: Layer 5 (owned inference)
A4: Total revenue excl. owned inference (R'm) | B4: =Revenue_Bridge!B10 -> 763.22317 | C4: =Revenue_Bridge!C10 -> 27879.004 | D4: =Revenue_Bridge!D10 -> 28092.864 | E4: =Revenue_Bridge!E10 -> 31133.962 | F4: =Revenue_Bridge!F10 -> 36058.319 | G4: =Revenue_Bridge!G10 -> 35192.265 | H4: =Revenue_Bridge!H10 -> 27038.566 | I4: =Revenue_Bridge!I10 -> 27699.025 | ... K4: =Revenue_Bridge!K10 -> 29033.666 | M4: NPV (R'm) | N4: =NPV(Scenario_Control!$B$9,B36:K36) -> 45538.63 | O4: Excluded from the investment case.
A5: Total revenue incl. owned inference (R'm) | B5: =Revenue_Bridge!B12 -> 763.22317 | C5: =Revenue_Bridge!C12 -> 27879.004 | D5: =Revenue_Bridge!D12 -> 28092.864 | E5: =Revenue_Bridge!E12 -> 31133.962 | F5: =Revenue_Bridge!F12 -> 36058.319 | G5: =Revenue_Bridge!G12 -> 35192.265 | H5: =Revenue_Bridge!H12 -> 27038.566 | I5: =Revenue_Bridge!I12 -> 27699.025 | ... K5: =Revenue_Bridge!K12 -> 29033.666 | M5: IRR | N5: =IRR(B36:K36) -> 0.38486848 | O5: Held as a separate strategic option / potential SPV.
A6: Operating cost - mining power (R'm) | B6: =Load_Tariff!B19 -> 326.2224 | C6: =Load_Tariff!C19 -> 6973.0038 | D6: =Load_Tariff!D19 -> 7319.6151 | E6: =Load_Tariff!E19 -> 6184.633 | F6: =Load_Tariff!F19 -> 6184.633 | G6: =Load_Tariff!G19 -> 5708.892 | H6: =Load_Tariff!H19 -> 5708.892 | I6: =Load_Tariff!I19 -> 5708.892 | ... K6: =Load_Tariff!K19 -> 5708.892 | M6: Terminal value undiscounted (R'm) | N6: =K15*Scenario_Control!$B$10 -> 149082.05 | O6: See Layer5_Option tab; toggle Scenario_Control!B54 to evaluate.
A7: Operating cost - AI/DC host power (R'm) | B7: =AI_DC_Model!B9 -> 0 | C7: =AI_DC_Model!C9 -> 637.4214 | D7: =AI_DC_Model!D9 -> 1545.264 | E7: =AI_DC_Model!E9 -> 2266.3872 | F7: =AI_DC_Model!F9 -> 3296.5632 | G7: =AI_DC_Model!G9 -> 3227.8848 | H7: =AI_DC_Model!H9 -> 3227.8848 | I7: =AI_DC_Model!I9 -> 3227.8848 | ... K7: =AI_DC_Model!K9 -> 3227.8848 | M7: Cumulative capex excl. owned inference (R'm) | N7: =Capex_Model!K22 -> 85910
A8: Operating cost - own inference power (R'm) | B8: =AI_DC_Model!B16 -> 0 | C8: =AI_DC_Model!C16 -> 0 | D8: =AI_DC_Model!D16 -> 0 | E8: =AI_DC_Model!E16 -> 0 | F8: =AI_DC_Model!F16 -> 0 | G8: =AI_DC_Model!G16 -> 0 | H8: =AI_DC_Model!H16 -> 0 | I8: =AI_DC_Model!I16 -> 0 | ... K8: =AI_DC_Model!K16 -> 0 | M8: Cumulative capex incl. owned inference (R'm) | N8: =Capex_Model!K23 -> 85910
A9: Operating cost - platform overhead (R'm) | B9: =100*(1+Scenario_Control!$B$13)^0*(1+0.05)^(B$3-2026) -> 100 | C9: =100*(1+Scenario_Control!$B$13)^0*(1+0.05)^(C$3-2026) -> 105 | D9: =100*(1+Scenario_Control!$B$13)^0*(1+0.05)^(D$3-2026) -> 110.25 | E9: =100*(1+Scenario_Control!$B$13)^0*(1+0.05)^(E$3-2026) -> 115.7625 | F9: =100*(1+Scenario_Control!$B$13)^0*(1+0.05)^(F$3-2026) -> 121.55062 | G9: =100*(1+Scenario_Control!$B$13)^0*(1+0.05)^(G$3-2026) -> 127.62816 | H9: =100*(1+Scenario_Control!$B$13)^0*(1+0.05)^(H$3-2026) -> 134.00956 | I9: =100*(1+Scenario_Control!$B$13)^0*(1+0.05)^(I$3-2026) -> 140.71004 | ... K9: =100*(1+Scenario_Control!$B$13)^0*(1+0.05)^(K$3-2026) -> 155.13282 | M9: 2035 EBITDA (R'm) | N9: =K15 -> 18635.257
A10: Operating cost - mining opex (R'm) | B10: =Load_Tariff!B11*0.4 -> 16 | C10: =Load_Tariff!C11*0.4 -> 513 | D10: =Load_Tariff!D11*0.4 -> 718 | E10: =Load_Tariff!E11*0.4 -> 728 | F10: =Load_Tariff!F11*0.4 -> 728 | G10: =Load_Tariff!G11*0.4 -> 672 | H10: =Load_Tariff!H11*0.4 -> 672 | I10: =Load_Tariff!I11*0.4 -> 672 | ... K10: =Load_Tariff!K11*0.4 -> 672 | M10: 2035 Revenue (R'm) | N10: =K4 -> 29033.666
A11: Operating cost - AI/DC hosting opex (R'm) | B11: =AI_DC_Model!B12 -> 0 | C11: =AI_DC_Model!C12 -> 91.125 | D11: =AI_DC_Model!D12 -> 270 | E11: =AI_DC_Model!E12 -> 445.5 | F11: =AI_DC_Model!F12 -> 648 | G11: =AI_DC_Model!G12 -> 634.5 | H11: =AI_DC_Model!H12 -> 634.5 | I11: =AI_DC_Model!I12 -> 634.5 | ... K11: =AI_DC_Model!K12 -> 634.5 | M11: Cumulative equity required (R'm) | N11: =SUM(B22:K22) -> 29723.5
A12: Operating cost - own inference non-power opex (R'm) | B12: =AI_DC_Model!B15 -> 0 | C12: =AI_DC_Model!C15 -> 0 | D12: =AI_DC_Model!D15 -> 0 | E12: =AI_DC_Model!E15 -> 0 | F12: =AI_DC_Model!F15 -> 0 | G12: =AI_DC_Model!G15 -> 0 | H12: =AI_DC_Model!H15 -> 0 | I12: =AI_DC_Model!I15 -> 0 | ... K12: =AI_DC_Model!K15 -> 0
A13: Total opex excl. owned inference (R'm) | B13: =SUM(B6:B7,B9:B11) -> 442.2224 | C13: =SUM(C6:C7,C9:C11) -> 8319.5502 | D13: =SUM(D6:D7,D9:D11) -> 9963.1291 | E13: =SUM(E6:E7,E9:E11) -> 9740.2827 | F13: =SUM(F6:F7,F9:F11) -> 10978.747 | G13: =SUM(G6:G7,G9:G11) -> 10370.905 | H13: =SUM(H6:H7,H9:H11) -> 10377.286 | I13: =SUM(I6:I7,I9:I11) -> 10383.987 | ... K13: =SUM(K6:K7,K9:K11) -> 10398.41
